Workbook

Sheet ALL 3
A2: =(E2=F2) -> TRUE | B2: =(F2=G2) -> TRUE | C2: =AND(A2,B2) -> TRUE | E2: =SPMB!A2 -> 44383 | F2: =VMBS!A2 -> 44383 | G2: =MBB!A2 -> 44383 | I2: =SPMB!E2 -> 25.87 | J2: =VMBS!E2 -> 53.44 | K2: =MBB!E2 -> 108.36 | M2: =J2/I2 -> 2.0657132 | N2: =K2/J2 -> 2.0276946 | O2: =K2/I2 -> 4.1886355
A3: =(E3=F3) -> TRUE | B3: =(F3=G3) -> TRUE | C3: =AND(A3,B3) -> TRUE | E3: =SPMB!A3 -> 44384 | F3: =VMBS!A3 -> 44384 | G3: =MBB!A3 -> 44384 | I3: =SPMB!E3 -> 25.88 | J3: =VMBS!E3 -> 53.43 | K3: =MBB!E3 -> 108.37 | M3: =J3/I3 -> 2.0645286 | N3: =K3/J3 -> 2.0282613 | O3: =K3/I3 -> 4.1874034
A4: =(E4=F4) -> TRUE | B4: =(F4=G4) -> TRUE | C4: =AND(A4,B4) -> TRUE | E4: =SPMB!A4 -> 44385 | F4: =VMBS!A4 -> 44385 | G4: =MBB!A4 -> 44385 | I4: =SPMB!E4 -> 25.9 | J4: =VMBS!E4 -> 53.52 | K4: =MBB!E4 -> 108.5 | M4: =J4/I4 -> 2.0664093 | N4: =K4/J4 -> 2.0272795 | O4: =K4/I4 -> 4.1891892
A5: =(E5=F5) -> TRUE | B5: =(F5=G5) -> TRUE | C5: =AND(A5,B5) -> TRUE | E5: =SPMB!A5 -> 44386 | F5: =VMBS!A5 -> 44386 | G5: =MBB!A5 -> 44386 | I5: =SPMB!E5 -> 25.84 | J5: =VMBS!E5 -> 53.43 | K5: =MBB!E5 -> 108.27 | M5: =J5/I5 -> 2.0677245 | N5: =K5/J5 -> 2.0263897 | O5: =K5/I5 -> 4.1900155
A6: =(E6=F6) -> TRUE | B6: =(F6=G6) -> TRUE | C6: =AND(A6,B6) -> TRUE | E6: =SPMB!A6 -> 44389 | F6: =VMBS!A6 -> 44389 | G6: =MBB!A6 -> 44389 | I6: =SPMB!E6 -> 25.82 | J6: =VMBS!E6 -> 53.45 | K6: =MBB!E6 -> 108.28 | M6: =J6/I6 -> 2.0701007 | N6: =K6/J6 -> 2.0258185 | O6: =K6/I6 -> 4.1936483
A7: =(E7=F7) -> TRUE | B7: =(F7=G7) -> TRUE | C7: =AND(A7,B7) -> TRUE | E7: =SPMB!A7 -> 44390 | F7: =VMBS!A7 -> 44390 | G7: =MBB!A7 -> 44390 | I7: =SPMB!E7 -> 25.79 | J7: =VMBS!E7 -> 53.34 | K7: =MBB!E7 -> 108.17 | M7: =J7/I7 -> 2.0682435 | N7: =K7/J7 -> 2.027934 | O7: =K7/I7 -> 4.1942613
A8: =(E8=F8) -> TRUE | B8: =(F8=G8) -> TRUE | C8: =AND(A8,B8) -> TRUE | E8: =SPMB!A8 -> 44391 | F8: =VMBS!A8 -> 44391 | G8: =MBB!A8 -> 44391 | I8: =SPMB!E8 -> 25.85 | J8: =VMBS!E8 -> 53.41 | K8: =MBB!E8 -> 108.4 | M8: =J8/I8 -> 2.0661509 | N8: =K8/J8 -> 2.0295825 | O8: =K8/I8 -> 4.1934236
A9: =(E9=F9) -> TRUE | B9: =(F9=G9) -> TRUE | C9: =AND(A9,B9) -> TRUE | E9: =SPMB!A9 -> 44392 | F9: =VMBS!A9 -> 44392 | G9: =MBB!A9 -> 44392 | I9: =SPMB!E9 -> 25.87 | J9: =VMBS!E9 -> 53.45 | K9: =MBB!E9 -> 108.49 | M9: =J9/I9 -> 2.0660997 | N9: =K9/J9 -> 2.0297474 | O9: =K9/I9 -> 4.1936606
A10: =(E10=F10) -> TRUE | B10: =(F10=G10) -> TRUE | C10: =AND(A10,B10) -> TRUE | E10: =SPMB!A10 -> 44393 | F10: =VMBS!A10 -> 44393 | G10: =MBB!A10 -> 44393 | I10: =SPMB!E10 -> 25.83 | J10: =VMBS!E10 -> 53.39 | K10: =MBB!E10 -> 108.45 | M10: =J10/I10 -> 2.0669764 | N10: =K10/J10 -> 2.0312793 | O10: =K10/I10 -> 4.1986063
A11: =(E11=F11) -> TRUE | B11: =(F11=G11) -> TRUE | C11: =AND(A11,B11) -> TRUE | E11: =SPMB!A11 -> 44396 | F11: =VMBS!A11 -> 44396 | G11: =MBB!A11 -> 44396 | I11: =SPMB!E11 -> 25.91 | J11: =VMBS!E11 -> 53.52 | K11: =MBB!E11 -> 108.62 | M11: =J11/I11 -> 2.0656117 | N11: =K11/J11 -> 2.0295217 | O11: =K11/I11 -> 4.1922038
A12: =(E12=F12) -> TRUE | B12: =(F12=G12) -> TRUE | C12: =AND(A12,B12) -> TRUE | E12: =SPMB!A12 -> 44397 | F12: =VMBS!A12 -> 44397 | G12: =MBB!A12 -> 44397 | I12: =SPMB!E12 -> 25.91 | J12: =VMBS!E12 -> 53.54 | K12: =MBB!E12 -> 108.56 | M12: =J12/I12 -> 2.0663836 | N12: =K12/J12 -> 2.0276429 | O12: =K12/I12 -> 4.1898881
A13: =(E13=F13) -> TRUE | B13: =(F13=G13) -> TRUE | C13: =AND(A13,B13) -> TRUE | E13: =SPMB!A13 -> 44398 | F13: =VMBS!A13 -> 44398 | G13: =MBB!A13 -> 44398 | I13: =SPMB!E13 -> 25.87 | J13: =VMBS!E13 -> 53.41 | K13: =MBB!E13 -> 108.37 | M13: =J13/I13 -> 2.0645535 | N13: =K13/J13 -> 2.0290208 | O13: =K13/I13 -> 4.189022
... A1255: =(E1255=F1255) -> TRUE | B1255: =(F1255=G1255) -> TRUE | C1255: =AND(A1255,B1255) -> TRUE | E1255: =SPMB!A1255 -> 46205 | F1255: =VMBS!A1255 -> 46205 | G1255: =MBB!A1255 -> 46205 | I1255: =SPMB!E1255 -> 22.2 | J1255: =VMBS!E1255 -> 46.61 | K1255: =MBB!E1255 -> 94.13 | M1255: =J1255/I1255 -> 2.0995495 | N1255: =K1255/J1255 -> 2.0195237 | O1255: =K1255/I1255 -> 4.2400901

Sheet ALL 3 2024+
Q1: 20 | U1: 40 | Y1: 60 | AC1: 120 | AH1: 240
A2: TRUE | B2: TRUE | C2: TRUE | E2: 45293 | F2: 45293 | G2: 45293 | I2: 21.94 | J2: 46.1 | K2: 93.53 | M2: =J2/I2 -> 2.1011851 | N2: =K2/J2 -> 2.0288503 | O2: =K2/I2 -> 4.26299
A3: TRUE | B3: TRUE | C3: TRUE | E3: 45294 | F3: 45294 | G3: 45294 | I3: 21.97 | J3: 46.12 | K3: 93.65 | M3: =J3/I3 -> 2.0992262 | N3: =K3/J3 -> 2.0305724 | O3: =K3/I3 -> 4.2626309
A4: TRUE | B4: TRUE | C4: TRUE | E4: 45295 | F4: 45295 | G4: 45295 | I4: 21.82 | J4: 45.84 | K4: 93.14 | M4: =J4/I4 -> 2.1008249 | N4: =K4/J4 -> 2.0318499 | O4: =K4/I4 -> 4.268561
A5: TRUE | B5: TRUE | C5: TRUE | E5: 45296 | F5: 45296 | G5: 45296 | I5: 21.8 | J5: 45.77 | K5: 92.97 | M5: =J5/I5 -> 2.0995413 | N5: =K5/J5 -> 2.0312432 | O5: =K5/I5 -> 4.2646789
A6: TRUE | B6: TRUE | C6: TRUE | E6: 45299 | F6: 45299 | G6: 45299 | I6: 21.9 | J6: 46.01 | K6: 93.4 | M6: =J6/I6 -> 2.1009132 | N6: =K6/J6 -> 2.0299935 | O6: =K6/I6 -> 4.2648402
A7: TRUE | B7: TRUE | C7: TRUE | E7: 45300 | F7: 45300 | G7: 45300 | I7: 21.89 | J7: 45.97 | K7: 93.25 | M7: =J7/I7 -> 2.1000457 | N7: =K7/J7 -> 2.0284968 | O7: =K7/I7 -> 4.259936
A8: TRUE | B8: TRUE | C8: TRUE | E8: 45301 | F8: 45301 | G8: 45301 | I8: 21.88 | J8: 45.91 | K8: 93.2 | M8: =J8/I8 -> 2.0982633 | N8: =K8/J8 -> 2.0300588 | O8: =K8/I8 -> 4.2595978
A9: TRUE | B9: TRUE | C9: TRUE | E9: 45302 | F9: 45302 | G9: 45302 | I9: 22 | J9: 46.19 | K9: 93.85 | M9: =J9/I9 -> 2.0995455 | N9: =K9/J9 -> 2.0318251 | O9: =K9/I9 -> 4.2659091
A10: TRUE | B10: TRUE | C10: TRUE | E10: 45303 | F10: 45303 | G10: 45303 | I10: 22.04 | J10: 46.29 | K10: 93.98 | M10: =J10/I10 -> 2.1002722 | N10: =K10/J10 -> 2.0302441 | O10: =K10/I10 -> 4.2640653
A11: TRUE | B11: TRUE | C11: TRUE | E11: 45307 | F11: 45307 | G11: 45307 | I11: 21.85 | J11: 45.9 | K11: 93.15 | M11: =J11/I11 -> 2.1006865 | N11: =K11/J11 -> 2.0294118 | O11: =K11/I11 -> 4.2631579
A12: TRUE | B12: TRUE | C12: TRUE | E12: 45308 | F12: 45308 | G12: 45308 | I12: 21.75 | J12: 45.7 | K12: 92.85 | M12: =J12/I12 -> 2.1011494 | N12: =K12/J12 -> 2.0317287 | O12: =K12/I12 -> 4.2689655
A13: TRUE | B13: TRUE | C13: TRUE | E13: 45309 | F13: 45309 | G13: 45309 | I13: 21.75 | J13: 45.68 | K13: 92.72 | M13: =J13/I13 -> 2.1002299 | N13: =K13/J13 -> 2.0297723 | O13: =K13/I13 -> 4.2629885
... A21: TRUE | B21: TRUE | C21: TRUE | E21: 45321 | F21: 45321 | G21: 45321 | I21: 21.9 | J21: 45.99 | K21: 93.31 | M21: =J21/I21 -> 2.1 | N21: =K21/J21 -> 2.0289193 | O21: =K21/I21 -> 4.2607306
A22: TRUE | B22: TRUE | C22: TRUE | E22: 45322 | F22: 45322 | G22: 45322 | I22: 22.02 | J22: 46.19 | K22: 93.8 | M22: =J22/I22 -> 2.0976385 | N22: =K22/J22 -> 2.0307426 | O22: =K22/I22 -> 4.2597639 | Q22: =AVERAGE(M2:M21) -> 2.1002112 | R22: =AVERAGE(N2:N21) -> 2.0298904 | S22: =AVERAGE(O2:O21) -> 4.2631984
A23: TRUE | B23: TRUE | C23: TRUE | E23: 45323 | F23: 45323 | G23: 45323 | I23: 22.04 | J23: 46.29 | K23: 93.95 | M23: =J23/I23 -> 2.1002722 | N23: =K23/J23 -> 2.029596 | O23: =K23/I23 -> 4.2627042 | Q23: =AVERAGE(M3:M22) -> 2.1000338 | R23: =AVERAGE(N3:N22) -> 2.029985 | S23: =AVERAGE(O3:O22) -> 4.2630371
A24: TRUE | B24: TRUE | C24: TRUE | E24: 45324 | F24: 45324 | G24: 45324 | I24: 21.82 | J24: 45.81 | K24: 93.02 | M24: =J24/I24 -> 2.09945 | N24: =K24/J24 -> 2.030561 | O24: =K24/I24 -> 4.2630614 | Q24: =AVERAGE(M4:M23) -> 2.1000861 | R24: =AVERAGE(N4:N23) -> 2.0299362 | S24: =AVERAGE(O4:O23) -> 4.2630408
A25: TRUE | B25: TRUE | C25: TRUE | E25: 45327 | F25: 45327 | G25: 45327 | I25: 21.63 | J25: 45.42 | K25: 92.24 | M25: =J25/I25 -> 2.0998613 | N25: =K25/J25 -> 2.0308234 | O25: =K25/I25 -> 4.2644475 | Q25: =AVERAGE(M5:M24) -> 2.1000174 | R25: =AVERAGE(N5:N24) -> 2.0298718 | S25: =AVERAGE(O5:O24) -> 4.2627658
A26: TRUE | B26: TRUE | C26: TRUE | E26: 45328 | F26: 45328 | G26: 45328 | I26: 21.78 | J26: 45.67 | K26: 92.71 | M26: =J26/I26 -> 2.0968779 | N26: =K26/J26 -> 2.0299978 | O26: =K26/I26 -> 4.2566575 | Q26: =AVERAGE(M6:M25) -> 2.1000334 | R26: =AVERAGE(N6:N25) -> 2.0298508 | S26: =AVERAGE(O6:O25) -> 4.2627542
A27: TRUE | B27: TRUE | C27: TRUE | E27: 45329 | F27: 45329 | G27: 45329 | I27: 21.69 | J27: 45.55 | K27: 92.42 | M27: =J27/I27 -> 2.1000461 | N27: =K27/J27 -> 2.0289791 | O27: =K27/I27 -> 4.2609497 | Q27: =AVERAGE(M7:M26) -> 2.0998316 | R27: =AVERAGE(N7:N26) -> 2.029851 | S27: =AVERAGE(O7:O26) -> 4.2623451
A28: TRUE | B28: TRUE | C28: TRUE | E28: 45330 | F28: 45330 | G28: 45330 | I28: 21.66 | J28: 45.47 | K28: 92.24 | M28: =J28/I28 -> 2.0992613 | N28: =K28/J28 -> 2.0285903 | O28: =K28/I28 -> 4.2585411 | Q28: =AVERAGE(M8:M27) -> 2.0998316 | R28: =AVERAGE(N8:N27) -> 2.0298751 | S28: =AVERAGE(O8:O27) -> 4.2623958
A29: TRUE | B29: TRUE | C29: TRUE | E29: 45331 | F29: 45331 | G29: 45331 | I29: 21.63 | J29: 45.47 | K29: 92.18 | M29: =J29/I29 -> 2.1021729 | N29: =K29/J29 -> 2.0272707 | O29: =K29/I29 -> 4.2616736 | Q29: =AVERAGE(M9:M28) -> 2.0998815 | R29: =AVERAGE(N9:N28) -> 2.0298017 | S29: =AVERAGE(O9:O28) -> 4.262343
A30: TRUE | B30: TRUE | C30: TRUE | E30: 45334 | F30: 45334 | G30: 45334 | I30: 21.63 | J30: 45.44 | K30: 92.16 | M30: =J30/I30 -> 2.1007859 | N30: =K30/J30 -> 2.028169 | O30: =K30/I30 -> 4.260749 | Q30: =AVERAGE(M10:M29) -> 2.1000129 | R30: =AVERAGE(N10:N29) -> 2.029574 | S30: =AVERAGE(O10:O29) -> 4.2621312
A31: TRUE | B31: TRUE | C31: TRUE | E31: 45335 | F31: 45335 | G31: 45335 | I31: 21.42 | J31: 44.98 | K31: 91.2 | M31: =J31/I31 -> 2.0999066 | N31: =K31/J31 -> 2.0275678 | O31: =K31/I31 -> 4.2577031 | Q31: =AVERAGE(M11:M30) -> 2.1000386 | R31: =AVERAGE(N11:N30) -> 2.0294702 | S31: =AVERAGE(O11:O30) -> 4.2619654
A32: TRUE | B32: TRUE | C32: TRUE | E32: 45336 | F32: 45336 | G32: 45336 | I32: 21.52 | J32: 45.25 | K32: 91.77 | M32: =J32/I32 -> 2.1026952 | N32: =K32/J32 -> 2.0280663 | O32: =K32/I32 -> 4.2644052 | Q32: =AVERAGE(M12:M31) -> 2.0999996 | R32: =AVERAGE(N12:N31) -> 2.029378 | S32: =AVERAGE(O12:O31) -> 4.2616926
A33: TRUE | B33: TRUE | C33: TRUE | E33: 45337 | F33: 45337 | G33: 45337 | I33: 21.62 | J33: 45.41 | K33: 92.05 | M33: =J33/I33 -> 2.10037 | N33: =K33/J33 -> 2.0270865 | O33: =K33/I33 -> 4.2576318 | Q33: =AVERAGE(M13:M32) -> 2.1000769 | R33: =AVERAGE(N13:N32) -> 2.0291949 | S33: =AVERAGE(O13:O32) -> 4.2614646
... A41: TRUE | B41: TRUE | C41: TRUE | E41: 45350 | F41: 45350 | G41: 45350 | I41: 21.51 | J41: 45.26 | K41: 91.74 | M41: =J41/I41 -> 2.1041376 | N41: =K41/J41 -> 2.0269554 | O41: =K41/I41 -> 4.264993 | Q41: =AVERAGE(M21:M40) -> 2.1009641 | R41: =AVERAGE(N21:N40) -> 2.0284293 | S41: =AVERAGE(O21:O40) -> 4.2616551
A42: TRUE | B42: TRUE | C42: TRUE | E42: 45351 | F42: 45351 | G42: 45351 | I42: 21.56 | J42: 45.34 | K42: 91.91 | M42: =J42/I42 -> 2.1029685 | N42: =K42/J42 -> 2.0271284 | O42: =K42/I42 -> 4.262987 | Q42: =AVERAGE(M22:M41) -> 2.101171 | R42: =AVERAGE(N22:N41) -> 2.0283311 | S42: =AVERAGE(O22:O41) -> 4.2618682 | U42: =AVERAGE(M2:M41) -> 2.1006911 | V42: =AVERAGE(N2:N41) -> 2.0291107 | W42: =AVERAGE(O2:O41) -> 4.2625333
A43: TRUE | B43: TRUE | C43: TRUE | E43: 45352 | F43: 45352 | G43: 45352 | I43: 21.58 | J43: 45.39 | K43: 92.06 | M43: =J43/I43 -> 2.1033364 | N43: =K43/J43 -> 2.0282 | O43: =K43/I43 -> 4.265987 | Q43: =AVERAGE(M23:M42) -> 2.1014375 | R43: =AVERAGE(N23:N42) -> 2.0281503 | S43: =AVERAGE(O23:O42) -> 4.2620294 | U43: =AVERAGE(M3:M42) -> 2.1007357 | V43: =AVERAGE(N3:N42) -> 2.0290677 | W43: =AVERAGE(O3:O42) -> 4.2625333
A44: TRUE | B44: TRUE | C44: TRUE | E44: 45355 | F44: 45355 | G44: 45355 | I44: 21.52 | J44: 45.24 | K44: 91.78 | M44: =J44/I44 -> 2.1022305 | N44: =K44/J44 -> 2.0287356 | O44: =K44/I44 -> 4.2648699 | Q44: =AVERAGE(M24:M43) -> 2.1015907 | R44: =AVERAGE(N24:N43) -> 2.0280805 | S44: =AVERAGE(O24:O43) -> 4.2621935 | U44: =AVERAGE(M4:M43) -> 2.1008384 | V44: =AVERAGE(N4:N43) -> 2.0290084 | W44: =AVERAGE(O4:O43) -> 4.2626172
A45: TRUE | B45: TRUE | C45: TRUE | E45: 45356 | F45: 45356 | G45: 45356 | I45: 21.68 | J45: 45.58 | K45: 92.45 | M45: =J45/I45 -> 2.1023985 | N45: =K45/J45 -> 2.0283019 | O45: =K45/I45 -> 4.2642989 | Q45: =AVERAGE(M25:M44) -> 2.1017297 | R45: =AVERAGE(N25:N44) -> 2.0279893 | S45: =AVERAGE(O25:O44) -> 4.262284 | U45: =AVERAGE(M5:M44) -> 2.1008736 | V45: =AVERAGE(N5:N44) -> 2.0289305 | W45: =AVERAGE(O5:O44) -> 4.2625249
A46: TRUE | B46: TRUE | C46: TRUE | E46: 45357 | F46: 45357 | G46: 45357 | I46: 21.71 | J46: 45.62 | K46: 92.6 | M46: =J46/I46 -> 2.1013358 | N46: =K46/J46 -> 2.0298115 | O46: =K46/I46 -> 4.2653155 | Q46: =AVERAGE(M26:M45) -> 2.1018566 | R46: =AVERAGE(N26:N45) -> 2.0278632 | S46: =AVERAGE(O26:O45) -> 4.2622765 | U46: =AVERAGE(M6:M45) -> 2.100945 | V46: =AVERAGE(N6:N45) -> 2.028857 | W46: =AVERAGE(O6:O45) -> 4.2625154
A47: TRUE | B47: TRUE | C47: TRUE | E47: 45358 | F47: 45358 | G47: 45358 | I47: 21.76 | J47: 45.72 | K47: 92.77 | M47: =J47/I47 -> 2.1011029 | N47: =K47/J47 -> 2.0290901 | O47: =K47/I47 -> 4.2633272 | Q47: =AVERAGE(M27:M46) -> 2.1020795 | R47: =AVERAGE(N27:N46) -> 2.0278539 | S47: =AVERAGE(O27:O46) -> 4.2627094 | U47: =AVERAGE(M7:M46) -> 2.1009556 | V47: =AVERAGE(N7:N46) -> 2.0288524 | W47: =AVERAGE(O7:O46) -> 4.2625273
A48: TRUE | B48: TRUE | C48: TRUE | E48: 45359 | F48: 45359 | G48: 45359 | I48: 21.81 | J48: 45.79 | K48: 92.93 | M48: =J48/I48 -> 2.0994956 | N48: =K48/J48 -> 2.0294824 | O48: =K48/I48 -> 4.2608895 | Q48: =AVERAGE(M28:M47) -> 2.1021323 | R48: =AVERAGE(N28:N47) -> 2.0278594 | S48: =AVERAGE(O28:O47) -> 4.2628283 | U48: =AVERAGE(M8:M47) -> 2.100982 | V48: =AVERAGE(N8:N47) -> 2.0288673 | W48: =AVERAGE(O8:O47) -> 4.262612
A49: TRUE | B49: TRUE | C49: TRUE | E49: 45362 | F49: 45362 | G49: 45362 | I49: 21.78 | J49: 45.75 | K49: 92.85 | M49: =J49/I49 -> 2.100551 | N49: =K49/J49 -> 2.0295082 | O49: =K49/I49 -> 4.2630854 | Q49: =AVERAGE(M29:M48) -> 2.1021441 | R49: =AVERAGE(N29:N48) -> 2.027904 | S49: =AVERAGE(O29:O48) -> 4.2629457 | U49: =AVERAGE(M9:M48) -> 2.1010128 | V49: =AVERAGE(N9:N48) -> 2.0288529 | W49: =AVERAGE(O9:O48) -> 4.2626443
A50: TRUE | B50: TRUE | C50: TRUE | E50: 45363 | F50: 45363 | G50: 45363 | I50: 21.74 | J50: 45.64 | K50: 92.56 | M50: =J50/I50 -> 2.099356 | N50: =K50/J50 -> 2.0280456 | O50: =K50/I50 -> 4.2575897 | Q50: =AVERAGE(M30:M49) -> 2.102063 | R50: =AVERAGE(N30:N49) -> 2.0280159 | S50: =AVERAGE(O30:O49) -> 4.2630163 | U50: =AVERAGE(M10:M49) -> 2.1010379 | V50: =AVERAGE(N10:N49) -> 2.0287949 | W50: =AVERAGE(O10:O49) -> 4.2625737
A51: TRUE | B51: TRUE | C51: TRUE | E51: 45364 | F51: 45364 | G51: 45364 | I51: 21.71 | J51: 45.59 | K51: 92.45 | M51: =J51/I51 -> 2.0999539 | N51: =K51/J51 -> 2.027857 | O51: =K51/I51 -> 4.2584063 | Q51: =AVERAGE(M31:M50) -> 2.1019915 | R51: =AVERAGE(N31:N50) -> 2.0280097 | S51: =AVERAGE(O31:O50) -> 4.2628584 | U51: =AVERAGE(M11:M50) -> 2.101015 | V51: =AVERAGE(N11:N50) -> 2.02874 | W51: =AVERAGE(O11:O50) -> 4.2624119
A52: TRUE | B52: TRUE | C52: TRUE | E52: 45365 | F52: 45365 | G52: 45365 | I52: 21.56 | J52: 45.24 | K52: 91.73 | M52: =J52/I52 -> 2.0983302 | N52: =K52/J52 -> 2.0276304 | O52: =K52/I52 -> 4.2546382 | Q52: =AVERAGE(M32:M51) -> 2.1019938 | R52: =AVERAGE(N32:N51) -> 2.0280242 | S52: =AVERAGE(O32:O51) -> 4.2628935 | U52: =AVERAGE(M12:M51) -> 2.1009967 | V52: =AVERAGE(N12:N51) -> 2.0287011 | W52: =AVERAGE(O12:O51) -> 4.2622931
A53: TRUE | B53: TRUE | C53: TRUE | E53: 45366 | F53: 45366 | G53: 45366 | I53: 21.51 | J53: 45.22 | K53: 91.67 | M53: =J53/I53 -> 2.102278 | N53: =K53/J53 -> 2.0272004 | O53: =K53/I53 -> 4.2617387 | Q53: =AVERAGE(M33:M52) -> 2.1017756 | R53: =AVERAGE(N33:N52) -> 2.0280024 | S53: =AVERAGE(O33:O52) -> 4.2624052 | U53: =AVERAGE(M13:M52) -> 2.1009262 | V53: =AVERAGE(N13:N52) -> 2.0285987 | W53: =AVERAGE(O13:O52) -> 4.2619349
... A60: TRUE | B60: TRUE | C60: TRUE | E60: 45377 | F60: 45377 | G60: 45377 | I60: 21.71 | J60: 45.66 | K60: 92.5 | M60: =J60/I60 -> 2.1031783 | N60: =K60/J60 -> 2.0258432 | O60: =K60/I60 -> 4.2607094 | Q60: =AVERAGE(M40:M59) -> 2.1015179 | R60: =AVERAGE(N40:N59) -> 2.028007 | S60: =AVERAGE(O40:O59) -> 4.2618927 | U60: =AVERAGE(M20:M59) -> 2.1012401 | V60: =AVERAGE(N20:N59) -> 2.0282377 | W60: =AVERAGE(O20:O59) -> 4.2618131
...

Sheet 20
AE1: =SUM(AE2:AE376) -> 11.78011 | AG1: =SUM(AG2:AG376) -> 187 | AH1: =SUM(AH2:AH376) -> 165 | AI1: =SUM(AI2:AI376) -> 188 | AK1: 21.26 | AL1: 10.12 | AM1: 5 | AO1: =AE1*1000 -> 11780.11 | AQ1: =SUM(P:P,R:R)*1000 -> 3887.6309
A2: ='ALL 3 2024+'!E254 -> 45659 | B2: ='ALL 3 2024+'!F254 -> 45659 | C2: ='ALL 3 2024+'!G254 -> 45659 | E2: ='ALL 3 2024+'!I254 -> 21.54 | F2: ='ALL 3 2024+'!J254 -> 45.28 | G2: ='ALL 3 2024+'!K254 -> 91.6 | I2: ='ALL 3 2024+'!Q254 -> 2.1017891 | J2: ='ALL 3 2024+'!R254 -> 2.0229102 | K2: ='ALL 3 2024+'!S254 -> 4.2517273 | M2: =E2*K2 -> 91.582206 | N2: =J2*F2 -> 91.597376 | O2: =G2 -> 91.6 | Q2: =MAX(M2:O2)-MIN(M2:O2) -> 0.017794042 | W2: =IF(M2=MAX($M2:$O2),-1,IF(M2=MIN($M2:$O2),1,0)) -> 1 | X2: =IF(N2=MAX($M2:$O2),-1,IF(N2=MIN($M2:$O2),1,0)) -> 0 | Y2: =IF(O2=MAX($M2:$O2),-1,IF(O2=MIN($M2:$O2),1,0)) -> -1 | AG2: =ABS(W2-W1) -> 1 | AH2: =ABS(X2-X1) -> 0 | AI2: =ABS(Y2-Y1) -> 1 | AK2: =AK1*AG1 -> 3975.62 | AL2: =AL1*AH1 -> 1669.8 | AM2: =AM1*AI1 -> 940
A3: ='ALL 3 2024+'!E255 -> 45660 | B3: ='ALL 3 2024+'!F255 -> 45660 | C3: ='ALL 3 2024+'!G255 -> 45660 | E3: ='ALL 3 2024+'!I255 -> 21.48 | F3: ='ALL 3 2024+'!J255 -> 45.24 | G3: ='ALL 3 2024+'!K255 -> 91.48 | I3: ='ALL 3 2024+'!Q255 -> 2.1018229 | J3: ='ALL 3 2024+'!R255 -> 2.0228689 | K3: ='ALL 3 2024+'!S255 -> 4.2517089 | M3: =E3*K3 -> 91.326708 | N3: =J3*F3 -> 91.514591 | O3: =G3 -> 91.48 | Q3: =MAX(M3:O3)-MIN(M3:O3) -> 0.18788341 | S3: =M3-M2 -> -0.25549832 | T3: =N3-N2 -> -0.082784474 | U3: =O3-O2 -> -0.12 | W3: =IF(M3=MAX($M3:$O3),-1,IF(M3=MIN($M3:$O3),1,0)) -> 1 | X3: =IF(N3=MAX($M3:$O3),-1,IF(N3=MIN($M3:$O3),1,0)) -> -1 | Y3: =IF(O3=MAX($M3:$O3),-1,IF(O3=MIN($M3:$O3),1,0)) -> 0 | AA3: =W2*S3 -> -0.25549832 | AB3: =X2*T3 -> 0 | AC3: =Y2*U3 -> 0.12 | AE3: =SUM(AA3:AC3) -> -0.13549832 | AG3: =ABS(W3-W2) -> 0 | AH3: =ABS(X3-X2) -> 1 | AI3: =ABS(Y3-Y2) -> 1 | AM3: =SUM(AK2:AM2) -> 6585.42 | AO3: =AO1-AM3 -> 5194.69
A4: ='ALL 3 2024+'!E256 -> 45663 | B4: ='ALL 3 2024+'!F256 -> 45663 | C4: ='ALL 3 2024+'!G256 -> 45663 | E4: ='ALL 3 2024+'!I256 -> 21.47 | F4: ='ALL 3 2024+'!J256 -> 45.19 | G4: ='ALL 3 2024+'!K256 -> 91.38 | I4: ='ALL 3 2024+'!Q256 -> 2.1024223 | J4: ='ALL 3 2024+'!R256 -> 2.0227099 | K4: ='ALL 3 2024+'!S256 -> 4.2525876 | M4: =E4*K4 -> 91.303055 | N4: =J4*F4 -> 91.406262 | O4: =G4 -> 91.38 | Q4: =MAX(M4:O4)-MIN(M4:O4) -> 0.10320621 | S4: =M4-M3 -> -0.023652349 | T4: =N4-N3 -> -0.10832955 | U4: =O4-O3 -> -0.1 | W4: =IF(M4=MAX($M4:$O4),-1,IF(M4=MIN($M4:$O4),1,0)) -> 1 | X4: =IF(N4=MAX($M4:$O4),-1,IF(N4=MIN($M4:$O4),1,0)) -> -1 | Y4: =IF(O4=MAX($M4:$O4),-1,IF(O4=MIN($M4:$O4),1,0)) -> 0 | AA4: =W3*S4 -> -0.023652349 | AB4: =X3*T4 -> 0.10832955 | AC4: =Y3*U4 -> 0 | AE4: =SUM(AA4:AC4) -> 0.084677201 | AG4: =ABS(W4-W3) -> 0 | AH4: =ABS(X4-X3) -> 0 | AI4: =ABS(Y4-Y3) -> 0 | AO4: 32000
A5: ='ALL 3 2024+'!E257 -> 45664 | B5: ='ALL 3 2024+'!F257 -> 45664 | C5: ='ALL 3 2024+'!G257 -> 45664 | E5: ='ALL 3 2024+'!I257 -> 21.38 | F5: ='ALL 3 2024+'!J257 -> 45.06 | G5: ='ALL 3 2024+'!K257 -> 91.12 | I5: ='ALL 3 2024+'!Q257 -> 2.1027307 | J5: ='ALL 3 2024+'!R257 -> 2.0225528 | K5: ='ALL 3 2024+'!S257 -> 4.2528811 | M5: =E5*K5 -> 90.926598 | N5: =J5*F5 -> 91.136228 | O5: =G5 -> 91.12 | Q5: =MAX(M5:O5)-MIN(M5:O5) -> 0.20963004 | S5: =M5-M4 -> -0.37645766 | T5: =N5-N4 -> -0.27003384 | U5: =O5-O4 -> -0.26 | W5: =IF(M5=MAX($M5:$O5),-1,IF(M5=MIN($M5:$O5),1,0)) -> 1 | X5: =IF(N5=MAX($M5:$O5),-1,IF(N5=MIN($M5:$O5),1,0)) -> -1 | Y5: =IF(O5=MAX($M5:$O5),-1,IF(O5=MIN($M5:$O5),1,0)) -> 0 | AA5: =W4*S5 -> -0.37645766 | AB5: =X4*T5 -> 0.27003384 | AC5: =Y4*U5 -> 0 | AE5: =SUM(AA5:AC5) -> -0.10642383 | AG5: =ABS(W5-W4) -> 0 | AH5: =ABS(X5-X4) -> 0 | AI5: =ABS(Y5-Y4) -> 0 | AO5: =+AO3/AO4 -> 0.16233406
A6: ='ALL 3 2024+'!E258 -> 45665 | B6: ='ALL 3 2024+'!F258 -> 45665 | C6: ='ALL 3 2024+'!G258 -> 45665 | E6: ='ALL 3 2024+'!I258 -> 21.4 | F6: ='ALL 3 2024+'!J258 -> 45.08 | G6: ='ALL 3 2024+'!K258 -> 91.17 | I6: ='ALL 3 2024+'!Q258 -> 2.1031477 | J6: ='ALL 3 2024+'!R258 -> 2.0224725 | K6: ='ALL 3 2024+'!S258 -> 4.2535558 | M6: =E6*K6 -> 91.026095 | N6: =J6*F6 -> 91.173062 | O6: =G6 -> 91.17 | Q6: =MAX(M6:O6)-MIN(M6:O6) -> 0.14696762 | S6: =M6-M5 -> 0.099497021 | T6: =N6-N5 -> 0.036834601 | U6: =O6-O5 -> 0.05 | W6: =IF(M6=MAX($M6:$O6),-1,IF(M6=MIN($M6:$O6),1,0)) -> 1 | X6: =IF(N6=MAX($M6:$O6),-1,IF(N6=MIN($M6:$O6),1,0)) -> -1 | Y6: =IF(O6=MAX($M6:$O6),-1,IF(O6=MIN($M6:$O6),1,0)) -> 0 | AA6: =W5*S6 -> 0.099497021 | AB6: =X5*T6 -> -0.036834601 | AC6: =Y5*U6 -> 0 | AE6: =SUM(AA6:AC6) -> 0.062662421 | AG6: =ABS(W6-W5) -> 0 | AH6: =ABS(X6-X5) -> 0 | AI6: =ABS(Y6-Y5) -> 0 | AK6: 0.15 | AL6: 0.15 | AM6: 0.15
A7: ='ALL 3 2024+'!E259 -> 45667 | B7: ='ALL 3 2024+'!F259 -> 45667 | C7: ='ALL 3 2024+'!G259 -> 45667 | E7: ='ALL 3 2024+'!I259 -> 21.28 | F7: ='ALL 3 2024+'!J259 -> 44.77 | G7: ='ALL 3 2024+'!K259 -> 90.52 | I7: ='ALL 3 2024+'!Q259 -> 2.1036246 | J7: ='ALL 3 2024+'!R259 -> 2.0223596 | K7: ='ALL 3 2024+'!S259 -> 4.2542834 | M7: =E7*K7 -> 90.531151 | N7: =J7*F7 -> 90.541041 | O7: =G7 -> 90.52 | P7: =M7-M3 -> -0.79555645 | Q7: =MAX(M7:O7)-MIN(M7:O7) -> 0.021041333 | R7: =N3-N7 -> 0.97354972 | S7: =M7-M6 -> -0.49494346 | T7: =N7-N6 -> -0.63202093 | U7: =O7-O6 -> -0.65 | W7: =IF(M7=MAX($M7:$O7),-1,IF(M7=MIN($M7:$O7),1,0)) -> 0 | X7: =IF(N7=MAX($M7:$O7),-1,IF(N7=MIN($M7:$O7),1,0)) -> -1 | Y7: =IF(O7=MAX($M7:$O7),-1,IF(O7=MIN($M7:$O7),1,0)) -> 1 | AA7: =W6*S7 -> -0.49494346 | AB7: =X6*T7 -> 0.63202093 | AC7: =Y6*U7 -> 0 | AE7: =SUM(AA7:AC7) -> 0.13707747 | AG7: =ABS(W7-W6) -> 1 | AH7: =ABS(X7-X6) -> 0 | AI7: =ABS(Y7-Y6) -> 1 | AM7: =AM6*O2*1000 -> 13740
A8: ='ALL 3 2024+'!E260 -> 45670 | B8: ='ALL 3 2024+'!F260 -> 45670 | C8: ='ALL 3 2024+'!G260 -> 45670 | E8: ='ALL 3 2024+'!I260 -> 21.23 | F8: ='ALL 3 2024+'!J260 -> 44.68 | G8: ='ALL 3 2024+'!K260 -> 90.37 | I8: ='ALL 3 2024+'!Q260 -> 2.1039307 | J8: ='ALL 3 2024+'!R260 -> 2.0221463 | K8: ='ALL 3 2024+'!S260 -> 4.2544545 | M8: =E8*K8 -> 90.32207 | N8: =J8*F8 -> 90.349498 | O8: =G8 -> 90.37 | Q8: =MAX(M8:O8)-MIN(M8:O8) -> 0.047929914 | S8: =M8-M7 -> -0.2090811 | T8: =N8-N7 -> -0.19154348 | U8: =O8-O7 -> -0.15 | W8: =IF(M8=MAX($M8:$O8),-1,IF(M8=MIN($M8:$O8),1,0)) -> 1 | X8: =IF(N8=MAX($M8:$O8),-1,IF(N8=MIN($M8:$O8),1,0)) -> 0 | Y8: =IF(O8=MAX($M8:$O8),-1,IF(O8=MIN($M8:$O8),1,0)) -> -1 | AA8: =W7*S8 -> 0 | AB8: =X7*T8 -> 0.19154348 | AC8: =Y7*U8 -> -0.15 | AE8: =SUM(AA8:AC8) -> 0.041543478 | AG8: =ABS(W8-W7) -> 1 | AH8: =ABS(X8-X7) -> 1 | AI8: =ABS(Y8-Y7) -> 2
A9: ='ALL 3 2024+'!E261 -> 45671 | B9: ='ALL 3 2024+'!F261 -> 45671 | C9: ='ALL 3 2024+'!G261 -> 45671 | E9: ='ALL 3 2024+'!I261 -> 21.25 | F9: ='ALL 3 2024+'!J261 -> 44.77 | G9: ='ALL 3 2024+'!K261 -> 90.46 | I9: ='ALL 3 2024+'!Q261 -> 2.1042959 | J9: ='ALL 3 2024+'!R261 -> 2.0220282 | K9: ='ALL 3 2024+'!S261 -> 4.2549451 | M9: =E9*K9 -> 90.417584 | N9: =J9*F9 -> 90.5262 | O9: =G9 -> 90.46 | Q9: =MAX(M9:O9)-MIN(M9:O9) -> 0.10861591 | S9: =M9-M8 -> 0.095514337 | T9: =N9-N8 -> 0.17670248 | U9: =O9-O8 -> 0.09 | W9: =IF(M9=MAX($M9:$O9),-1,IF(M9=MIN($M9:$O9),1,0)) -> 1 | X9: =IF(N9=MAX($M9:$O9),-1,IF(N9=MIN($M9:$O9),1,0)) -> -1 | Y9: =IF(O9=MAX($M9:$O9),-1,IF(O9=MIN($M9:$O9),1,0)) -> 0 | AA9: =W8*S9 -> 0.095514337 | AB9: =X8*T9 -> 0 | AC9: =Y8*U9 -> -0.09 | AE9: =SUM(AA9:AC9) -> 0.0055143375 | AG9: =ABS(W9-W8) -> 0 | AH9: =ABS(X9-X8) -> 1 | AI9: =ABS(Y9-Y8) -> 1
A10: ='ALL 3 2024+'!E262 -> 45672 | B10: ='ALL 3 2024+'!F262 -> 45672 | C10: ='ALL 3 2024+'!G262 -> 45672 | E10: ='ALL 3 2024+'!I262 -> 21.48 | F10: ='ALL 3 2024+'!J262 -> 45.2 | G10: ='ALL 3 2024+'!K262 -> 91.41 | I10: ='ALL 3 2024+'!Q262 -> 2.1046566 | J10: ='ALL 3 2024+'!R262 -> 2.0218707 | K10: ='ALL 3 2024+'!S262 -> 4.2553433 | M10: =E10*K10 -> 91.404773 | N10: =J10*F10 -> 91.388556 | O10: =G10 -> 91.41 | Q10: =MAX(M10:O10)-MIN(M10:O10) -> 0.021443951 | S10: =M10-M9 -> 0.9871886 | T10: =N10-N9 -> 0.86235571 | U10: =O10-O9 -> 0.95 | W10: =IF(M10=MAX($M10:$O10),-1,IF(M10=MIN($M10:$O10),1,0)) -> 0 | X10: =IF(N10=MAX($M10:$O10),-1,IF(N10=MIN($M10:$O10),1,0)) -> 1 | Y10: =IF(O10=MAX($M10:$O10),-1,IF(O10=MIN($M10:$O10),1,0)) -> -1 | AA10: =W9*S10 -> 0.9871886 | AB10: =X9*T10 -> -0.86235571 | AC10: =Y9*U10 -> 0 | AE10: =SUM(AA10:AC10) -> 0.12483288 | AG10: =ABS(W10-W9) -> 1 | AH10: =ABS(X10-X9) -> 2 | AI10: =ABS(Y10-Y9) -> 1
A11: ='ALL 3 2024+'!E263 -> 45673 | B11: ='ALL 3 2024+'!F263 -> 45673 | C11: ='ALL 3 2024+'!G263 -> 45673 | E11: ='ALL 3 2024+'!I263 -> 21.51 | F11: ='ALL 3 2024+'!J263 -> 45.31 | G11: ='ALL 3 2024+'!K263 -> 91.66 | I11: ='ALL 3 2024+'!Q263 -> 2.1046831 | J11: ='ALL 3 2024+'!R263 -> 2.021984 | K11: ='ALL 3 2024+'!S263 -> 4.255635 | M11: =E11*K11 -> 91.538708 | N11: =J11*F11 -> 91.616094 | O11: =G11 -> 91.66 | Q11: =MAX(M11:O11)-MIN(M11:O11) -> 0.12129185 | S11: =M11-M10 -> 0.13393513 | T11: =N11-N10 -> 0.22753756 | U11: =O11-O10 -> 0.25 | W11: =IF(M11=MAX($M11:$O11),-1,IF(M11=MIN($M11:$O11),1,0)) -> 1 | X11: =IF(N11=MAX($M11:$O11),-1,IF(N11=MIN($M11:$O11),1,0)) -> 0 | Y11: =IF(O11=MAX($M11:$O11),-1,IF(O11=MIN($M11:$O11),1,0)) -> -1 | AA11: =W10*S11 -> 0 | AB11: =X10*T11 -> 0.22753756 | AC11: =Y10*U11 -> -0.25 | AE11: =SUM(AA11:AC11) -> -0.022462443 | AG11: =ABS(W11-W10) -> 1 | AH11: =ABS(X11-X10) -> 1 | AI11: =ABS(Y11-Y10) -> 0
A12: ='ALL 3 2024+'!E264 -> 45674 | B12: ='ALL 3 2024+'!F264 -> 45674 | C12: ='ALL 3 2024+'!G264 -> 45674 | E12: ='ALL 3 2024+'!I264 -> 21.51 | F12: ='ALL 3 2024+'!J264 -> 45.31 | G12: ='ALL 3 2024+'!K264 -> 91.59 | I12: ='ALL 3 2024+'!Q264 -> 2.1050296 | J12: ='ALL 3 2024+'!R264 -> 2.0220266 | K12: ='ALL 3 2024+'!S264 -> 4.2564256 | M12: =E12*K12 -> 91.555714 | N12: =J12*F12 -> 91.618026 | O12: =G12 -> 91.59 | Q12: =MAX(M12:O12)-MIN(M12:O12) -> 0.062311187 | S12: =M12-M11 -> 0.017006307 | T12: =N12-N11 -> 0.0019320415 | U12: =O12-O11 -> -0.07 | W12: =IF(M12=MAX($M12:$O12),-1,IF(M12=MIN($M12:$O12),1,0)) -> 1 | X12: =IF(N12=MAX($M12:$O12),-1,IF(N12=MIN($M12:$O12),1,0)) -> -1 | Y12: =IF(O12=MAX($M12:$O12),-1,IF(O12=MIN($M12:$O12),1,0)) -> 0 | AA12: =W11*S12 -> 0.017006307 | AB12: =X11*T12 -> 0 | AC12: =Y11*U12 -> 0.07 | AE12: =SUM(AA12:AC12) -> 0.087006307 | AG12: =ABS(W12-W11) -> 0 | AH12: =ABS(X12-X11) -> 1 | AI12: =ABS(Y12-Y11) -> 1
A13: ='ALL 3 2024+'!E265 -> 45678 | B13: ='ALL 3 2024+'!F265 -> 45678 | C13: ='ALL 3 2024+'!G265 -> 45678 | E13: ='ALL 3 2024+'!I265 -> 21.59 | F13: ='ALL 3 2024+'!J265 -> 45.46 | G13: ='ALL 3 2024+'!K265 -> 91.92 | I13: ='ALL 3 2024+'!Q265 -> 2.1053188 | J13: ='ALL 3 2024+'!R265 -> 2.0220415 | K13: ='ALL 3 2024+'!S265 -> 4.2570415 | M13: =E13*K13 -> 91.909526 | N13: =J13*F13 -> 91.922007 | O13: =G13 -> 91.92 | Q13: =MAX(M13:O13)-MIN(M13:O13) -> 0.012480888 | S13: =M13-M12 -> 0.35381131 | T13: =N13-N12 -> 0.30398101 | U13: =O13-O12 -> 0.33 | W13: =IF(M13=MAX($M13:$O13),-1,IF(M13=MIN($M13:$O13),1,0)) -> 1 | X13: =IF(N13=MAX($M13:$O13),-1,IF(N13=MIN($M13:$O13),1,0)) -> -1 | Y13: =IF(O13=MAX($M13:$O13),-1,IF(O13=MIN($M13:$O13),1,0)) -> 0 | AA13: =W12*S13 -> 0.35381131 | AB13: =X12*T13 -> -0.30398101 | AC13: =Y12*U13 -> 0 | AE13: =SUM(AA13:AC13) -> 0.0498303 | AG13: =ABS(W13-W12) -> 0 | AH13: =ABS(X13-X12) -> 0 | AI13: =ABS(Y13-Y12) -> 0
A14: ='ALL 3 2024+'!E266 -> 45679 | B14: ='ALL 3 2024+'!F266 -> 45679 | C14: ='ALL 3 2024+'!G266 -> 45679 | E14: ='ALL 3 2024+'!I266 -> 21.55 | F14: ='ALL 3 2024+'!J266 -> 45.36 | G14: ='ALL 3 2024+'!K266 -> 91.77 | I14: ='ALL 3 2024+'!Q266 -> 2.1053356 | J14: ='ALL 3 2024+'!R266 -> 2.0220389 | K14: ='ALL 3 2024+'!S266 -> 4.25707 | M14: =E14*K14 -> 91.739859 | N14: =J14*F14 -> 91.719685 | O14: =G14 -> 91.77 | Q14: =MAX(M14:O14)-MIN(M14:O14) -> 0.050315269 | S14: =M14-M13 -> -0.16966667 | T14: =N14-N13 -> -0.20232193 | U14: =O14-O13 -> -0.15 | W14: =IF(M14=MAX($M14:$O14),-1,IF(M14=MIN($M14:$O14),1,0)) -> 0 | X14: =IF(N14=MAX($M14:$O14),-1,IF(N14=MIN($M14:$O14),1,0)) -> 1 | Y14: =IF(O14=MAX($M14:$O14),-1,IF(O14=MIN($M14:$O14),1,0)) -> -1 | AA14: =W13*S14 -> -0.16966667 | AB14: =X13*T14 -> 0.20232193 | AC14: =Y13*U14 -> 0 | AE14: =SUM(AA14:AC14) -> 0.032655259 | AG14: =ABS(W14-W13) -> 1 | AH14: =ABS(X14-X13) -> 2 | AI14: =ABS(Y14-Y13) -> 1
A15: ='ALL 3 2024+'!E267 -> 45680 | B15: ='ALL 3 2024+'!F267 -> 45680 | C15: ='ALL 3 2024+'!G267 -> 45680 | E15: ='ALL 3 2024+'!I267 -> 21.48 | F15: ='ALL 3 2024+'!J267 -> 45.26 | G15: ='ALL 3 2024+'!K267 -> 91.53 | I15: ='ALL 3 2024+'!Q267 -> 2.1053099 | J15: ='ALL 3 2024+'!R267 -> 2.0221005 | K15: ='ALL 3 2024+'!S267 -> 4.2571477 | M15: =E15*K15 -> 91.443533 | N15: =J15*F15 -> 91.52027 | O15: =G15 -> 91.53 | Q15: =MAX(M15:O15)-MIN(M15:O15) -> 0.086466745 | S15: =M15-M14 -> -0.29632585 | T15: =N15-N14 -> -0.19941476 | U15: =O15-O14 -> -0.24 | W15: =IF(M15=MAX($M15:$O15),-1,IF(M15=MIN($M15:$O15),1,0)) -> 1 | X15: =IF(N15=MAX($M15:$O15),-1,IF(N15=MIN($M15:$O15),1,0)) -> 0 | Y15: =IF(O15=MAX($M15:$O15),-1,IF(O15=MIN($M15:$O15),1,0)) -> -1 | AA15: =W14*S15 -> 0 | AB15: =X14*T15 -> -0.19941476 | AC15: =Y14*U15 -> 0.24 | AE15: =SUM(AA15:AC15) -> 0.04058524 | AG15: =ABS(W15-W14) -> 1 | AH15: =ABS(X15-X14) -> 1 | AI15: =ABS(Y15-Y14) -> 0
A16: ='ALL 3 2024+'!E268 -> 45681 | B16: ='ALL 3 2024+'!F268 -> 45681 | C16: ='ALL 3 2024+'!G268 -> 45681 | E16: ='ALL 3 2024+'!I268 -> 21.52 | F16: ='ALL 3 2024+'!J268 -> 45.32 | G16: ='ALL 3 2024+'!K268 -> 91.65 | I16: ='ALL 3 2024+'!Q268 -> 2.1054028 | J16: ='ALL 3 2024+'!R268 -> 2.0221118 | K16: ='ALL 3 2024+'!S268 -> 4.2573596 | M16: =E16*K16 -> 91.618379 | N16: =J16*F16 -> 91.642109 | O16: =G16 -> 91.65 | Q16: =MAX(M16:O16)-MIN(M16:O16) -> 0.031621479 | S16: =M16-M15 -> 0.17484527 | T16: =N16-N15 -> 0.12183882 | U16: =O16-O15 -> 0.12 | W16: =IF(M16=MAX($M16:$O16),-1,IF(M16=MIN($M16:$O16),1,0)) -> 1 | X16: =IF(N16=MAX($M16:$O16),-1,IF(N16=MIN($M16:$O16),1,0)) -> 0 | Y16: =IF(O16=MAX($M16:$O16),-1,IF(O16=MIN($M16:$O16),1,0)) -> -1 | AA16: =W15*S16 -> 0.17484527 | AB16: =X15*T16 -> 0 | AC16: =Y15*U16 -> -0.12 | AE16: =SUM(AA16:AC16) -> 0.054845265 | AG16: =ABS(W16-W15) -> 0 | AH16: =ABS(X16-X15) -> 0 | AI16: =ABS(Y16-Y15) -> 0
A17: ='ALL 3 2024+'!E269 -> 45684 | B17: ='ALL 3 2024+'!F269 -> 45684 | C17: ='ALL 3 2024+'!G269 -> 45684 | E17: ='ALL 3 2024+'!I269 -> 21.66 | F17: ='ALL 3 2024+'!J269 -> 45.58 | G17: ='ALL 3 2024+'!K269 -> 92.17 | I17: ='ALL 3 2024+'!Q269 -> 2.1054301 | J17: ='ALL 3 2024+'!R269 -> 2.0221206 | K17: ='ALL 3 2024+'!S269 -> 4.2574331 | M17: =E17*K17 -> 92.216 | N17: =J17*F17 -> 92.168255 | O17: =G17 -> 92.17 | Q17: =MAX(M17:O17)-MIN(M17:O17) -> 0.047745532 | S17: =M17-M16 -> 0.5976217 | T17: =N17-N16 -> 0.5261459 | U17: =O17-O16 -> 0.52 | W17: =IF(M17=MAX($M17:$O17),-1,IF(M17=MIN($M17:$O17),1,0)) -> -1 | X17: =IF(N17=MAX($M17:$O17),-1,IF(N17=MIN($M17:$O17),1,0)) -> 1 | Y17: =IF(O17=MAX($M17:$O17),-1,IF(O17=MIN($M17:$O17),1,0)) -> 0 | AA17: =W16*S17 -> 0.5976217 | AB17: =X16*T17 -> 0 | AC17: =Y16*U17 -> -0.52 | AE17: =SUM(AA17:AC17) -> 0.077621703 | AG17: =ABS(W17-W16) -> 2 | AH17: =ABS(X17-X16) -> 1 | AI17: =ABS(Y17-Y16) -> 1
A18: ='ALL 3 2024+'!E270 -> 45685 | B18: ='ALL 3 2024+'!F270 -> 45685 | C18: ='ALL 3 2024+'!G270 -> 45685 | E18: ='ALL 3 2024+'!I270 -> 21.66 | F18: ='ALL 3 2024+'!J270 -> 45.55 | G18: ='ALL 3 2024+'!K270 -> 92.17 | I18: ='ALL 3 2024+'!Q270 -> 2.1053557 | J18: ='ALL 3 2024+'!R270 -> 2.0221658 | K18: ='ALL 3 2024+'!S270 -> 4.257378 | M18: =E18*K18 -> 92.214808 | N18: =J18*F18 -> 92.109654 | O18: =G18 -> 92.17 | Q18: =MAX(M18:O18)-MIN(M18:O18) -> 0.10515389 | S18: =M18-M17 -> -0.0011923077 | T18: =N18-N17 -> -0.058600663 | U18: =O18-O17 -> 0 | W18: =IF(M18=MAX($M18:$O18),-1,IF(M18=MIN($M18:$O18),1,0)) -> -1 | X18: =IF(N18=MAX($M18:$O18),-1,IF(N18=MIN($M18:$O18),1,0)) -> 1 | Y18: =IF(O18=MAX($M18:$O18),-1,IF(O18=MIN($M18:$O18),1,0)) -> 0 | AA18: =W17*S18 -> 0.0011923077 | AB18: =X17*T18 -> -0.058600663 | AC18: =Y17*U18 -> 0 | AE18: =SUM(AA18:AC18) -> -0.057408355 | AG18: =ABS(W18-W17) -> 0 | AH18: =ABS(X18-X17) -> 0 | AI18: =ABS(Y18-Y17) -> 0
A19: ='ALL 3 2024+'!E271 -> 45686 | B19: ='ALL 3 2024+'!F271 -> 45686 | C19: ='ALL 3 2024+'!G271 -> 45686 | E19: ='ALL 3 2024+'!I271 -> 21.67 | F19: ='ALL 3 2024+'!J271 -> 45.6 | G19: ='ALL 3 2024+'!K271 -> 92.2 | I19: ='ALL 3 2024+'!Q271 -> 2.1052942 | J19: ='ALL 3 2024+'!R271 -> 2.0222352 | K19: ='ALL 3 2024+'!S271 -> 4.2573993 | M19: =E19*K19 -> 92.257843 | N19: =J19*F19 -> 92.213923 | O19: =G19 -> 92.2 | Q19: =MAX(M19:O19)-MIN(M19:O19) -> 0.057842839 | S19: =M19-M18 -> 0.043034923 | T19: =N19-N18 -> 0.10426914 | U19: =O19-O18 -> 0.03 | W19: =IF(M19=MAX($M19:$O19),-1,IF(M19=MIN($M19:$O19),1,0)) -> -1 | X19: =IF(N19=MAX($M19:$O19),-1,IF(N19=MIN($M19:$O19),1,0)) -> 0 | Y19: =IF(O19=MAX($M19:$O19),-1,IF(O19=MIN($M19:$O19),1,0)) -> 1 | AA19: =W18*S19 -> -0.043034923 | AB19: =X18*T19 -> 0.10426914 | AC19: =Y18*U19 -> 0 | AE19: =SUM(AA19:AC19) -> 0.061234217 | AG19: =ABS(W19-W18) -> 0 | AH19: =ABS(X19-X18) -> 1 | AI19: =ABS(Y19-Y18) -> 1
A20: ='ALL 3 2024+'!E272 -> 45687 | B20: ='ALL 3 2024+'!F272 -> 45687 | C20: ='ALL 3 2024+'!G272 -> 45687 | E20: ='ALL 3 2024+'!I272 -> 21.69 | F20: ='ALL 3 2024+'!J272 -> 45.64 | G20: ='ALL 3 2024+'!K272 -> 92.33 | I20: ='ALL 3 2024+'!Q272 -> 2.1051033 | J20: ='ALL 3 2024+'!R272 -> 2.0222706 | K20: ='ALL 3 2024+'!S272 -> 4.2570883 | M20: =E20*K20 -> 92.336245 | N20: =J20*F20 -> 92.296432 | O20: =G20 -> 92.33 | Q20: =MAX(M20:O20)-MIN(M20:O20) -> 0.039812591 | S20: =M20-M19 -> 0.078401784 | T20: =N20-N19 -> 0.082508863 | U20: =O20-O19 -> 0.13 | W20: =IF(M20=MAX($M20:$O20),-1,IF(M20=MIN($M20:$O20),1,0)) -> -1 | X20: =IF(N20=MAX($M20:$O20),-1,IF(N20=MIN($M20:$O20),1,0)) -> 1 | Y20: =IF(O20=MAX($M20:$O20),-1,IF(O20=MIN($M20:$O20),1,0)) -> 0 | AA20: =W19*S20 -> -0.078401784 | AB20: =X19*T20 -> 0 | AC20: =Y19*U20 -> 0.13 | AE20: =SUM(AA20:AC20) -> 0.051598216 | AG20: =ABS(W20-W19) -> 0 | AH20: =ABS(X20-X19) -> 1 | AI20: =ABS(Y20-Y19) -> 1
A21: ='ALL 3 2024+'!E273 -> 45688 | B21: ='ALL 3 2024+'!F273 -> 45688 | C21: ='ALL 3 2024+'!G273 -> 45688 | E21: ='ALL 3 2024+'!I273 -> 21.63 | F21: ='ALL 3 2024+'!J273 -> 45.6 | G21: ='ALL 3 2024+'!K273 -> 92.19 | I21: ='ALL 3 2024+'!Q273 -> 2.1051439 | J21: ='ALL 3 2024+'!R273 -> 2.0222969 | K21: ='ALL 3 2024+'!S273 -> 4.2572255 | M21: =E21*K21 -> 92.083787 | N21: =J21*F21 -> 92.216737 | O21: =G21 -> 92.19 | Q21: =MAX(M21:O21)-MIN(M21:O21) -> 0.1329499 | S21: =M21-M20 -> -0.25245787 | T21: =N21-N20 -> -0.079695379 | U21: =O21-O20 -> -0.14 | W21: 0 | X21: 0 | Y21: 0 | AA21: =W20*S21 -> 0.25245787 | AB21: =X20*T21 -> -0.079695379 | AC21: =Y20*U21 -> 0 | AE21: =SUM(AA21:AC21) -> 0.17276249 | AG21: =ABS(W21-W20) -> 1 | AH21: =ABS(X21-X20) -> 1 | AI21: =ABS(Y21-Y20) -> 0
A22: ='ALL 3 2024+'!E274 -> 45691 | B22: ='ALL 3 2024+'!F274 -> 45691 | C22: ='ALL 3 2024+'!G274 -> 45691 | E22: ='ALL 3 2024+'!I274 -> 21.58 | F22: ='ALL 3 2024+'!J274 -> 45.45 | G22: ='ALL 3 2024+'!K274 -> 91.8 | I22: ='ALL 3 2024+'!Q274 -> 2.1053558 | J22: ='ALL 3 2024+'!R274 -> 2.0222796 | K22: ='ALL 3 2024+'!S274 -> 4.2576176 | M22: =E22*K22 -> 91.879389 | N22: =J22*F22 -> 91.912608 | O22: =G22 -> 91.8 | Q22: =MAX(M22:O22)-MIN(M22:O22) -> 0.11260799 | S22: =M22-M21 -> -0.20439805 | T22: =N22-N21 -> -0.30412866 | U22: =O22-O21 -> -0.39 | W22: =IF(M22=MAX($M22:$O22),-1,IF(M22=MIN($M22:$O22),1,0)) -> 0 | X22: =IF(N22=MAX($M22:$O22),-1,IF(N22=MIN($M22:$O22),1,0)) -> -1 | Y22: =IF(O22=MAX($M22:$O22),-1,IF(O22=MIN($M22:$O22),1,0)) -> 1 | AA22: =W21*S22 -> 0 | AB22: =X21*T22 -> 0 | AC22: =Y21*U22 -> 0 | AE22: =SUM(AA22:AC22) -> 0 | AG22: =ABS(W22-W21) -> 0 | AH22: =ABS(X22-X21) -> 1 | AI22: =ABS(Y22-Y21) -> 1
A23: ='ALL 3 2024+'!E275 -> 45692 | B23: ='ALL 3 2024+'!F275 -> 45692 | C23: ='ALL 3 2024+'!G275 -> 45692 | E23: ='ALL 3 2024+'!I275 -> 21.61 | F23: ='ALL 3 2024+'!J275 -> 45.49 | G23: ='ALL 3 2024+'!K275 -> 91.97 | I23: ='ALL 3 2024+'!Q275 -> 2.1055549 | J23: ='ALL 3 2024+'!R275 -> 2.0221213 | K23: ='ALL 3 2024+'!S275 -> 4.2576869 | M23: =E23*K23 -> 92.008614 | N23: =J23*F23 -> 91.986298 | O23: =G23 -> 91.97 | Q23: =MAX(M23:O23)-MIN(M23:O23) -> 0.038614206 | S23: =M23-M22 -> 0.1292255 | T23: =N23-N22 -> 0.073689622 | U23: =O23-O22 -> 0.17 | W23: =IF(M23=MAX($M23:$O23),-1,IF(M23=MIN($M23:$O23),1,0)) -> -1 | X23: =IF(N23=MAX($M23:$O23),-1,IF(N23=MIN($M23:$O23),1,0)) -> 0 | Y23: =IF(O23=MAX($M23:$O23),-1,IF(O23=MIN($M23:$O23),1,0)) -> 1 | AA23: =W22*S23 -> 0 | AB23: =X22*T23 -> -0.073689622 | AC23: =Y22*U23 -> 0.17 | AE23: =SUM(AA23:AC23) -> 0.096310378 | AG23: =ABS(W23-W22) -> 1 | AH23: =ABS(X23-X22) -> 1 | AI23: =ABS(Y23-Y22) -> 0
A24: ='ALL 3 2024+'!E276 -> 45693 | B24: ='ALL 3 2024+'!F276 -> 45693 | C24: ='ALL 3 2024+'!G276 -> 45693 | E24: ='ALL 3 2024+'!I276 -> 21.74 | F24: ='ALL 3 2024+'!J276 -> 45.71 | G24: ='ALL 3 2024+'!K276 -> 92.48 | I24: ='ALL 3 2024+'!Q276 -> 2.1054998 | J24: ='ALL 3 2024+'!R276 -> 2.0221042 | K24: ='ALL 3 2024+'!S276 -> 4.2575396 | M24: =E24*K24 -> 92.558912 | N24: =J24*F24 -> 92.430384 | O24: =G24 -> 92.48 | Q24: =MAX(M24:O24)-MIN(M24:O24) -> 0.12852763 | S24: =M24-M23 -> 0.55029766 | T24: =N24-N23 -> 0.44408663 | U24: =O24-O23 -> 0.51 | W24: =IF(M24=MAX($M24:$O24),-1,IF(M24=MIN($M24:$O24),1,0)) -> -1 | X24: =IF(N24=MAX($M24:$O24),-1,IF(N24=MIN($M24:$O24),1,0)) -> 1 | Y24: =IF(O24=MAX($M24:$O24),-1,IF(O24=MIN($M24:$O24),1,0)) -> 0 | AA24: =W23*S24 -> -0.55029766 | AB24: =X23*T24 -> 0 | AC24: =Y23*U24 -> 0.51 | AE24: =SUM(AA24:AC24) -> -0.040297658 | AG24: =ABS(W24-W23) -> 0 | AH24: =ABS(X24-X23) -> 1 | AI24: =ABS(Y24-Y23) -> 1
A25: ='ALL 3 2024+'!E277 -> 45694 | B25: ='ALL 3 2024+'!F277 -> 45694 | C25: ='ALL 3 2024+'!G277 -> 45694 | E25: ='ALL 3 2024+'!I277 -> 21.73 | F25: ='ALL 3 2024+'!J277 -> 45.66 | G25: ='ALL 3 2024+'!K277 -> 92.39 | I25: ='ALL 3 2024+'!Q277 -> 2.1053887 | J25: ='ALL 3 2024+'!R277 -> 2.0221573 | K25: ='ALL 3 2024+'!S277 -> 4.2574266 | M25: =E25*K25 -> 92.513879 | N25: =J25*F25 -> 92.331701 | O25: =G25 -> 92.39 | Q25: =MAX(M25:O25)-MIN(M25:O25) -> 0.18217826 | S25: =M25-M24 -> -0.04503258 | T25: =N25-N24 -> -0.098683212 | U25: =O25-O24 -> -0.09 | W25: =IF(M25=MAX($M25:$O25),-1,IF(M25=MIN($M25:$O25),1,0)) -> -1 | X25: =IF(N25=MAX($M25:$O25),-1,IF(N25=MIN($M25:$O25),1,0)) -> 1 | Y25: =IF(O25=MAX($M25:$O25),-1,IF(O25=MIN($M25:$O25),1,0)) -> 0 | AA25: =W24*S25 -> 0.04503258 | AB25: =X24*T25 -> -0.098683212 | AC25: =Y24*U25 -> 0 | AE25: =SUM(AA25:AC25) -> -0.053650633 | AG25: =ABS(W25-W24) -> 0 | AH25: =ABS(X25-X24) -> 0 | AI25: =ABS(Y25-Y24) -> 0
A26: ='ALL 3 2024+'!E278 -> 45695 | B26: ='ALL 3 2024+'!F278 -> 45695 | C26: ='ALL 3 2024+'!G278 -> 45695 | E26: ='ALL 3 2024+'!I278 -> 21.67 | F26: ='ALL 3 2024+'!J278 -> 45.56 | G26: ='ALL 3 2024+'!K278 -> 92.18 | I26: ='ALL 3 2024+'!Q278 -> 2.105072 | J26: ='ALL 3 2024+'!R278 -> 2.0222193 | K26: ='ALL 3 2024+'!S278 -> 4.2569165 | M26: =E26*K26 -> 92.247381 | N26: =J26*F26 -> 92.132313 | O26: =G26 -> 92.18 | Q26: =MAX(M26:O26)-MIN(M26:O26) -> 0.11506726 | S26: =M26-M25 -> -0.26649871 | T26: =N26-N25 -> -0.19938771 | U26: =O26-O25 -> -0.21 | W26: =IF(M26=MAX($M26:$O26),-1,IF(M26=MIN($M26:$O26),1,0)) -> -1 | X26: =IF(N26=MAX($M26:$O26),-1,IF(N26=MIN($M26:$O26),1,0)) -> 1 | Y26: =IF(O26=MAX($M26:$O26),-1,IF(O26=MIN($M26:$O26),1,0)) -> 0 | AA26: =W25*S26 -> 0.26649871 | AB26: =X25*T26 -> -0.19938771 | AC26: =Y25*U26 -> 0 | AE26: =SUM(AA26:AC26) -> 0.067111 | AG26: =ABS(W26-W25) -> 0 | AH26: =ABS(X26-X25) -> 0 | AI26: =ABS(Y26-Y25) -> 0
A27: ='ALL 3 2024+'!E279 -> 45698 | B27: ='ALL 3 2024+'!F279 -> 45698 | C27: ='ALL 3 2024+'!G279 -> 45698 | E27: ='ALL 3 2024+'!I279 -> 21.68 | F27: ='ALL 3 2024+'!J279 -> 45.55 | G27: ='ALL 3 2024+'!K279 -> 92.2 | I27: ='ALL 3 2024+'!Q279 -> 2.1048672 | J27: ='ALL 3 2024+'!R279 -> 2.0222624 | K27: ='ALL 3 2024+'!S279 -> 4.2565928 | M27: =E27*K27 -> 92.282933 | N27: =J27*F27 -> 92.114053 | O27: =G27 -> 92.2 | Q27: =MAX(M27:O27)-MIN(M27:O27) -> 0.16887974 | S27: =M27-M26 -> 0.035552143 | T27: =N27-N26 -> -0.018260335 | U27: =O27-O26 -> 0.02 | W27: =IF(M27=MAX($M27:$O27),-1,IF(M27=MIN($M27:$O27),1,0)) -> -1 | X27: =IF(N27=MAX($M27:$O27),-1,IF(N27=MIN($M27:$O27),1,0)) -> 1 | Y27: =IF(O27=MAX($M27:$O27),-1,IF(O27=MIN($M27:$O27),1,0)) -> 0 | AA27: =W26*S27 -> -0.035552143 | AB27: =X26*T27 -> -0.018260335 | AC27: =Y26*U27 -> 0 | AE27: =SUM(AA27:AC27) -> -0.053812478 | AG27: =ABS(W27-W26) -> 0 | AH27: =ABS(X27-X26) -> 0 | AI27: =ABS(Y27-Y26) -> 0
A28: ='ALL 3 2024+'!E280 -> 45699 | B28: ='ALL 3 2024+'!F280 -> 45699 | C28: ='ALL 3 2024+'!G280 -> 45699 | E28: ='ALL 3 2024+'!I280 -> 21.64 | F28: ='ALL 3 2024+'!J280 -> 45.47 | G28: ='ALL 3 2024+'!K280 -> 91.95 | I28: ='ALL 3 2024+'!Q280 -> 2.1047253 | J28: ='ALL 3 2024+'!R280 -> 2.0223754 | K28: ='ALL 3 2024+'!S280 -> 4.2565432 | M28: =E28*K28 -> 92.111596 | N28: =J28*F28 -> 91.957409 | O28: =G28 -> 91.95 | Q28: =MAX(M28:O28)-MIN(M28:O28) -> 0.1615958 | S28: =M28-M27 -> -0.17133692 | T28: =N28-N27 -> -0.15664373 | U28: =O28-O27 -> -0.25 | W28: =IF(M28=MAX($M28:$O28),-1,IF(M28=MIN($M28:$O28),1,0)) -> -1 | X28: =IF(N28=MAX($M28:$O28),-1,IF(N28=MIN($M28:$O28),1,0)) -> 0 | Y28: =IF(O28=MAX($M28:$O28),-1,IF(O28=MIN($M28:$O28),1,0)) -> 1 | AA28: =W27*S28 -> 0.17133692 | AB28: =X27*T28 -> -0.15664373 | AC28: =Y27*U28 -> 0 | AE28: =SUM(AA28:AC28) -> 0.014693189 | AG28: =ABS(W28-W27) -> 0 | AH28: =ABS(X28-X27) -> 1 | AI28: =ABS(Y28-Y27) -> 1
A29: ='ALL 3 2024+'!E281 -> 45700 | B29: ='ALL 3 2024+'!F281 -> 45700 | C29: ='ALL 3 2024+'!G281 -> 45700 | E29: ='ALL 3 2024+'!I281 -> 21.51 | F29: ='ALL 3 2024+'!J281 -> 45.25 | G29: ='ALL 3 2024+'!K281 -> 91.44 | I29: ='ALL 3 2024+'!Q281 -> 2.1045569 | J29: ='ALL 3 2024+'!R281 -> 2.0223558 | K29: ='ALL 3 2024+'!S281 -> 4.2561614 | M29: =E29*K29 -> 91.550032 | N29: =J29*F29 -> 91.511598 | O29: =G29 -> 91.44 | Q29: =MAX(M29:O29)-MIN(M29:O29) -> 0.11003221 | S29: =M29-M28 -> -0.56156359 | T29: =N29-N28 -> -0.44581117 | U29: =O29-O28 -> -0.51 | W29: =IF(M29=MAX($M29:$O29),-1,IF(M29=MIN($M29:$O29),1,0)) -> -1 | X29: =IF(N29=MAX($M29:$O29),-1,IF(N29=MIN($M29:$O29),1,0)) -> 0 | Y29: =IF(O29=MAX($M29:$O29),-1,IF(O29=MIN($M29:$O29),1,0)) -> 1 | AA29: =W28*S29 -> 0.56156359 | AB29: =X28*T29 -> 0 | AC29: =Y28*U29 -> -0.51 | AE29: =SUM(AA29:AC29) -> 0.051563585 | AG29: =ABS(W29-W28) -> 0 | AH29: =ABS(X29-X28) -> 0 | AI29: =ABS(Y29-Y28) -> 0
A30: ='ALL 3 2024+'!E282 -> 45701 | B30: ='ALL 3 2024+'!F282 -> 45701 | C30: ='ALL 3 2024+'!G282 -> 45701 | E30: ='ALL 3 2024+'!I282 -> 21.64 | F30: ='ALL 3 2024+'!J282 -> 45.54 | G30: ='ALL 3 2024+'!K282 -> 92.07 | I30: ='ALL 3 2024+'!Q282 -> 2.1043994 | J30: ='ALL 3 2024+'!R282 -> 2.022367 | K30: ='ALL 3 2024+'!S282 -> 4.2558667 | M30: =E30*K30 -> 92.096955 | N30: =J30*F30 -> 92.098591 | O30: =G30 -> 92.07 | P30: =M25-M30 -> 0.41692464 | Q30: =MAX(M30:O30)-MIN(M30:O30) -> 0.028591308 | R30: =N30-N25 -> -0.23310972 | S30: =M30-M29 -> 0.54692243 | T30: =N30-N29 -> 0.58699323 | U30: =O30-O29 -> 0.63 | W30: =IF(M30=MAX($M30:$O30),-1,IF(M30=MIN($M30:$O30),1,0)) -> 0 | X30: =IF(N30=MAX($M30:$O30),-1,IF(N30=MIN($M30:$O30),1,0)) -> -1 | Y30: =IF(O30=MAX($M30:$O30),-1,IF(O30=MIN($M30:$O30),1,0)) -> 1 | AA30: =W29*S30 -> -0.54692243 | AB30: =X29*T30 -> 0 | AC30: =Y29*U30 -> 0.63 | AE30: =SUM(AA30:AC30) -> 0.083077569 | AG30: =ABS(W30-W29) -> 1 | AH30: =ABS(X30-X29) -> 1 | AI30: =ABS(Y30-Y29) -> 0
A31: ='ALL 3 2024+'!E283 -> 45702 | B31: ='ALL 3 2024+'!F283 -> 45702 | C31: ='ALL 3 2024+'!G283 -> 45702 | E31: ='ALL 3 2024+'!I283 -> 21.74 | F31: ='ALL 3 2024+'!J283 -> 45.73 | G31: ='ALL 3 2024+'!K283 -> 92.43 | I31: ='ALL 3 2024+'!Q283 -> 2.104407 | J31: ='ALL 3 2024+'!R283 -> 2.0223367 | K31: ='ALL 3 2024+'!S283 -> 4.2558184 | M31: =E31*K31 -> 92.521492 | N31: =J31*F31 -> 92.481455 | O31: =G31 -> 92.43 | Q31: =MAX(M31:O31)-MIN(M31:O31) -> 0.091491789 | S31: =M31-M30 -> 0.42453715 | T31: =N31-N30 -> 0.3828641 | U31: =O31-O30 -> 0.36 | W31: =IF(M31=MAX($M31:$O31),-1,IF(M31=MIN($M31:$O31),1,0)) -> -1 | X31: =IF(N31=MAX($M31:$O31),-1,IF(N31=MIN($M31:$O31),1,0)) -> 0 | Y31: =IF(O31=MAX($M31:$O31),-1,IF(O31=MIN($M31:$O31),1,0)) -> 1 | AA31: =W30*S31 -> 0 | AB31: =X30*T31 -> -0.3828641 | AC31: =Y30*U31 -> 0.36 | AE31: =SUM(AA31:AC31) -> -0.022864098 | AG31: =ABS(W31-W30) -> 1 | AH31: =ABS(X31-X30) -> 1 | AI31: =ABS(Y31-Y30) -> 0
A32: ='ALL 3 2024+'!E284 -> 45706 | B32: ='ALL 3 2024+'!F284 -> 45706 | C32: ='ALL 3 2024+'!G284 -> 45706 | E32: ='ALL 3 2024+'!I284 -> 21.64 | F32: ='ALL 3 2024+'!J284 -> 45.52 | G32: ='ALL 3 2024+'!K284 -> 91.99 | I32: ='ALL 3 2024+'!Q284 -> 2.1042587 | J32: ='ALL 3 2024+'!R284 -> 2.0222496 | K32: ='ALL 3 2024+'!S284 -> 4.2553352 | M32: =E32*K32 -> 92.085454 | N32: =J32*F32 -> 92.052801 | O32: =G32 -> 91.99 | Q32: =MAX(M32:O32)-MIN(M32:O32) -> 0.095453621 | S32: =M32-M31 -> -0.43603817 | T32: =N32-N31 -> -0.42865443 | U32: =O32-O31 -> -0.44 | W32: =IF(M32=MAX($M32:$O32),-1,IF(M32=MIN($M32:$O32),1,0)) -> -1 | X32: =IF(N32=MAX($M32:$O32),-1,IF(N32=MIN($M32:$O32),1,0)) -> 0 | Y32: =IF(O32=MAX($M32:$O32),-1,IF(O32=MIN($M32:$O32),1,0)) -> 1 | AA32: =W31*S32 -> 0.43603817 | AB32: =X31*T32 -> 0 | AC32: =Y31*U32 -> -0.44 | AE32: =SUM(AA32:AC32) -> -0.0039618315 | AG32: =ABS(W32-W31) -> 0 | AH32: =ABS(X32-X31) -> 0 | AI32: =ABS(Y32-Y31) -> 0
A33: ='ALL 3 2024+'!E285 -> 45707 | B33: ='ALL 3 2024+'!F285 -> 45707 | C33: ='ALL 3 2024+'!G285 -> 45707 | E33: ='ALL 3 2024+'!I285 -> 21.69 | F33: ='ALL 3 2024+'!J285 -> 45.6 | G33: ='ALL 3 2024+'!K285 -> 92.13 | I33: ='ALL 3 2024+'!Q285 -> 2.1041112 | J33: ='ALL 3 2024+'!R285 -> 2.0222227 | K33: ='ALL 3 2024+'!S285 -> 4.2549804 | M33: =E33*K33 -> 92.290526 | N33: =J33*F33 -> 92.213354 | O33: =G33 -> 92.13 | Q33: =MAX(M33:O33)-MIN(M33:O33) -> 0.16052552 | S33: =M33-M32 -> 0.20507189 | T33: =N33-N32 -> 0.16055303 | U33: =O33-O32 -> 0.14 | W33: =IF(M33=MAX($M33:$O33),-1,IF(M33=MIN($M33:$O33),1,0)) -> -1 | X33: =IF(N33=MAX($M33:$O33),-1,IF(N33=MIN($M33:$O33),1,0)) -> 0 | Y33: =IF(O33=MAX($M33:$O33),-1,IF(O33=MIN($M33:$O33),1,0)) -> 1 | AA33: =W32*S33 -> -0.20507189 | AB33: =X32*T33 -> 0 | AC33: =Y32*U33 -> 0.14 | AE33: =SUM(AA33:AC33) -> -0.065071895 | AG33: =ABS(W33-W32) -> 0 | AH33: =ABS(X33-X32) -> 0 | AI33: =ABS(Y33-Y32) -> 0
A34: ='ALL 3 2024+'!E286 -> 45708 | B34: ='ALL 3 2024+'!F286 -> 45708 | C34: ='ALL 3 2024+'!G286 -> 45708 | E34: ='ALL 3 2024+'!I286 -> 21.74 | F34: ='ALL 3 2024+'!J286 -> 45.7 | G34: ='ALL 3 2024+'!K286 -> 92.38 | I34: ='ALL 3 2024+'!Q286 -> 2.1039485 | J34: ='ALL 3 2024+'!R286 -> 2.0221425 | K34: ='ALL 3 2024+'!S286 -> 4.2544831 | M34: =E34*K34 -> 92.492462 | N34: =J34*F34 -> 92.411914 | O34: =G34 -> 92.38 | Q34: =MAX(M34:O34)-MIN(M34:O34) -> 0.11246204 | S34: =M34-M33 -> 0.20193652 | T34: =N34-N33 -> 0.19856027 | U34: =O34-O33 -> 0.25 | W34: =IF(M34=MAX($M34:$O34),-1,IF(M34=MIN($M34:$O34),1,0)) -> -1 | X34: =IF(N34=MAX($M34:$O34),-1,IF(N34=MIN($M34:$O34),1,0)) -> 0 | Y34: =IF(O34=MAX($M34:$O34),-1,IF(O34=MIN($M34:$O34),1,0)) -> 1 | AA34: =W33*S34 -> -0.20193652 | AB34: =X33*T34 -> 0 | AC34: =Y33*U34 -> 0.25 | AE34: =SUM(AA34:AC34) -> 0.048063479 | AG34: =ABS(W34-W33) -> 0 | AH34: =ABS(X34-X33) -> 0 | AI34: =ABS(Y34-Y33) -> 0
A35: ='ALL 3 2024+'!E287 -> 45709 | B35: ='ALL 3 2024+'!F287 -> 45709 | C35: ='ALL 3 2024+'!G287 -> 45709 | E35: ='ALL 3 2024+'!I287 -> 21.83 | F35: ='ALL 3 2024+'!J287 -> 45.94 | G35: ='ALL 3 2024+'!K287 -> 92.87 | I35: ='ALL 3 2024+'!Q287 -> 2.1038107 | J35: ='ALL 3 2024+'!R287 -> 2.0220573 | K35: ='ALL 3 2024+'!S287 -> 4.2540251 | M35: =E35*K35 -> 92.865369 | N35: =J35*F35 -> 92.893315 | O35: =G35 -> 92.87 | Q35: =MAX(M35:O35)-MIN(M35:O35) -> 0.027945682 | S35: =M35-M34 -> 0.37290681 | T35: =N35-N34 -> 0.48140024 | U35: =O35-O34 -> 0.49 | W35: =IF(M35=MAX($M35:$O35),-1,IF(M35=MIN($M35:$O35),1,0)) -> 1 | X35: =IF(N35=MAX($M35:$O35),-1,IF(N35=MIN($M35:$O35),1,0)) -> -1 | Y35: =IF(O35=MAX($M35:$O35),-1,IF(O35=MIN($M35:$O35),1,0)) -> 0 | AA35: =W34*S35 -> -0.37290681 | AB35: =X34*T35 -> 0 | AC35: =Y34*U35 -> 0.49 | AE35: =SUM(AA35:AC35) -> 0.11709319 | AG35: =ABS(W35-W34) -> 2 | AH35: =ABS(X35-X34) -> 1 | AI35: =ABS(Y35-Y34) -> 1
A36: ='ALL 3 2024+'!E288 -> 45712 | B36: ='ALL 3 2024+'!F288 -> 45712 | C36: ='ALL 3 2024+'!G288 -> 45712 | E36: ='ALL 3 2024+'!I288 -> 21.84 | F36: ='ALL 3 2024+'!J288 -> 45.98 | G36: ='ALL 3 2024+'!K288 -> 92.99 | I36: ='ALL 3 2024+'!Q288 -> 2.1036791 | J36: ='ALL 3 2024+'!R288 -> 2.0220191 | K36: ='ALL 3 2024+'!S288 -> 4.2536783 | M36: =E36*K36 -> 92.900335 | N36: =J36*F36 -> 92.972437 | O36: =G36 -> 92.99 | Q36: =MAX(M36:O36)-MIN(M36:O36) -> 0.089664901 | S36: =M36-M35 -> 0.034966253 | T36: =N36-N35 -> 0.079122035 | U36: =O36-O35 -> 0.12 | W36: =IF(M36=MAX($M36:$O36),-1,IF(M36=MIN($M36:$O36),1,0)) -> 1 | X36: =IF(N36=MAX($M36:$O36),-1,IF(N36=MIN($M36:$O36),1,0)) -> 0 | Y36: =IF(O36=MAX($M36:$O36),-1,IF(O36=MIN($M36:$O36),1,0)) -> -1 | AA36: =W35*S36 -> 0.034966253 | AB36: =X35*T36 -> -0.079122035 | AC36: =Y35*U36 -> 0 | AE36: =SUM(AA36:AC36) -> -0.044155782 | AG36: =ABS(W36-W35) -> 0 | AH36: =ABS(X36-X35) -> 1 | AI36: =ABS(Y36-Y35) -> 1
A37: ='ALL 3 2024+'!E289 -> 45713 | B37: ='ALL 3 2024+'!F289 -> 45713 | C37: ='ALL 3 2024+'!G289 -> 45713 | E37: ='ALL 3 2024+'!I289 -> 22.01 | F37: ='ALL 3 2024+'!J289 -> 46.28 | G37: ='ALL 3 2024+'!K289 -> 93.54 | I37: ='ALL 3 2024+'!Q289 -> 2.1036472 | J37: ='ALL 3 2024+'!R289 -> 2.0220248 | K37: ='ALL 3 2024+'!S289 -> 4.2536261 | M37: =E37*K37 -> 93.62231 | N37: =J37*F37 -> 93.579309 | O37: =G37 -> 93.54 | Q37: =MAX(M37:O37)-MIN(M37:O37) -> 0.08231027 | S37: =M37-M36 -> 0.72197517 | T37: =N37-N36 -> 0.60687201 | U37: =O37-O36 -> 0.55 | W37: =IF(M37=MAX($M37:$O37),-1,IF(M37=MIN($M37:$O37),1,0)) -> -1 | X37: =IF(N37=MAX($M37:$O37),-1,IF(N37=MIN($M37:$O37),1,0)) -> 0 | Y37: =IF(O37=MAX($M37:$O37),-1,IF(O37=MIN($M37:$O37),1,0)) -> 1 | AA37: =W36*S37 -> 0.72197517 | AB37: =X36*T37 -> 0 | AC37: =Y36*U37 -> -0.55 | AE37: =SUM(AA37:AC37) -> 0.17197517 | AG37: =ABS(W37-W36) -> 2 | AH37: =ABS(X37-X36) -> 0 | AI37: =ABS(Y37-Y36) -> 2
A38: ='ALL 3 2024+'!E290 -> 45714 | B38: ='ALL 3 2024+'!F290 -> 45714 | C38: ='ALL 3 2024+'!G290 -> 45714 | E38: ='ALL 3 2024+'!I290 -> 22.05 | F38: ='ALL 3 2024+'!J290 -> 46.34 | G38: ='ALL 3 2024+'!K290 -> 93.8 | I38: ='ALL 3 2024+'!Q290 -> 2.1035643 | J38: ='ALL 3 2024+'!R290 -> 2.0219756 | K38: ='ALL 3 2024+'!S290 -> 4.2533549 | M38: =E38*K38 -> 93.786477 | N38: =J38*F38 -> 93.698352 | O38: =G38 -> 93.8 | Q38: =MAX(M38:O38)-MIN(M38:O38) -> 0.10164845 | S38: =M38-M37 -> 0.16416628 | T38: =N38-N37 -> 0.11904298 | U38: =O38-O37 -> 0.26 | W38: =IF(M38=MAX($M38:$O38),-1,IF(M38=MIN($M38:$O38),1,0)) -> 0 | X38: =IF(N38=MAX($M38:$O38),-1,IF(N38=MIN($M38:$O38),1,0)) -> 1 | Y38: =IF(O38=MAX($M38:$O38),-1,IF(O38=MIN($M38:$O38),1,0)) -> -1 | AA38: =W37*S38 -> -0.16416628 | AB38: =X37*T38 -> 0 | AC38: =Y37*U38 -> 0.26 | AE38: =SUM(AA38:AC38) -> 0.095833715 | AG38: =ABS(W38-W37) -> 1 | AH38: =ABS(X38-X37) -> 1 | AI38: =ABS(Y38-Y37) -> 2
A39: ='ALL 3 2024+'!E291 -> 45715 | B39: ='ALL 3 2024+'!F291 -> 45715 | C39: ='ALL 3 2024+'!G291 -> 45715 | E39: ='ALL 3 2024+'!I291 -> 22.04 | F39: ='ALL 3 2024+'!J291 -> 46.28 | G39: ='ALL 3 2024+'!K291 -> 93.67 | I39: ='ALL 3 2024+'!Q291 -> 2.1034959 | J39: ='ALL 3 2024+'!R291 -> 2.0220096 | K39: ='ALL 3 2024+'!S291 -> 4.2532879 | M39: =E39*K39 -> 93.742465 | N39: =J39*F39 -> 93.578603 | O39: =G39 -> 93.67 | Q39: =MAX(M39:O39)-MIN(M39:O39) -> 0.16386205 | S39: =M39-M38 -> -0.044011411 | T39: =N39-N38 -> -0.11974846 | U39: =O39-O38 -> -0.13 | W39: =IF(M39=MAX($M39:$O39),-1,IF(M39=MIN($M39:$O39),1,0)) -> -1 | X39: =IF(N39=MAX($M39:$O39),-1,IF(N39=MIN($M39:$O39),1,0)) -> 1 | Y39: =IF(O39=MAX($M39:$O39),-1,IF(O39=MIN($M39:$O39),1,0)) -> 0 | AA39: =W38*S39 -> 0 | AB39: =X38*T39 -> -0.11974846 | AC39: =Y38*U39 -> 0.13 | AE39: =SUM(AA39:AC39) -> 0.010251544 | AG39: =ABS(W39-W38) -> 1 | AH39: =ABS(X39-X38) -> 0 | AI39: =ABS(Y39-Y38) -> 1
A40: ='ALL 3 2024+'!E292 -> 45716 | B40: ='ALL 3 2024+'!F292 -> 45716 | C40: ='ALL 3 2024+'!G292 -> 45716 | E40: ='ALL 3 2024+'!I292 -> 22.14 | F40: ='ALL 3 2024+'!J292 -> 46.49 | G40: ='ALL 3 2024+'!K292 -> 94.08 | I40: ='ALL 3 2024+'!Q292 -> 2.1032722 | J40: ='ALL 3 2024+'!R292 -> 2.0221123 | K40: ='ALL 3 2024+'!S292 -> 4.2530514 | M40: =E40*K40 -> 94.162558 | N40: =J40*F40 -> 94.008001 | O40: =G40 -> 94.08 | Q40: =MAX(M40:O40)-MIN(M40:O40) -> 0.15455671 | S40: =M40-M39 -> 0.42009263 | T40: =N40-N39 -> 0.42939797 | U40: =O40-O39 -> 0.41 | W40: 0 | X40: 0 | Y40: 0 | AA40: =W39*S40 -> -0.42009263 | AB40: =X39*T40 -> 0.42939797 | AC40: =Y39*U40 -> 0 | AE40: =SUM(AA40:AC40) -> 0.0093053368 | AG40: =ABS(W40-W39) -> 1 | AH40: =ABS(X40-X39) -> 1 | AI40: =ABS(Y40-Y39) -> 0
...

Sheet 40
AC1: =SUM(AC3:AC376) -> 10.310503
A2: ='ALL 3 2024+'!E254 -> 45659 | B2: ='ALL 3 2024+'!F254 -> 45659 | C2: ='ALL 3 2024+'!G254 -> 45659 | E2: ='ALL 3 2024+'!I254 -> 21.54 | F2: ='ALL 3 2024+'!J254 -> 45.28 | G2: ='ALL 3 2024+'!K254 -> 91.6 | I2: ='ALL 3 2024+'!U254 -> 2.1003378 | J2: ='ALL 3 2024+'!V254 -> 2.0241209 | K2: ='ALL 3 2024+'!W254 -> 4.2513332 | M2: =E2*K2 -> 91.573717 | N2: =J2*F2 -> 91.652196 | O2: =G2 -> 91.6 | U2: =IF(M2=MAX($M2:$O2),-1,IF(M2=MIN($M2:$O2),1,0)) -> 1 | V2: =IF(N2=MAX($M2:$O2),-1,IF(N2=MIN($M2:$O2),1,0)) -> -1 | W2: =IF(O2=MAX($M2:$O2),-1,IF(O2=MIN($M2:$O2),1,0)) -> 0
A3: ='ALL 3 2024+'!E255 -> 45660 | B3: ='ALL 3 2024+'!F255 -> 45660 | C3: ='ALL 3 2024+'!G255 -> 45660 | E3: ='ALL 3 2024+'!I255 -> 21.48 | F3: ='ALL 3 2024+'!J255 -> 45.24 | G3: ='ALL 3 2024+'!K255 -> 91.48 | I3: ='ALL 3 2024+'!U255 -> 2.1004303 | J3: ='ALL 3 2024+'!V255 -> 2.0240169 | K3: ='ALL 3 2024+'!W255 -> 4.251302 | M3: =E3*K3 -> 91.317967 | N3: =J3*F3 -> 91.566525 | O3: =G3 -> 91.48 | Q3: =M3-M2 -> -0.2557501 | R3: =N3-N2 -> -0.085671281 | S3: =O3-O2 -> -0.12 | U3: =IF(M3=MAX($M3:$O3),-1,IF(M3=MIN($M3:$O3),1,0)) -> 1 | V3: =IF(N3=MAX($M3:$O3),-1,IF(N3=MIN($M3:$O3),1,0)) -> -1 | W3: =IF(O3=MAX($M3:$O3),-1,IF(O3=MIN($M3:$O3),1,0)) -> 0 | Y3: =U2*Q3 -> -0.2557501 | Z3: =V2*R3 -> 0.085671281 | AA3: =W2*S3 -> 0 | AC3: =SUM(Y3:AA3) -> -0.17007882
A4: ='ALL 3 2024+'!E256 -> 45663 | B4: ='ALL 3 2024+'!F256 -> 45663 | C4: ='ALL 3 2024+'!G256 -> 45663 | E4: ='ALL 3 2024+'!I256 -> 21.47 | F4: ='ALL 3 2024+'!J256 -> 45.19 | G4: ='ALL 3 2024+'!K256 -> 91.38 | I4: ='ALL 3 2024+'!U256 -> 2.1007103 | J4: ='ALL 3 2024+'!V256 -> 2.0238852 | K4: ='ALL 3 2024+'!W256 -> 4.2515922 | M4: =E4*K4 -> 91.281685 | N4: =J4*F4 -> 91.459374 | O4: =G4 -> 91.38 | Q4: =M4-M3 -> -0.036282822 | R4: =N4-N3 -> -0.10715066 | S4: =O4-O3 -> -0.1 | U4: =IF(M4=MAX($M4:$O4),-1,IF(M4=MIN($M4:$O4),1,0)) -> 1 | V4: =IF(N4=MAX($M4:$O4),-1,IF(N4=MIN($M4:$O4),1,0)) -> -1 | W4: =IF(O4=MAX($M4:$O4),-1,IF(O4=MIN($M4:$O4),1,0)) -> 0 | Y4: =U3*Q4 -> -0.036282822 | Z4: =V3*R4 -> 0.10715066 | AA4: =W3*S4 -> 0 | AC4: =SUM(Y4:AA4) -> 0.070867839
A5: ='ALL 3 2024+'!E257 -> 45664 | B5: ='ALL 3 2024+'!F257 -> 45664 | C5: ='ALL 3 2024+'!G257 -> 45664 | E5: ='ALL 3 2024+'!I257 -> 21.38 | F5: ='ALL 3 2024+'!J257 -> 45.06 | G5: ='ALL 3 2024+'!K257 -> 91.12 | I5: ='ALL 3 2024+'!U257 -> 2.1008794 | J5: ='ALL 3 2024+'!V257 -> 2.0238101 | K5: ='ALL 3 2024+'!W257 -> 4.2517764 | M5: =E5*K5 -> 90.90298 | N5: =J5*F5 -> 91.192881 | O5: =G5 -> 91.12 | Q5: =M5-M4 -> -0.37870424 | R5: =N5-N4 -> -0.26649256 | S5: =O5-O4 -> -0.26 | U5: =IF(M5=MAX($M5:$O5),-1,IF(M5=MIN($M5:$O5),1,0)) -> 1 | V5: =IF(N5=MAX($M5:$O5),-1,IF(N5=MIN($M5:$O5),1,0)) -> -1 | W5: =IF(O5=MAX($M5:$O5),-1,IF(O5=MIN($M5:$O5),1,0)) -> 0 | Y5: =U4*Q5 -> -0.37870424 | Z5: =V4*R5 -> 0.26649256 | AA5: =W4*S5 -> 0 | AC5: =SUM(Y5:AA5) -> -0.11221168
A6: ='ALL 3 2024+'!E258 -> 45665 | B6: ='ALL 3 2024+'!F258 -> 45665 | C6: ='ALL 3 2024+'!G258 -> 45665 | E6: ='ALL 3 2024+'!I258 -> 21.4 | F6: ='ALL 3 2024+'!J258 -> 45.08 | G6: ='ALL 3 2024+'!K258 -> 91.17 | I6: ='ALL 3 2024+'!U258 -> 2.1011509 | J6: ='ALL 3 2024+'!V258 -> 2.0236519 | K6: ='ALL 3 2024+'!W258 -> 4.2519935 | M6: =E6*K6 -> 90.992661 | N6: =J6*F6 -> 91.226227 | O6: =G6 -> 91.17 | Q6: =M6-M5 -> 0.089680333 | R6: =N6-N5 -> 0.03334595 | S6: =O6-O5 -> 0.05 | U6: =IF(M6=MAX($M6:$O6),-1,IF(M6=MIN($M6:$O6),1,0)) -> 1 | V6: =IF(N6=MAX($M6:$O6),-1,IF(N6=MIN($M6:$O6),1,0)) -> -1 | W6: =IF(O6=MAX($M6:$O6),-1,IF(O6=MIN($M6:$O6),1,0)) -> 0 | Y6: =U5*Q6 -> 0.089680333 | Z6: =V5*R6 -> -0.03334595 | AA6: =W5*S6 -> 0 | AC6: =SUM(Y6:AA6) -> 0.056334383
A7: ='ALL 3 2024+'!E259 -> 45667 | B7: ='ALL 3 2024+'!F259 -> 45667 | C7: ='ALL 3 2024+'!G259 -> 45667 | E7: ='ALL 3 2024+'!I259 -> 21.28 | F7: ='ALL 3 2024+'!J259 -> 44.77 | G7: ='ALL 3 2024+'!K259 -> 90.52 | I7: ='ALL 3 2024+'!U259 -> 2.1014341 | J7: ='ALL 3 2024+'!V259 -> 2.0235058 | K7: ='ALL 3 2024+'!W259 -> 4.25226 | M7: =E7*K7 -> 90.488093 | N7: =J7*F7 -> 90.592356 | O7: =G7 -> 90.52 | Q7: =M7-M6 -> -0.50456725 | R7: =N7-N6 -> -0.63387125 | S7: =O7-O6 -> -0.65 | U7: =IF(M7=MAX($M7:$O7),-1,IF(M7=MIN($M7:$O7),1,0)) -> 1 | V7: =IF(N7=MAX($M7:$O7),-1,IF(N7=MIN($M7:$O7),1,0)) -> -1 | W7: =IF(O7=MAX($M7:$O7),-1,IF(O7=MIN($M7:$O7),1,0)) -> 0 | Y7: =U6*Q7 -> -0.50456725 | Z7: =V6*R7 -> 0.63387125 | AA7: =W6*S7 -> 0 | AC7: =SUM(Y7:AA7) -> 0.129304
A8: ='ALL 3 2024+'!E260 -> 45670 | B8: ='ALL 3 2024+'!F260 -> 45670 | C8: ='ALL 3 2024+'!G260 -> 45670 | E8: ='ALL 3 2024+'!I260 -> 21.23 | F8: ='ALL 3 2024+'!J260 -> 44.68 | G8: ='ALL 3 2024+'!K260 -> 90.37 | I8: ='ALL 3 2024+'!U260 -> 2.1016389 | J8: ='ALL 3 2024+'!V260 -> 2.0233687 | K8: ='ALL 3 2024+'!W260 -> 4.2523867 | M8: =E8*K8 -> 90.278169 | N8: =J8*F8 -> 90.404113 | O8: =G8 -> 90.37 | Q8: =M8-M7 -> -0.20992411 | R8: =N8-N7 -> -0.18824283 | S8: =O8-O7 -> -0.15 | U8: =IF(M8=MAX($M8:$O8),-1,IF(M8=MIN($M8:$O8),1,0)) -> 1 | V8: =IF(N8=MAX($M8:$O8),-1,IF(N8=MIN($M8:$O8),1,0)) -> -1 | W8: =IF(O8=MAX($M8:$O8),-1,IF(O8=MIN($M8:$O8),1,0)) -> 0 | Y8: =U7*Q8 -> -0.20992411 | Z8: =V7*R8 -> 0.18824283 | AA8: =W7*S8 -> 0 | AC8: =SUM(Y8:AA8) -> -0.021681286
A9: ='ALL 3 2024+'!E261 -> 45671 | B9: ='ALL 3 2024+'!F261 -> 45671 | C9: ='ALL 3 2024+'!G261 -> 45671 | E9: ='ALL 3 2024+'!I261 -> 21.25 | F9: ='ALL 3 2024+'!J261 -> 44.77 | G9: ='ALL 3 2024+'!K261 -> 90.46 | I9: ='ALL 3 2024+'!U261 -> 2.1018859 | J9: ='ALL 3 2024+'!V261 -> 2.0232711 | K9: ='ALL 3 2024+'!W261 -> 4.2526817 | M9: =E9*K9 -> 90.369487 | N9: =J9*F9 -> 90.581846 | O9: =G9 -> 90.46 | Q9: =M9-M8 -> 0.09131769 | R9: =N9-N8 -> 0.17773287 | S9: =O9-O8 -> 0.09 | U9: =IF(M9=MAX($M9:$O9),-1,IF(M9=MIN($M9:$O9),1,0)) -> 1 | V9: =IF(N9=MAX($M9:$O9),-1,IF(N9=MIN($M9:$O9),1,0)) -> -1 | W9: =IF(O9=MAX($M9:$O9),-1,IF(O9=MIN($M9:$O9),1,0)) -> 0 | Y9: =U8*Q9 -> 0.09131769 | Z9: =V8*R9 -> -0.17773287 | AA9: =W8*S9 -> 0 | AC9: =SUM(Y9:AA9) -> -0.086415181
A10: ='ALL 3 2024+'!E262 -> 45672 | B10: ='ALL 3 2024+'!F262 -> 45672 | C10: ='ALL 3 2024+'!G262 -> 45672 | E10: ='ALL 3 2024+'!I262 -> 21.48 | F10: ='ALL 3 2024+'!J262 -> 45.2 | G10: ='ALL 3 2024+'!K262 -> 91.41 | I10: ='ALL 3 2024+'!U262 -> 2.1021329 | J10: ='ALL 3 2024+'!V262 -> 2.023154 | K10: ='ALL 3 2024+'!W262 -> 4.2529352 | M10: =E10*K10 -> 91.353048 | N10: =J10*F10 -> 91.446561 | O10: =G10 -> 91.41 | Q10: =M10-M9 -> 0.98356143 | R10: =N10-N9 -> 0.86471448 | S10: =O10-O9 -> 0.95 | U10: =IF(M10=MAX($M10:$O10),-1,IF(M10=MIN($M10:$O10),1,0)) -> 1 | V10: =IF(N10=MAX($M10:$O10),-1,IF(N10=MIN($M10:$O10),1,0)) -> -1 | W10: =IF(O10=MAX($M10:$O10),-1,IF(O10=MIN($M10:$O10),1,0)) -> 0 | Y10: =U9*Q10 -> 0.98356143 | Z10: =V9*R10 -> -0.86471448 | AA10: =W9*S10 -> 0 | AC10: =SUM(Y10:AA10) -> 0.11884696
A11: ='ALL 3 2024+'!E263 -> 45673 | B11: ='ALL 3 2024+'!F263 -> 45673 | C11: ='ALL 3 2024+'!G263 -> 45673 | E11: ='ALL 3 2024+'!I263 -> 21.51 | F11: ='ALL 3 2024+'!J263 -> 45.31 | G11: ='ALL 3 2024+'!K263 -> 91.66 | I11: ='ALL 3 2024+'!U263 -> 2.1023056 | J11: ='ALL 3 2024+'!V263 -> 2.0230432 | K11: ='ALL 3 2024+'!W263 -> 4.253052 | M11: =E11*K11 -> 91.483149 | N11: =J11*F11 -> 91.664088 | O11: =G11 -> 91.66 | Q11: =M11-M10 -> 0.13010077 | R11: =N11-N10 -> 0.21752762 | S11: =O11-O10 -> 0.25 | U11: =IF(M11=MAX($M11:$O11),-1,IF(M11=MIN($M11:$O11),1,0)) -> 1 | V11: =IF(N11=MAX($M11:$O11),-1,IF(N11=MIN($M11:$O11),1,0)) -> -1 | W11: =IF(O11=MAX($M11:$O11),-1,IF(O11=MIN($M11:$O11),1,0)) -> 0 | Y11: =U10*Q11 -> 0.13010077 | Z11: =V10*R11 -> -0.21752762 | AA11: =W10*S11 -> 0 | AC11: =SUM(Y11:AA11) -> -0.087426853
