Workbook

Sheet README
A2: This is designed as a database of information about crypto for use in Python scripts
A4: The main tabs of database information are named Bitcoin and Ethereum
A6: The main interfaces to identify active cryptos for the Python scripts are BTC and ETH
A7: The tabs TST and Test are available for testing new Python scripts
A9: The tab titled ETF Options Summary connects to the ETF options tabs in the next line
A10: There are tabs for option dumps of expiry and strike for each of the ETFs
B11: ARKB Options
B12: BITB Options
B13: BTC Options
B14: BRRR Options - not available - no options listed yet
B15: BTCW Options
B16: EZBC Options
B17: FBTC Options
B18: GBTC Options
B19: HODL Options
B20: IBIT Options
A22: There are tabs for streaming product dumps
B23: Coinbase Product List
B24: Gemini Product List

Sheet Notes
A1: scalars come from ….
A2: native commissions assume $100MM per month of BTC volume
G4: Support
A5: CBTX | B5: 45746 | G5: USD | H5: Non-USD
A6: symbol | B6: etf_name | C6: % of CBTX | G6: Coinbase | H6: Binance
A7: IBIT | B7: iShares Bitcoin Trust ETF | C7: 0.2 | G7: Kraken | H7: ByBit
A8: ARKB | B8: ARK 21Shares Bitcoin ETF | C8: 0.1 | E8: THE BLOCK | G8: Bitstamp | H8: OKX
A9: BITB | B9: Bitwise Bitcoin ETF Trust | C9: 0.1 | G9: LMAX Digital | H9: Bitget
A10: FBTC | B10: Fidelity Wise Origin Bitcoin Fund | C10: 0.1 | G10: Bitfinex | H10: Huobi
A11: GBTC | B11: Grayscale Bitcoin Trust | C11: 0.1 | E11: https://bitcointreasuries.net | G11: 12 others | H11: 17 others
A12: HODL | B12: VanEck Bitcoin Trust | C12: 0.1
A13: BRRR | B13: Coinshare Valkyrie Bitcoin Fund | C13: 0.0981
A14: BTCO | B14: Invesco Galaxy Bitcoin ETF | C14: 0.0872
A15: EZBC | B15: Franklin Bitcoin ETF | C15: 0.0738
A16: BTCW | B16: WisdomTree Bitcoin Fund | C16: 0.0409
C17: =SUM(C7:C16) -> 1
A18: BITO
A19: BAKKT
A21: BITI | B21: ProShares Short Bitcoin ETF
A22: BITO | B22: ProShares Bitcoin ETF
A23: BITU | B23: ProShares Ultra Bitcoin ETF
A24: SBIT | B24: ProShares UltraShort Bitcoin ETF

Sheet Venue Tables
A1: BTC | C1: API | D1: Spot | H1: Perps | K1: Expiring Futures | O1: Option
B2: Importance | C2: Ranking | D2: BTC-USD | E2: BTC-USDC | F2: BTC-USDT | G2: BTC-USD1 | H2: PERP BTC-USD | I2: PERP BTC-USDC | J2: PERP BTC-USDT | K2: USD | L2: USDC | M2: USDT | N2: Others | O2: USD | P2: USDC | Q2: USDT | R2: Others
A3: Binance | B3: Tier 1 | C3: 4 | D3: BTCUSD | E3: BTCUSDC | F3: BTCUSDT | G3: BTCUSD1 | H3: FALSE | I3: FALSE | J3: FALSE
A4: Binance-Derivs | B4: - | C4: - | D4: FALSE | E4: FALSE | F4: FALSE | G4: FALSE
A5: BinanceUS | B5: - | C5: - | D5: BTCUSD | E5: BTCUSDC | F5: BTCUSDT | G5: FALSE | H5: FALSE | I5: FALSE | J5: FALSE
A6: Bitfinex | B6: Tier 2 | C6: 8 | D6: tBTCUSD | E6: FALSE | F6: tBTCUST | G6: FALSE
A7: Bitnomial | B7: - | C7: - | D7: spot contracts - not spot | H7: FALSE | I7: FALSE | J7: FALSE | K7: TRUE
A8: Bybit | B8: Tier 1 | C8: 5 | D8: BTCUSD | E8: BTCUSDC | F8: BTCUSDT | G8: FALSE | H8: BTCUSD | I8: BTCPERP | J8: BTCUSDT
A9: Coinbase | B9: Tier 1 | C9: 1 | D9: BTC-USD | E9: NO PRICE | F9: BTC-USDT | G9: FALSE | H9: FALSE | I9: FALSE | J9: FALSE
A10: Deribit | B10: Tier 1 | C10: 9 | D10: FALSE | E10: BTC_USDC | F10: BTC_USDT | G10: FALSE
A11: EDX | B11: - | C11: - | H11: FALSE | I11: FALSE | J11: FALSE
A12: Gate | B12: Tier 3 | C12: - | D12: FALSE | E12: BTC_USDC | F12: BTC_USDT | G12: BTC_USD1
A13: Gemini | B13: Tier 4 | C13: 3 | D13: btcusd | E13: btcusdc | F13: btcusdt | G13: FALSE | H13: FALSE | I13: FALSE | J13: FALSE
A14: Huobi | B14: Tier 5 | C14: 10 | D14: FALSE | E14: btcusdc | F14: btcusdt | G14: btcusd1
A15: Kraken | B15: Tier 2 | C15: 2 | D15: BTC/USD | E15: BTC/USDC | F15: BTC/USDT | G15: BTC/USD1 | H15: FALSE | I15: FALSE | J15: FALSE
A16: Kraken-Derivs | B16: - | C16: - | D16: FALSE | E16: FALSE | F16: FALSE | G16: FALSE
A17: KuCoin | B17: Tier 2 | C17: 7 | D17: FALSE | E17: BTC-USDC | F17: BTC-USDT | G17: BTC-USD1 | H17: FALSE | I17: FALSE | J17: FALSE
A18: KuCoin-Derivs | B18: - | C18: - | D18: FALSE | E18: FALSE | F18: FALSE | G18: FALSE
A19: MEXC | B19: Tier 3 | C19: -
A20: OKX | B20: Tier 1 | C20: 6 | D20: BTC-USD | E20: BTC-USDC | F20: BTC-USDT | G20: FALSE
A21: Phemex | B21: Tier 3 | C21: - | D21: FALSE | E21: sBTCUSDC | F21: sBTCUSDT | G21: FALSE
C22: count | D22: =COUNTA(D3:D21)-COUNTIF(D3:D21,"FALSE")-COUNTIF(D3:D21, "NO PRICE") -> 9 | E22: =COUNTA(E3:E21)-COUNTIF(E3:E21,"FALSE")-COUNTIF(E3:E21, "NO PRICE") -> 11 | F22: =COUNTA(F3:F21)-COUNTIF(F3:F21,"FALSE")-COUNTIF(F3:F21, "NO PRICE") -> 13 | G22: =COUNTA(G3:G21)-COUNTIF(G3:G21,"FALSE")-COUNTIF(G3:G21, "NO PRICE") -> 5 | H22: =COUNTA(H3:H21)-COUNTIF(H3:H21,"FALSE")-COUNTIF(H3:H21, "NO PRICE") -> 1
A24: Binance
A25: BinanceUS
A26: Bitfinex
A27: Bybit
A28: Coinbase
A29: Deribit
A30: Gate
A31: Gemini
A32: Huobi
A33: Kraken
A34: KuCoin
A35: OKX
A36: Phemex

Sheet Bitcoin
A1: vpn | B1: my_prod_type | C1: my_fi_name | D1: my_pf_name | E1: pf_locator | F1: top_currency | G1: base_currency | H1: comm_type | I1: comm_maker | J1: comm_taker | K1: comm_misc | L1: comm_update
A2: TRUE | B2: spot | C2: BTC-USD | D2: BinanceSpot | E2: BTCUSD | F2: import | G2: import | H2: flat_pct | I2: 0.001 | J2: 0.001 | K2: 0
A3: TRUE | B3: spot | C3: BTC-USD1 | D3: BinanceSpot | E3: BTCUSD1 | F3: import | G3: import | H3: flat_pct | I3: 0.001 | J3: 0.001 | K3: 0
A4: TRUE | B4: spot | C4: BTC-USDC | D4: BinanceSpot | E4: BTCUSDC | F4: import | G4: import | H4: flat_pct | I4: 0.001 | J4: 0.001 | K4: 0
A5: TRUE | B5: spot | C5: BTC-USDT | D5: BinanceSpot | E5: BTCUSDT | F5: import | G5: import | H5: flat_pct | I5: 0.001 | J5: 0.001 | K5: 0
A6: FALSE | B6: spot | C6: BTC-USD | D6: BinanceUS | E6: BTCUSD | F6: import | G6: import | H6: flat_pct | I6: 0.001 | J6: 0.001 | K6: 0
A7: FALSE | B7: spot | C7: BTC-USDC | D7: BinanceUS | E7: BTCUSDC | F7: import | G7: import | H7: flat_pct | I7: 0.001 | J7: 0.001 | K7: 0
A8: FALSE | B8: spot | C8: BTC-USDT | D8: BinanceUS | E8: BTCUSDT | F8: import | G8: import | H8: flat_pct | I8: 0.001 | J8: 0.001 | K8: 0
A9: TRUE | B9: spot | C9: BTC-USD | D9: Bitfinex | E9: tBTCUSD | F9: USD | G9: BTC | H9: flat_pct | I9: 0.001 | J9: 0.002 | K9: 0
A10: TRUE | B10: spot | C10: BTC-USDT | D10: Bitfinex | E10: tBTCUST | F10: USDT | G10: BTC | H10: flat_pct | I10: 0.001 | J10: 0.002 | K10: 0
A11: TRUE | B11: spot | C11: BTC-USD | D11: Bybit | E11: BTCUSD | F11: import | G11: import | H11: flat_pct | I11: 0.001 | J11: 0.001 | K11: 0
A12: TRUE | B12: spot | C12: BTC-USDC | D12: Bybit | E12: BTCUSDC | F12: import | G12: import | H12: flat_pct | I12: 0.001 | J12: 0.001 | K12: 0
A13: TRUE | B13: spot | C13: BTC-USDT | D13: Bybit | E13: BTCUSDT | F13: import | G13: import | H13: flat_pct | I13: 0.001 | J13: 0.001 | K13: 0
... A26: TRUE | B26: spot | C26: BTC-USDT | D26: Huobi | E26: btcusdt | F26: import | G26: import | H26: flat_pct | I26: 0.002 | J26: 0.002 | K26: 0
A27: FALSE | B27: spot | C27: BTC-USD | D27: IBKR | E27: 541686651 | F27: USD | G27: BTC | H27: flat_pct_with_min | I27: 0.0012 | J27: 0.0012 | K27: 1.75 | L27: 46054
A28: FALSE | B28: spot | C28: BTC-USD | D28: KrakenSpot | E28: BTC/USD | F28: import | G28: import | H28: flat_pct | I28: 0.0016 | J28: 0.0026 | K28: 0
A29: FALSE | B29: spot | C29: BTC-USD1 | D29: KrakenSpot | E29: BTC/USD1 | F29: import | G29: import | H29: flat_pct | I29: 0.0016 | J29: 0.0026 | K29: 0
A30: FALSE | B30: spot | C30: BTC-USDC | D30: KrakenSpot | E30: BTC/USDC | F30: import | G30: import | H30: flat_pct | I30: 0.0016 | J30: 0.0026 | K30: 0
A31: FALSE | B31: spot | C31: BTC-USDT | D31: KrakenSpot | E31: BTC/USDT | F31: import | G31: import | H31: flat_pct | I31: 0.0016 | J31: 0.0026 | K31: 0
A32: TRUE | B32: spot | C32: BTC-USD1 | D32: KuCoinSpot | E32: BTC-USD1 | F32: import | G32: import | H32: flat_pct | I32: 0.001 | J32: 0.001 | K32: 0
A33: TRUE | B33: spot | C33: BTC-USDC | D33: KuCoinSpot | E33: BTC-USDC | F33: import | G33: import | H33: flat_pct | I33: 0.001 | J33: 0.001 | K33: 0
A34: TRUE | B34: spot | C34: BTC-USDT | D34: KuCoinSpot | E34: BTC-USDT | F34: import | G34: import | H34: flat_pct | I34: 0.001 | J34: 0.001 | K34: 0
A35: TRUE | B35: spot | C35: BTC-USD1 | D35: MEXC | E35: BTCUSD1 | F35: import | G35: import | H35: flat_pct | I35: 0 | J35: 0 | K35: 0
A36: TRUE | B36: spot | C36: BTC-USDC | D36: MEXC | E36: BTCUSDC | F36: import | G36: import | H36: flat_pct | I36: 0 | J36: 0 | K36: 0
A37: TRUE | B37: spot | C37: BTC-USDT | D37: MEXC | E37: BTCUSDT | F37: import | G37: import | H37: flat_pct | I37: 0 | J37: 0 | K37: 0
A38: TRUE | B38: spot | C38: BTC-USD | D38: OKX | E38: BTC-USD | F38: import | G38: import | H38: flat_pct | I38: 0.0008 | J38: 0.001 | K38: 0
A39: TRUE | B39: spot | C39: BTC-USDC | D39: OKX | E39: BTC-USDC | F39: import | G39: import | H39: flat_pct | I39: 0.0008 | J39: 0.001 | K39: 0
... A42: TRUE | B42: spot | C42: BTC-USDT | D42: Phemex | E42: sBTCUSDT | F42: import | G42: import | H42: flat_pct | I42: 0.001 | J42: 0.001 | K42: 0
A43: TRUE | B43: future | C43: BTCM6 | D43: Coinbase-Derivs | E43: BIT-26JUN26-CDE | F43: USD | G43: BTC | H43: flat_amt | I43: 12.52 | J43: 12.52 | K43: 0 | L43: 46054
A44: TRUE | B44: future | C44: BTCN6 | D44: Coinbase-Derivs | E44: BIT-31JUL26-CDE | F44: USD | G44: BTC | H44: flat_amt | I44: 12.52 | J44: 12.52 | K44: 0 | L44: 46054
A45: TRUE | B45: future | C45: BTCQ6 | D45: Coinbase-Derivs | E45: BIT-28AUG26-CDE | F45: USD | G45: BTC | H45: flat_amt | I45: 12.52 | J45: 12.52 | K45: 0 | L45: 46054
A46: TRUE | B46: future | C46: BTCM6 | D46: Deribit | E46: BTC-26JUN26 | F46: import | G46: import | H46: flat_amt | I46: import | J46: import | K46: 0
A47: TRUE | B47: future | C47: BTCN6 | D47: Deribit | E47: BTC-31JUL26 | F47: import | G47: import | H47: flat_amt | I47: import | J47: import | K47: 0
A48: TRUE | B48: future | C48: BTCQ6 | D48: Deribit | E48: BTC-28AUG26 | F48: import | G48: import | H48: flat_amt | I48: import | J48: import | K48: 0
A49: TRUE | B49: future | C49: BTCU6 | D49: Deribit | E49: BTC-25SEP26 | F49: import | G49: import | H49: flat_amt | I49: import | J49: import | K49: 0
A50: TRUE | B50: future | C50: BTCZ6 | D50: Deribit | E50: BTC-25DEC26 | F50: import | G50: import | H50: flat_amt | I50: import | J50: import | K50: 0
A51: TRUE | B51: future | C51: BTCH7 | D51: Deribit | E51: BTC-26MAR27 | F51: import | G51: import | H51: flat_amt | I51: import | J51: import | K51: 0
A52: FALSE | B52: future | C52: BTCM6 | D52: IBKR | E52: 751356962 | F52: USD | G52: BTC | H52: flat_amt | I52: 12.52 | J52: 12.52 | K52: 0 | L52: 46054
A53: FALSE | B53: future | C53: BTCN6 | D53: IBKR | E53: 850790355 | F53: USD | G53: BTC | H53: flat_amt | I53: 12.52 | J53: 12.52 | K53: 0 | L53: 46054
A54: FALSE | B54: future | C54: BTCQ6 | D54: IBKR | E54: 859040542 | F54: USD | G54: BTC | H54: flat_amt | I54: 12.52 | J54: 12.52 | K54: 0 | L54: 46054
...

Sheet Ethereum
A1: * | B1: my_prod_type | C1: my_platform | D1: crypto_currency | E1: quote_currency | F1: fut_coll_currency | G1: fut_settle_type | H1: my_name | I1: platform_id | J1: ibkr_conId | K1: platform_symbol | L1: platform_type | M1: price_scalar | N1: size_scalar | O1: scalar_fee | P1: scalar_date | Q1: comm_type | R1: comm_maker | S1: comm_taker | T1: comm_min | U1: comm_update | V1: settle_days_trade | W1: settle_days_comm | X1: settle_days_expiry | Y1: settle_update
B2: spot | C2: Binance | E2: USDT | I2: Binance | J2: none | M2: none | N2: none | O2: none | P2: 46047 | Q2: flat_pct | T2: 0 | V2: 0 | W2: 0 | X2: none | Y2: 46046
B3: spot | C3: Bitfinex | E3: USDT | I3: Bitfinex | J3: none | M3: none | N3: none | O3: none | P3: 46047 | Q3: flat_pct | T3: 0 | V3: 0 | W3: 0 | X3: none | Y3: 46046
B4: spot | C4: Bitget | I4: Bitget | J4: none | M4: none | N4: none | O4: none | P4: 46047 | X4: none | Y4: 46053
B5: spot | C5: Bybit | E5: USDT | I5: Bybit | J5: none | M5: none | N5: none | O5: none | P5: 46047 | Q5: flat_pct | T5: 0 | V5: 0 | W5: 0 | X5: none | Y5: 46046
B6: spot | C6: Coinbase | E6: USD | I6: Coinbase | J6: none | M6: none | N6: none | O6: none | P6: 46047 | Q6: flat_pct | T6: 0 | V6: 0 | W6: 0 | X6: none | Y6: 46046
B7: spot | C7: Delta | I7: Delta | J7: none | M7: none | N7: none | O7: none | P7: 46053 | V7: 0 | W7: 0 | X7: none | Y7: 46053
B8: spot | C8: Deribit | I8: Deribit | J8: none | M8: none | N8: none | O8: none | P8: 46047 | V8: 0 | W8: 0 | X8: none | Y8: 46053
B9: spot | C9: Gemini | E9: USD | I9: Gemini | J9: none | M9: none | N9: none | O9: none | P9: 46047 | Q9: flat_pct | T9: 0 | V9: 0 | W9: 0 | X9: none | Y9: 46046
B10: spot | C10: Huobi | E10: USD | I10: Huobi | J10: none | M10: none | N10: none | O10: none | P10: 46047 | Q10: flat_pct | T10: 0 | V10: 0 | W10: 0 | X10: none | Y10: 46046
B11: spot | C11: IBKR | E11: USD | H11: IBKR_ETH | I11: IBKR | J11: 541686654 | K11: ETH.USD | M11: none | N11: none | O11: none | P11: 46053 | Q11: flat_pct_with_min | V11: 0 | W11: 0 | X11: none | Y11: 46046
B12: spot | C12: Kraken | E12: USD | I12: Kraken | J12: none | M12: none | N12: none | O12: none | P12: 46047 | Q12: flat_pct | T12: 0 | V12: 0 | W12: 0 | X12: none | Y12: 46046
B13: spot | C13: KuCoin | E13: USD | I13: KuCoin | J13: none | M13: none | N13: none | O13: none | P13: 46047 | Q13: flat_pct | T13: 0 | V13: 0 | W13: 0 | X13: none | Y13: 46046
B14: spot | C14: OKX | E14: USDT | I14: OKX | J14: none | M14: none | N14: none | O14: none | P14: 46047 | Q14: flat_pct | T14: 0 | V14: 0 | W14: 0 | X14: none | Y14: 46046
B15: perp | C15: Binance | I15: Binance | J15: none | M15: none | N15: none | O15: none | P15: 46053
B16: perp | C16: Bitfinex | I16: Bitfinex | J16: none | M16: none | N16: none | O16: none | P16: 46054
B17: perp | C17: Bitget | I17: Bitget | J17: none | M17: none | N17: none | O17: none | P17: 46055
B18: perp | C18: Bybit | I18: Bybit | J18: none | M18: none | N18: none | O18: none | P18: 46056
B19: perp | C19: Coinbase | I19: Coinbase | J19: none | M19: none | N19: none | O19: none | P19: 46057
B20: perp | C20: Delta | I20: Delta | J20: none | M20: none | N20: none | O20: none | P20: 46058
B21: perp | C21: Deribit | I21: Deribit | J21: none | M21: none | N21: none | O21: none | P21: 46059
B22: perp | C22: Gemini | I22: Gemini | J22: none | M22: none | N22: none | O22: none | P22: 46060
B23: perp | C23: Huobi | I23: Huobi | J23: none | M23: none | N23: none | O23: none | P23: 46061
B24: perp | C24: Kraken | I24: Kraken | J24: none | M24: none | N24: none | O24: none | P24: 46062
B25: perp | C25: KuCoin | I25: KuCoin | J25: none | M25: none | N25: none | O25: none | P25: 46063
B26: perp | C26: OKX | I26: OKX | J26: none | M26: none | N26: none | O26: none | P26: 46064
B27: option | C27: IBKR | I27: IBKR | J27: various
B28: option | C28: IBKR | I28: IBKR | J28: various
B29: option | C29: IBKR | I29: IBKR | J29: none
B30: option | C30: IBKR | I30: IBKR | J30: various
B31: option | C31: IBKR | I31: IBKR | J31: various
B32: option | C32: IBKR | I32: IBKR | J32: various
B33: option | C33: IBKR | I33: IBKR | J33: various
B34: option | C34: IBKR | I34: IBKR | J34: various
B35: option | C35: IBKR | I35: IBKR | J35: various
B36: option | C36: IBKR | I36: IBKR | J36: various
B37: option | C37: Binance | I37: Binance | J37: none | O37: none
B38: option | C38: Bitfinex | I38: Bitfinex | J38: none | O38: none
B39: option | C39: Bitget | I39: Bitget | J39: none | O39: none
B40: option | C40: Bybit | I40: Bybit | J40: none | O40: none
...

Sheet ETF Options Summary - BTC
A1: last update | B1: ='ARKB Options'!$A$1 -> 46098.676 | C1: ='BITB Options'!$A$1 -> 46098.676 | D1: ='BTC Options'!$A$1 -> 46098.677 | E1: ='BTCW Options'!$A$1 -> 46098.677 | F1: ='EZBC Options'!$A$1 -> 46098.676 | G1: ='FBTC Options'!$A$1 -> 46098.68 | H1: ='GBTC Options'!$A$1 -> 46098.679 | I1: ='HODL Options'!$A$1 -> 46098.677 | J1: ='IBIT Options'!$A$1 -> 46098.683
A2: count | B2: =COUNT('ARKB Options'!$E:$E) -> 430 | C2: =COUNT('BITB Options'!$E:$E) -> 408 | D2: =COUNT('BTC Options'!$E:$E) -> 580 | E2: =COUNT('BTCW Options'!$E:$E) -> 302 | F2: =COUNT('EZBC Options'!$E:$E) -> 310 | G2: =COUNT('FBTC Options'!$E:$E) -> 1060 | H2: =COUNT('GBTC Options'!$E:$E) -> 902 | I2: =COUNT('HODL Options'!$E:$E) -> 194 | J2: =COUNT('IBIT Options'!$E:$E) -> 3020
B3: ARKB | C3: BITB | D3: BTC | E3: BTCW | F3: EZBC | G3: FBTC | H3: GBTC | I3: HODL | J3: IBIT | L3: unique | M3: sorted | N3: =B3 -> ARKB | O3: =C3 -> BITB | P3: =D3 -> BTC | Q3: =E3 -> BTCW | R3: =F3 -> EZBC | S3: =G3 -> FBTC | T3: =H3 -> GBTC | U3: =I3 -> HODL | V3: =J3 -> IBIT
B4: {=_xlfn.UNIQUE('ARKB Options'!$D:$D)} -> 0 | C4: {=_xlfn.UNIQUE('BITB Options'!$D:$D)} -> 0 | D4: {=_xlfn.UNIQUE('BTC Options'!$D:$D)} -> 0 | E4: {=_xlfn.UNIQUE('BTCW Options'!$D:$D)} -> 0 | F4: {=_xlfn.UNIQUE('EZBC Options'!$D:$D)} -> 0 | G4: {=_xlfn.UNIQUE('FBTC Options'!$D:$D)} -> 0 | H4: {=_xlfn.UNIQUE('GBTC Options'!$D:$D)} -> 0 | I4: {=_xlfn.UNIQUE('HODL Options'!$D:$D)} -> 0 | J4: {=_xlfn.UNIQUE('IBIT Options'!$D:$D)} -> 0 | L4: {=_xlfn.UNIQUE(_xlfn.TOCOL(B6:J49, 1))} -> 20260320 | M4: {=_xlfn._xlws.SORT(_xlfn.ANCHORARRAY(L4))} -> 20260318 | N4: =ISNUMBER(MATCH($M4, B$6:B$50, 0)) -> FALSE | O4: =ISNUMBER(MATCH($M4, C$6:C$50, 0)) -> FALSE | P4: =ISNUMBER(MATCH($M4, D$6:D$50, 0)) -> FALSE | Q4: =ISNUMBER(MATCH($M4, E$6:E$50, 0)) -> FALSE | R4: =ISNUMBER(MATCH($M4, F$6:F$50, 0)) -> FALSE | S4: =ISNUMBER(MATCH($M4, G$6:G$50, 0)) -> FALSE | T4: =ISNUMBER(MATCH($M4, H$6:H$50, 0)) -> FALSE | U4: =ISNUMBER(MATCH($M4, I$6:I$50, 0)) -> FALSE | V4: =ISNUMBER(MATCH($M4, J$6:J$50, 0)) -> TRUE
B5: expiry | C5: expiry | D5: expiry | E5: expiry | F5: expiry | G5: expiry | H5: expiry | I5: expiry | J5: expiry | L5: 20260318 | M5: 20260320 | N5: =ISNUMBER(MATCH($M5, B$6:B$50, 0)) -> TRUE | O5: =ISNUMBER(MATCH($M5, C$6:C$50, 0)) -> TRUE | P5: =ISNUMBER(MATCH($M5, D$6:D$50, 0)) -> TRUE | Q5: =ISNUMBER(MATCH($M5, E$6:E$50, 0)) -> TRUE | R5: =ISNUMBER(MATCH($M5, F$6:F$50, 0)) -> TRUE | S5: =ISNUMBER(MATCH($M5, G$6:G$50, 0)) -> TRUE | T5: =ISNUMBER(MATCH($M5, H$6:H$50, 0)) -> TRUE | U5: =ISNUMBER(MATCH($M5, I$6:I$50, 0)) -> TRUE | V5: =ISNUMBER(MATCH($M5, J$6:J$50, 0)) -> TRUE
A6: expiries | B6: 20260320 | C6: 20260320 | D6: 20260320 | E6: 20260320 | F6: 20260320 | G6: 20260320 | H6: 20260320 | I6: 20260320 | J6: 20260318 | L6: 20260417 | M6: 20260323 | N6: =ISNUMBER(MATCH($M6, B$6:B$50, 0)) -> FALSE | O6: =ISNUMBER(MATCH($M6, C$6:C$50, 0)) -> FALSE | P6: =ISNUMBER(MATCH($M6, D$6:D$50, 0)) -> FALSE | Q6: =ISNUMBER(MATCH($M6, E$6:E$50, 0)) -> FALSE | R6: =ISNUMBER(MATCH($M6, F$6:F$50, 0)) -> FALSE | S6: =ISNUMBER(MATCH($M6, G$6:G$50, 0)) -> FALSE | T6: =ISNUMBER(MATCH($M6, H$6:H$50, 0)) -> FALSE | U6: =ISNUMBER(MATCH($M6, I$6:I$50, 0)) -> FALSE | V6: =ISNUMBER(MATCH($M6, J$6:J$50, 0)) -> TRUE
A7: expiries | B7: 20260417 | C7: 20260417 | D7: 20260417 | E7: 20260417 | F7: 20260417 | G7: 20260327 | H7: 20260327 | I7: 20260417 | J7: 20260320 | L7: 20260327 | M7: 20260325 | N7: =ISNUMBER(MATCH($M7, B$6:B$50, 0)) -> FALSE | O7: =ISNUMBER(MATCH($M7, C$6:C$50, 0)) -> FALSE | P7: =ISNUMBER(MATCH($M7, D$6:D$50, 0)) -> FALSE | Q7: =ISNUMBER(MATCH($M7, E$6:E$50, 0)) -> FALSE | R7: =ISNUMBER(MATCH($M7, F$6:F$50, 0)) -> FALSE | S7: =ISNUMBER(MATCH($M7, G$6:G$50, 0)) -> FALSE | T7: =ISNUMBER(MATCH($M7, H$6:H$50, 0)) -> FALSE | U7: =ISNUMBER(MATCH($M7, I$6:I$50, 0)) -> FALSE | V7: =ISNUMBER(MATCH($M7, J$6:J$50, 0)) -> TRUE
A8: expiries | B8: 20260618 | C8: 20260618 | D8: 20260618 | E8: 20260618 | F8: 20260618 | G8: 20260402 | H8: 20260402 | I8: 20260515 | J8: 20260323 | L8: 20260618 | M8: 20260327 | N8: =ISNUMBER(MATCH($M8, B$6:B$50, 0)) -> FALSE | O8: =ISNUMBER(MATCH($M8, C$6:C$50, 0)) -> FALSE | P8: =ISNUMBER(MATCH($M8, D$6:D$50, 0)) -> FALSE | Q8: =ISNUMBER(MATCH($M8, E$6:E$50, 0)) -> FALSE | R8: =ISNUMBER(MATCH($M8, F$6:F$50, 0)) -> FALSE | S8: =ISNUMBER(MATCH($M8, G$6:G$50, 0)) -> TRUE | T8: =ISNUMBER(MATCH($M8, H$6:H$50, 0)) -> TRUE | U8: =ISNUMBER(MATCH($M8, I$6:I$50, 0)) -> FALSE | V8: =ISNUMBER(MATCH($M8, J$6:J$50, 0)) -> TRUE
A9: expiries | B9: 20260918 | C9: 20260918 | D9: 20260918 | E9: 20260918 | F9: 20260918 | G9: 20260410 | H9: 20260410 | I9: 20260821 | J9: 20260325 | L9: 20260402 | M9: 20260330 | N9: =ISNUMBER(MATCH($M9, B$6:B$50, 0)) -> FALSE | O9: =ISNUMBER(MATCH($M9, C$6:C$50, 0)) -> FALSE | P9: =ISNUMBER(MATCH($M9, D$6:D$50, 0)) -> FALSE | Q9: =ISNUMBER(MATCH($M9, E$6:E$50, 0)) -> FALSE | R9: =ISNUMBER(MATCH($M9, F$6:F$50, 0)) -> FALSE | S9: =ISNUMBER(MATCH($M9, G$6:G$50, 0)) -> FALSE | T9: =ISNUMBER(MATCH($M9, H$6:H$50, 0)) -> FALSE | U9: =ISNUMBER(MATCH($M9, I$6:I$50, 0)) -> FALSE | V9: =ISNUMBER(MATCH($M9, J$6:J$50, 0)) -> TRUE
A10: expiries | B10: 20270115 | C10: 20270115 | D10: 20270115 | G10: 20260417 | H10: 20260417 | J10: 20260327 | L10: 20260515 | M10: 20260331 | N10: =ISNUMBER(MATCH($M10, B$6:B$50, 0)) -> FALSE | O10: =ISNUMBER(MATCH($M10, C$6:C$50, 0)) -> FALSE | P10: =ISNUMBER(MATCH($M10, D$6:D$50, 0)) -> FALSE | Q10: =ISNUMBER(MATCH($M10, E$6:E$50, 0)) -> FALSE | R10: =ISNUMBER(MATCH($M10, F$6:F$50, 0)) -> FALSE | S10: =ISNUMBER(MATCH($M10, G$6:G$50, 0)) -> FALSE | T10: =ISNUMBER(MATCH($M10, H$6:H$50, 0)) -> FALSE | U10: =ISNUMBER(MATCH($M10, I$6:I$50, 0)) -> FALSE | V10: =ISNUMBER(MATCH($M10, J$6:J$50, 0)) -> TRUE
A11: expiries | B11: 20280121 | D11: 20280121 | G11: 20260424 | H11: 20260424 | J11: 20260330 | L11: 20260323 | M11: 20260401 | N11: =ISNUMBER(MATCH($M11, B$6:B$50, 0)) -> FALSE | O11: =ISNUMBER(MATCH($M11, C$6:C$50, 0)) -> FALSE | P11: =ISNUMBER(MATCH($M11, D$6:D$50, 0)) -> FALSE | Q11: =ISNUMBER(MATCH($M11, E$6:E$50, 0)) -> FALSE | R11: =ISNUMBER(MATCH($M11, F$6:F$50, 0)) -> FALSE | S11: =ISNUMBER(MATCH($M11, G$6:G$50, 0)) -> FALSE | T11: =ISNUMBER(MATCH($M11, H$6:H$50, 0)) -> FALSE | U11: =ISNUMBER(MATCH($M11, I$6:I$50, 0)) -> FALSE | V11: =ISNUMBER(MATCH($M11, J$6:J$50, 0)) -> TRUE
A12: expiries | G12: 20260501 | H12: 20260501 | J12: 20260331 | L12: 20260918 | M12: 20260402 | N12: =ISNUMBER(MATCH($M12, B$6:B$50, 0)) -> FALSE | O12: =ISNUMBER(MATCH($M12, C$6:C$50, 0)) -> FALSE | P12: =ISNUMBER(MATCH($M12, D$6:D$50, 0)) -> FALSE | Q12: =ISNUMBER(MATCH($M12, E$6:E$50, 0)) -> FALSE | R12: =ISNUMBER(MATCH($M12, F$6:F$50, 0)) -> FALSE | S12: =ISNUMBER(MATCH($M12, G$6:G$50, 0)) -> TRUE | T12: =ISNUMBER(MATCH($M12, H$6:H$50, 0)) -> TRUE | U12: =ISNUMBER(MATCH($M12, I$6:I$50, 0)) -> FALSE | V12: =ISNUMBER(MATCH($M12, J$6:J$50, 0)) -> TRUE
A13: expiries | G13: 20260618 | H13: 20260618 | J13: 20260401 | L13: 20260410 | M13: 20260410 | N13: =ISNUMBER(MATCH($M13, B$6:B$50, 0)) -> FALSE | O13: =ISNUMBER(MATCH($M13, C$6:C$50, 0)) -> FALSE | P13: =ISNUMBER(MATCH($M13, D$6:D$50, 0)) -> FALSE | Q13: =ISNUMBER(MATCH($M13, E$6:E$50, 0)) -> FALSE | R13: =ISNUMBER(MATCH($M13, F$6:F$50, 0)) -> FALSE | S13: =ISNUMBER(MATCH($M13, G$6:G$50, 0)) -> TRUE | T13: =ISNUMBER(MATCH($M13, H$6:H$50, 0)) -> TRUE | U13: =ISNUMBER(MATCH($M13, I$6:I$50, 0)) -> FALSE | V13: =ISNUMBER(MATCH($M13, J$6:J$50, 0)) -> TRUE
A14: expiries | G14: 20260918 | H14: 20260918 | J14: 20260402 | L14: 20260821 | M14: 20260417 | N14: =ISNUMBER(MATCH($M14, B$6:B$50, 0)) -> TRUE | O14: =ISNUMBER(MATCH($M14, C$6:C$50, 0)) -> TRUE | P14: =ISNUMBER(MATCH($M14, D$6:D$50, 0)) -> TRUE | Q14: =ISNUMBER(MATCH($M14, E$6:E$50, 0)) -> TRUE | R14: =ISNUMBER(MATCH($M14, F$6:F$50, 0)) -> TRUE | S14: =ISNUMBER(MATCH($M14, G$6:G$50, 0)) -> TRUE | T14: =ISNUMBER(MATCH($M14, H$6:H$50, 0)) -> TRUE | U14: =ISNUMBER(MATCH($M14, I$6:I$50, 0)) -> TRUE | V14: =ISNUMBER(MATCH($M14, J$6:J$50, 0)) -> TRUE
A15: expiries | G15: 20270115 | H15: 20270115 | J15: 20260410 | L15: 20260325 | M15: 20260424 | N15: =ISNUMBER(MATCH($M15, B$6:B$50, 0)) -> FALSE | O15: =ISNUMBER(MATCH($M15, C$6:C$50, 0)) -> FALSE | P15: =ISNUMBER(MATCH($M15, D$6:D$50, 0)) -> FALSE | Q15: =ISNUMBER(MATCH($M15, E$6:E$50, 0)) -> FALSE | R15: =ISNUMBER(MATCH($M15, F$6:F$50, 0)) -> FALSE | S15: =ISNUMBER(MATCH($M15, G$6:G$50, 0)) -> TRUE | T15: =ISNUMBER(MATCH($M15, H$6:H$50, 0)) -> TRUE | U15: =ISNUMBER(MATCH($M15, I$6:I$50, 0)) -> FALSE | V15: =ISNUMBER(MATCH($M15, J$6:J$50, 0)) -> TRUE | W15: futures date
A16: expiries | G16: 20280121 | H16: 20280121 | J16: 20260417 | L16: 20270115 | M16: 20260501 | N16: =ISNUMBER(MATCH($M16, B$6:B$50, 0)) -> FALSE | O16: =ISNUMBER(MATCH($M16, C$6:C$50, 0)) -> FALSE | P16: =ISNUMBER(MATCH($M16, D$6:D$50, 0)) -> FALSE | Q16: =ISNUMBER(MATCH($M16, E$6:E$50, 0)) -> FALSE | R16: =ISNUMBER(MATCH($M16, F$6:F$50, 0)) -> FALSE | S16: =ISNUMBER(MATCH($M16, G$6:G$50, 0)) -> TRUE | T16: =ISNUMBER(MATCH($M16, H$6:H$50, 0)) -> TRUE | U16: =ISNUMBER(MATCH($M16, I$6:I$50, 0)) -> FALSE | V16: =ISNUMBER(MATCH($M16, J$6:J$50, 0)) -> TRUE
A17: expiries | J17: 20260424 | L17: 20280121 | M17: 20260515 | N17: =ISNUMBER(MATCH($M17, B$6:B$50, 0)) -> FALSE | O17: =ISNUMBER(MATCH($M17, C$6:C$50, 0)) -> FALSE | P17: =ISNUMBER(MATCH($M17, D$6:D$50, 0)) -> FALSE | Q17: =ISNUMBER(MATCH($M17, E$6:E$50, 0)) -> FALSE | R17: =ISNUMBER(MATCH($M17, F$6:F$50, 0)) -> FALSE | S17: =ISNUMBER(MATCH($M17, G$6:G$50, 0)) -> FALSE | T17: =ISNUMBER(MATCH($M17, H$6:H$50, 0)) -> FALSE | U17: =ISNUMBER(MATCH($M17, I$6:I$50, 0)) -> TRUE | V17: =ISNUMBER(MATCH($M17, J$6:J$50, 0)) -> TRUE
A18: expiries | J18: 20260501 | L18: 20260424 | M18: 20260618 | N18: =ISNUMBER(MATCH($M18, B$6:B$50, 0)) -> TRUE | O18: =ISNUMBER(MATCH($M18, C$6:C$50, 0)) -> TRUE | P18: =ISNUMBER(MATCH($M18, D$6:D$50, 0)) -> TRUE | Q18: =ISNUMBER(MATCH($M18, E$6:E$50, 0)) -> TRUE | R18: =ISNUMBER(MATCH($M18, F$6:F$50, 0)) -> TRUE | S18: =ISNUMBER(MATCH($M18, G$6:G$50, 0)) -> TRUE | T18: =ISNUMBER(MATCH($M18, H$6:H$50, 0)) -> TRUE | U18: =ISNUMBER(MATCH($M18, I$6:I$50, 0)) -> FALSE | V18: =ISNUMBER(MATCH($M18, J$6:J$50, 0)) -> TRUE
A19: expiries | J19: 20260515 | L19: 20260330 | M19: 20260630 | N19: =ISNUMBER(MATCH($M19, B$6:B$50, 0)) -> FALSE | O19: =ISNUMBER(MATCH($M19, C$6:C$50, 0)) -> FALSE | P19: =ISNUMBER(MATCH($M19, D$6:D$50, 0)) -> FALSE | Q19: =ISNUMBER(MATCH($M19, E$6:E$50, 0)) -> FALSE | R19: =ISNUMBER(MATCH($M19, F$6:F$50, 0)) -> FALSE | S19: =ISNUMBER(MATCH($M19, G$6:G$50, 0)) -> FALSE | T19: =ISNUMBER(MATCH($M19, H$6:H$50, 0)) -> FALSE | U19: =ISNUMBER(MATCH($M19, I$6:I$50, 0)) -> FALSE | V19: =ISNUMBER(MATCH($M19, J$6:J$50, 0)) -> TRUE
A20: expiries | J20: 20260618 | L20: 20260501 | M20: 20260731 | N20: =ISNUMBER(MATCH($M20, B$6:B$50, 0)) -> FALSE | O20: =ISNUMBER(MATCH($M20, C$6:C$50, 0)) -> FALSE | P20: =ISNUMBER(MATCH($M20, D$6:D$50, 0)) -> FALSE | Q20: =ISNUMBER(MATCH($M20, E$6:E$50, 0)) -> FALSE | R20: =ISNUMBER(MATCH($M20, F$6:F$50, 0)) -> FALSE | S20: =ISNUMBER(MATCH($M20, G$6:G$50, 0)) -> FALSE | T20: =ISNUMBER(MATCH($M20, H$6:H$50, 0)) -> FALSE | U20: =ISNUMBER(MATCH($M20, I$6:I$50, 0)) -> FALSE | V20: =ISNUMBER(MATCH($M20, J$6:J$50, 0)) -> TRUE
A21: expiries | J21: 20260630 | L21: 20260331 | M21: 20260821 | N21: =ISNUMBER(MATCH($M21, B$6:B$50, 0)) -> FALSE | O21: =ISNUMBER(MATCH($M21, C$6:C$50, 0)) -> FALSE | P21: =ISNUMBER(MATCH($M21, D$6:D$50, 0)) -> FALSE | Q21: =ISNUMBER(MATCH($M21, E$6:E$50, 0)) -> FALSE | R21: =ISNUMBER(MATCH($M21, F$6:F$50, 0)) -> FALSE | S21: =ISNUMBER(MATCH($M21, G$6:G$50, 0)) -> FALSE | T21: =ISNUMBER(MATCH($M21, H$6:H$50, 0)) -> FALSE | U21: =ISNUMBER(MATCH($M21, I$6:I$50, 0)) -> TRUE | V21: =ISNUMBER(MATCH($M21, J$6:J$50, 0)) -> TRUE
A22: expiries | J22: 20260731 | L22: 20260401 | M22: 20260831 | N22: =ISNUMBER(MATCH($M22, B$6:B$50, 0)) -> FALSE | O22: =ISNUMBER(MATCH($M22, C$6:C$50, 0)) -> FALSE | P22: =ISNUMBER(MATCH($M22, D$6:D$50, 0)) -> FALSE | Q22: =ISNUMBER(MATCH($M22, E$6:E$50, 0)) -> FALSE | R22: =ISNUMBER(MATCH($M22, F$6:F$50, 0)) -> FALSE | S22: =ISNUMBER(MATCH($M22, G$6:G$50, 0)) -> FALSE | T22: =ISNUMBER(MATCH($M22, H$6:H$50, 0)) -> FALSE | U22: =ISNUMBER(MATCH($M22, I$6:I$50, 0)) -> FALSE | V22: =ISNUMBER(MATCH($M22, J$6:J$50, 0)) -> TRUE
A23: expiries | J23: 20260821 | L23: 20260630 | M23: 20260918 | N23: =ISNUMBER(MATCH($M23, B$6:B$50, 0)) -> TRUE | O23: =ISNUMBER(MATCH($M23, C$6:C$50, 0)) -> TRUE | P23: =ISNUMBER(MATCH($M23, D$6:D$50, 0)) -> TRUE | Q23: =ISNUMBER(MATCH($M23, E$6:E$50, 0)) -> TRUE | R23: =ISNUMBER(MATCH($M23, F$6:F$50, 0)) -> TRUE | S23: =ISNUMBER(MATCH($M23, G$6:G$50, 0)) -> TRUE | T23: =ISNUMBER(MATCH($M23, H$6:H$50, 0)) -> TRUE | U23: =ISNUMBER(MATCH($M23, I$6:I$50, 0)) -> FALSE | V23: =ISNUMBER(MATCH($M23, J$6:J$50, 0)) -> TRUE
A24: expiries | J24: 20260831 | L24: 20260731 | M24: 20261016 | N24: =ISNUMBER(MATCH($M24, B$6:B$50, 0)) -> FALSE | O24: =ISNUMBER(MATCH($M24, C$6:C$50, 0)) -> FALSE | P24: =ISNUMBER(MATCH($M24, D$6:D$50, 0)) -> FALSE | Q24: =ISNUMBER(MATCH($M24, E$6:E$50, 0)) -> FALSE | R24: =ISNUMBER(MATCH($M24, F$6:F$50, 0)) -> FALSE | S24: =ISNUMBER(MATCH($M24, G$6:G$50, 0)) -> FALSE | T24: =ISNUMBER(MATCH($M24, H$6:H$50, 0)) -> FALSE | U24: =ISNUMBER(MATCH($M24, I$6:I$50, 0)) -> FALSE | V24: =ISNUMBER(MATCH($M24, J$6:J$50, 0)) -> TRUE
A25: expiries | J25: 20260918 | L25: 20260831 | M25: 20261130 | N25: =ISNUMBER(MATCH($M25, B$6:B$50, 0)) -> FALSE | O25: =ISNUMBER(MATCH($M25, C$6:C$50, 0)) -> FALSE | P25: =ISNUMBER(MATCH($M25, D$6:D$50, 0)) -> FALSE | Q25: =ISNUMBER(MATCH($M25, E$6:E$50, 0)) -> FALSE | R25: =ISNUMBER(MATCH($M25, F$6:F$50, 0)) -> FALSE | S25: =ISNUMBER(MATCH($M25, G$6:G$50, 0)) -> FALSE | T25: =ISNUMBER(MATCH($M25, H$6:H$50, 0)) -> FALSE | U25: =ISNUMBER(MATCH($M25, I$6:I$50, 0)) -> FALSE | V25: =ISNUMBER(MATCH($M25, J$6:J$50, 0)) -> TRUE
A26: expiries | J26: 20261016 | L26: 20261016 | M26: 20270115 | N26: =ISNUMBER(MATCH($M26, B$6:B$50, 0)) -> TRUE | O26: =ISNUMBER(MATCH($M26, C$6:C$50, 0)) -> TRUE | P26: =ISNUMBER(MATCH($M26, D$6:D$50, 0)) -> TRUE | Q26: =ISNUMBER(MATCH($M26, E$6:E$50, 0)) -> FALSE | R26: =ISNUMBER(MATCH($M26, F$6:F$50, 0)) -> FALSE | S26: =ISNUMBER(MATCH($M26, G$6:G$50, 0)) -> TRUE | T26: =ISNUMBER(MATCH($M26, H$6:H$50, 0)) -> TRUE | U26: =ISNUMBER(MATCH($M26, I$6:I$50, 0)) -> FALSE | V26: =ISNUMBER(MATCH($M26, J$6:J$50, 0)) -> TRUE
A27: expiries | J27: 20261130 | L27: 20261130 | M27: 20270617 | N27: =ISNUMBER(MATCH($M27, B$6:B$50, 0)) -> FALSE | O27: =ISNUMBER(MATCH($M27, C$6:C$50, 0)) -> FALSE | P27: =ISNUMBER(MATCH($M27, D$6:D$50, 0)) -> FALSE | Q27: =ISNUMBER(MATCH($M27, E$6:E$50, 0)) -> FALSE | R27: =ISNUMBER(MATCH($M27, F$6:F$50, 0)) -> FALSE | S27: =ISNUMBER(MATCH($M27, G$6:G$50, 0)) -> FALSE | T27: =ISNUMBER(MATCH($M27, H$6:H$50, 0)) -> FALSE | U27: =ISNUMBER(MATCH($M27, I$6:I$50, 0)) -> FALSE | V27: =ISNUMBER(MATCH($M27, J$6:J$50, 0)) -> TRUE
A28: expiries | J28: 20270115 | L28: 20270617 | M28: 20271217 | N28: =ISNUMBER(MATCH($M28, B$6:B$50, 0)) -> FALSE | O28: =ISNUMBER(MATCH($M28, C$6:C$50, 0)) -> FALSE | P28: =ISNUMBER(MATCH($M28, D$6:D$50, 0)) -> FALSE | Q28: =ISNUMBER(MATCH($M28, E$6:E$50, 0)) -> FALSE | R28: =ISNUMBER(MATCH($M28, F$6:F$50, 0)) -> FALSE | S28: =ISNUMBER(MATCH($M28, G$6:G$50, 0)) -> FALSE | T28: =ISNUMBER(MATCH($M28, H$6:H$50, 0)) -> FALSE | U28: =ISNUMBER(MATCH($M28, I$6:I$50, 0)) -> FALSE | V28: =ISNUMBER(MATCH($M28, J$6:J$50, 0)) -> TRUE
... A31: expiries | J31: 20280121 | L31: 20281215 | M31: 20281215 | N31: =ISNUMBER(MATCH($M31, B$6:B$50, 0)) -> FALSE | O31: =ISNUMBER(MATCH($M31, C$6:C$50, 0)) -> FALSE | P31: =ISNUMBER(MATCH($M31, D$6:D$50, 0)) -> FALSE | Q31: =ISNUMBER(MATCH($M31, E$6:E$50, 0)) -> FALSE | R31: =ISNUMBER(MATCH($M31, F$6:F$50, 0)) -> FALSE | S31: =ISNUMBER(MATCH($M31, G$6:G$50, 0)) -> FALSE | T31: =ISNUMBER(MATCH($M31, H$6:H$50, 0)) -> FALSE | U31: =ISNUMBER(MATCH($M31, I$6:I$50, 0)) -> FALSE | V31: =ISNUMBER(MATCH($M31, J$6:J$50, 0)) -> TRUE
A32: expiries | J32: 20280616
A33: expiries | J33: 20281215
A34: expiries

Sheet ARKB Options
A1: 46098.676
A2: underlying_symbol | B2: underlying_conId | C2: option_conId | D2: expiry | E2: strike | F2: right | G2: exchange | H2: multiplier | I2: currency | J2: tradingClass
A3: ARKB | B3: 677037663 | C3: 852717360 | D3: 20260320 | E3: 11 | F3: C | G3: SMART | H3: 100 | I3: USD | J3: ARKB
A4: ARKB | B4: 677037663 | C4: 852717842 | D4: 20260320 | E4: 11 | F4: P | G4: SMART | H4: 100 | I4: USD | J4: ARKB
A5: ARKB | B5: 677037663 | C5: 852717428 | D5: 20260320 | E5: 12 | F5: C | G5: SMART | H5: 100 | I5: USD | J5: ARKB
A6: ARKB | B6: 677037663 | C6: 852717896 | D6: 20260320 | E6: 12 | F6: P | G6: SMART | H6: 100 | I6: USD | J6: ARKB
A7: ARKB | B7: 677037663 | C7: 852717484 | D7: 20260320 | E7: 13 | F7: C | G7: SMART | H7: 100 | I7: USD | J7: ARKB
A8: ARKB | B8: 677037663 | C8: 852717956 | D8: 20260320 | E8: 13 | F8: P | G8: SMART | H8: 100 | I8: USD | J8: ARKB
A9: ARKB | B9: 677037663 | C9: 852717531 | D9: 20260320 | E9: 14 | F9: C | G9: SMART | H9: 100 | I9: USD | J9: ARKB
A10: ARKB | B10: 677037663 | C10: 852718013 | D10: 20260320 | E10: 14 | F10: P | G10: SMART | H10: 100 | I10: USD | J10: ARKB
A11: ARKB | B11: 677037663 | C11: 852717581 | D11: 20260320 | E11: 15 | F11: C | G11: SMART | H11: 100 | I11: USD | J11: ARKB
A12: ARKB | B12: 677037663 | C12: 852718073 | D12: 20260320 | E12: 15 | F12: P | G12: SMART | H12: 100 | I12: USD | J12: ARKB
A13: ARKB | B13: 677037663 | C13: 852717635 | D13: 20260320 | E13: 16 | F13: C | G13: SMART | H13: 100 | I13: USD | J13: ARKB
A14: ARKB | B14: 677037663 | C14: 852718131 | D14: 20260320 | E14: 16 | F14: P | G14: SMART | H14: 100 | I14: USD | J14: ARKB
... A432: ARKB | B432: 677037663 | C432: 820943010 | D432: 20280121 | E432: 60 | F432: P | G432: SMART | H432: 100 | I432: USD | J432: ARKB

Sheet BITB Options
A1: 46098.676
A2: underlying_symbol | B2: underlying_conId | C2: option_conId | D2: expiry | E2: strike | F2: right | G2: exchange | H2: multiplier | I2: currency | J2: tradingClass
A3: BITB | B3: 677037658 | C3: 832189703 | D3: 20260320 | E3: 25 | F3: C | G3: SMART | H3: 100 | I3: USD | J3: BITB
A4: BITB | B4: 677037658 | C4: 832189772 | D4: 20260320 | E4: 25 | F4: P | G4: SMART | H4: 100 | I4: USD | J4: BITB
A5: BITB | B5: 677037658 | C5: 858564143 | D5: 20260320 | E5: 26 | F5: C | G5: SMART | H5: 100 | I5: USD | J5: BITB
A6: BITB | B6: 677037658 | C6: 858564860 | D6: 20260320 | E6: 26 | F6: P | G6: SMART | H6: 100 | I6: USD | J6: BITB
A7: BITB | B7: 677037658 | C7: 858564234 | D7: 20260320 | E7: 27 | F7: C | G7: SMART | H7: 100 | I7: USD | J7: BITB
A8: BITB | B8: 677037658 | C8: 858564923 | D8: 20260320 | E8: 27 | F8: P | G8: SMART | H8: 100 | I8: USD | J8: BITB
A9: BITB | B9: 677037658 | C9: 858564299 | D9: 20260320 | E9: 28 | F9: C | G9: SMART | H9: 100 | I9: USD | J9: BITB
A10: BITB | B10: 677037658 | C10: 858564974 | D10: 20260320 | E10: 28 | F10: P | G10: SMART | H10: 100 | I10: USD | J10: BITB
A11: BITB | B11: 677037658 | C11: 858564364 | D11: 20260320 | E11: 29 | F11: C | G11: SMART | H11: 100 | I11: USD | J11: BITB
A12: BITB | B12: 677037658 | C12: 858565032 | D12: 20260320 | E12: 29 | F12: P | G12: SMART | H12: 100 | I12: USD | J12: BITB
A13: BITB | B13: 677037658 | C13: 825153194 | D13: 20260320 | E13: 30 | F13: C | G13: SMART | H13: 100 | I13: USD | J13: BITB
A14: BITB | B14: 677037658 | C14: 825153284 | D14: 20260320 | E14: 30 | F14: P | G14: SMART | H14: 100 | I14: USD | J14: BITB
... A410: BITB | B410: 677037658 | C410: 820958820 | D410: 20270115 | E410: 100 | F410: P | G410: SMART | H410: 100 | I410: USD | J410: BITB

Sheet BTC Options
A1: 46098.677
A2: underlying_symbol | B2: underlying_conId | C2: option_conId | D2: expiry | E2: strike | F2: right | G2: exchange | H2: multiplier | I2: currency | J2: tradingClass
A3: BTC | B3: 741192224 | C3: 852717324 | D3: 20260320 | E3: 15 | F3: C | G3: SMART | H3: 100 | I3: USD | J3: BTC
A4: BTC | B4: 741192224 | C4: 852718061 | D4: 20260320 | E4: 15 | F4: P | G4: SMART | H4: 100 | I4: USD | J4: BTC
A5: BTC | B5: 741192224 | C5: 852717378 | D5: 20260320 | E5: 16 | F5: C | G5: SMART | H5: 100 | I5: USD | J5: BTC
A6: BTC | B6: 741192224 | C6: 852718119 | D6: 20260320 | E6: 16 | F6: P | G6: SMART | H6: 100 | I6: USD | J6: BTC
A7: BTC | B7: 741192224 | C7: 852717425 | D7: 20260320 | E7: 17 | F7: C | G7: SMART | H7: 100 | I7: USD | J7: BTC
A8: BTC | B8: 741192224 | C8: 852718170 | D8: 20260320 | E8: 17 | F8: P | G8: SMART | H8: 100 | I8: USD | J8: BTC
A9: BTC | B9: 741192224 | C9: 852717481 | D9: 20260320 | E9: 18 | F9: C | G9: SMART | H9: 100 | I9: USD | J9: BTC
A10: BTC | B10: 741192224 | C10: 852718233 | D10: 20260320 | E10: 18 | F10: P | G10: SMART | H10: 100 | I10: USD | J10: BTC
A11: BTC | B11: 741192224 | C11: 852717538 | D11: 20260320 | E11: 19 | F11: C | G11: SMART | H11: 100 | I11: USD | J11: BTC
A12: BTC | B12: 741192224 | C12: 852718296 | D12: 20260320 | E12: 19 | F12: P | G12: SMART | H12: 100 | I12: USD | J12: BTC
A13: BTC | B13: 741192224 | C13: 833667666 | D13: 20260320 | E13: 20 | F13: C | G13: SMART | H13: 100 | I13: USD | J13: BTC
A14: BTC | B14: 741192224 | C14: 833667790 | D14: 20260320 | E14: 20 | F14: P | G14: SMART | H14: 100 | I14: USD | J14: BTC
... A582: BTC | B582: 741192224 | C582: 820952360 | D582: 20280121 | E582: 80 | F582: P | G582: SMART | H582: 100 | I582: USD | J582: BTC

Sheet BTCW Options
A1: 46098.677
A2: underlying_symbol | B2: underlying_conId | C2: option_conId | D2: expiry | E2: strike | F2: right | G2: exchange | H2: multiplier | I2: currency | J2: tradingClass
A3: BTCW | B3: 676783288 | C3: 851611252 | D3: 20260320 | E3: 45 | F3: C | G3: SMART | H3: 100 | I3: USD | J3: BTCW
A4: BTCW | B4: 676783288 | C4: 851611285 | D4: 20260320 | E4: 45 | F4: P | G4: SMART | H4: 100 | I4: USD | J4: BTCW
A5: BTCW | B5: 676783288 | C5: 832195806 | D5: 20260320 | E5: 50 | F5: C | G5: SMART | H5: 100 | I5: USD | J5: BTCW
A6: BTCW | B6: 676783288 | C6: 832196214 | D6: 20260320 | E6: 50 | F6: P | G6: SMART | H6: 100 | I6: USD | J6: BTCW
A7: BTCW | B7: 676783288 | C7: 832195821 | D7: 20260320 | E7: 55 | F7: C | G7: SMART | H7: 100 | I7: USD | J7: BTCW
A8: BTCW | B8: 676783288 | C8: 832196236 | D8: 20260320 | E8: 55 | F8: P | G8: SMART | H8: 100 | I8: USD | J8: BTCW
A9: BTCW | B9: 676783288 | C9: 832195848 | D9: 20260320 | E9: 60 | F9: C | G9: SMART | H9: 100 | I9: USD | J9: BTCW
A10: BTCW | B10: 676783288 | C10: 832196270 | D10: 20260320 | E10: 60 | F10: P | G10: SMART | H10: 100 | I10: USD | J10: BTCW
A11: BTCW | B11: 676783288 | C11: 832195868 | D11: 20260320 | E11: 65 | F11: C | G11: SMART | H11: 100 | I11: USD | J11: BTCW
A12: BTCW | B12: 676783288 | C12: 832196307 | D12: 20260320 | E12: 65 | F12: P | G12: SMART | H12: 100 | I12: USD | J12: BTCW
A13: BTCW | B13: 676783288 | C13: 832195889 | D13: 20260320 | E13: 70 | F13: C | G13: SMART | H13: 100 | I13: USD | J13: BTCW
A14: BTCW | B14: 676783288 | C14: 832196320 | D14: 20260320 | E14: 70 | F14: P | G14: SMART | H14: 100 | I14: USD | J14: BTCW
... A304: BTCW | B304: 676783288 | C304: 846846977 | D304: 20260918 | E304: 150 | F304: P | G304: SMART | H304: 100 | I304: USD | J304: BTCW

Sheet EZBC Options
A1: 46098.676
A2: underlying_symbol | B2: underlying_conId | C2: option_conId | D2: expiry | E2: strike | F2: right | G2: exchange | H2: multiplier | I2: currency | J2: tradingClass
A3: EZBC | B3: 676783282 | C3: 852806218 | D3: 20260320 | E3: 20 | F3: C | G3: SMART | H3: 100 | I3: USD | J3: EZBC
A4: EZBC | B4: 676783282 | C4: 852806658 | D4: 20260320 | E4: 20 | F4: P | G4: SMART | H4: 100 | I4: USD | J4: EZBC
A5: EZBC | B5: 676783282 | C5: 852806253 | D5: 20260320 | E5: 21 | F5: C | G5: SMART | H5: 100 | I5: USD | J5: EZBC
A6: EZBC | B6: 676783282 | C6: 852806678 | D6: 20260320 | E6: 21 | F6: P | G6: SMART | H6: 100 | I6: USD | J6: EZBC
A7: EZBC | B7: 676783282 | C7: 852806284 | D7: 20260320 | E7: 22 | F7: C | G7: SMART | H7: 100 | I7: USD | J7: EZBC
A8: EZBC | B8: 676783282 | C8: 852806715 | D8: 20260320 | E8: 22 | F8: P | G8: SMART | H8: 100 | I8: USD | J8: EZBC
A9: EZBC | B9: 676783282 | C9: 852806305 | D9: 20260320 | E9: 23 | F9: C | G9: SMART | H9: 100 | I9: USD | J9: EZBC
A10: EZBC | B10: 676783282 | C10: 852806732 | D10: 20260320 | E10: 23 | F10: P | G10: SMART | H10: 100 | I10: USD | J10: EZBC
A11: EZBC | B11: 676783282 | C11: 852806338 | D11: 20260320 | E11: 24 | F11: C | G11: SMART | H11: 100 | I11: USD | J11: EZBC
A12: EZBC | B12: 676783282 | C12: 852806778 | D12: 20260320 | E12: 24 | F12: P | G12: SMART | H12: 100 | I12: USD | J12: EZBC
A13: EZBC | B13: 676783282 | C13: 852806355 | D13: 20260320 | E13: 25 | F13: C | G13: SMART | H13: 100 | I13: USD | J13: EZBC
A14: EZBC | B14: 676783282 | C14: 852806799 | D14: 20260320 | E14: 25 | F14: P | G14: SMART | H14: 100 | I14: USD | J14: EZBC
... A312: EZBC | B312: 676783282 | C312: 846879401 | D312: 20260918 | E312: 59 | F312: P | G312: SMART | H312: 100 | I312: USD | J312: EZBC

Sheet FBTC Options
A1: 46098.68
A2: underlying_symbol | B2: underlying_conId | C2: option_conId | D2: expiry | E2: strike | F2: right | G2: exchange | H2: multiplier | I2: currency | J2: tradingClass
A3: FBTC | B3: 676783301 | C3: 852746177 | D3: 20260320 | E3: 30 | F3: C | G3: SMART | H3: 100 | I3: USD | J3: FBTC
A4: FBTC | B4: 676783301 | C4: 852746676 | D4: 20260320 | E4: 30 | F4: P | G4: SMART | H4: 100 | I4: USD | J4: FBTC
A5: FBTC | B5: 676783301 | C5: 852746231 | D5: 20260320 | E5: 35 | F5: C | G5: SMART | H5: 100 | I5: USD | J5: FBTC
A6: FBTC | B6: 676783301 | C6: 852746721 | D6: 20260320 | E6: 35 | F6: P | G6: SMART | H6: 100 | I6: USD | J6: FBTC
A7: FBTC | B7: 676783301 | C7: 833717141 | D7: 20260320 | E7: 40 | F7: C | G7: SMART | H7: 100 | I7: USD | J7: FBTC
A8: FBTC | B8: 676783301 | C8: 833717214 | D8: 20260320 | E8: 40 | F8: P | G8: SMART | H8: 100 | I8: USD | J8: FBTC
A9: FBTC | B9: 676783301 | C9: 829446872 | D9: 20260320 | E9: 45 | F9: C | G9: SMART | H9: 100 | I9: USD | J9: FBTC
A10: FBTC | B10: 676783301 | C10: 829446923 | D10: 20260320 | E10: 45 | F10: P | G10: SMART | H10: 100 | I10: USD | J10: FBTC
A11: FBTC | B11: 676783301 | C11: 857327984 | D11: 20260320 | E11: 47 | F11: C | G11: SMART | H11: 100 | I11: USD | J11: FBTC
A12: FBTC | B12: 676783301 | C12: 857328882 | D12: 20260320 | E12: 47 | F12: P | G12: SMART | H12: 100 | I12: USD | J12: FBTC
A13: FBTC | B13: 676783301 | C13: 857328054 | D13: 20260320 | E13: 48 | F13: C | G13: SMART | H13: 100 | I13: USD | J13: FBTC
A14: FBTC | B14: 676783301 | C14: 857328954 | D14: 20260320 | E14: 48 | F14: P | G14: SMART | H14: 100 | I14: USD | J14: FBTC
... A1062: FBTC | B1062: 676783301 | C1062: 820961870 | D1062: 20280121 | E1062: 160 | F1062: P | G1062: SMART | H1062: 100 | I1062: USD | J1062: FBTC

Sheet GBTC Options
A1: 46098.679
A2: underlying_symbol | B2: underlying_conId | C2: option_conId | D2: expiry | E2: strike | F2: right | G2: exchange | H2: multiplier | I2: currency | J2: tradingClass
A3: GBTC | B3: 349966059 | C3: 852767982 | D3: 20260320 | E3: 30 | F3: C | G3: SMART | H3: 100 | I3: USD | J3: GBTC
A4: GBTC | B4: 349966059 | C4: 852768038 | D4: 20260320 | E4: 30 | F4: P | G4: SMART | H4: 100 | I4: USD | J4: GBTC
A5: GBTC | B5: 349966059 | C5: 833730777 | D5: 20260320 | E5: 35 | F5: C | G5: SMART | H5: 100 | I5: USD | J5: GBTC
A6: GBTC | B6: 349966059 | C6: 833730855 | D6: 20260320 | E6: 35 | F6: P | G6: SMART | H6: 100 | I6: USD | J6: GBTC
A7: GBTC | B7: 349966059 | C7: 829845469 | D7: 20260320 | E7: 40 | F7: C | G7: SMART | H7: 100 | I7: USD | J7: GBTC
A8: GBTC | B8: 349966059 | C8: 829845539 | D8: 20260320 | E8: 40 | F8: P | G8: SMART | H8: 100 | I8: USD | J8: GBTC
A9: GBTC | B9: 349966059 | C9: 857333705 | D9: 20260320 | E9: 41 | F9: C | G9: SMART | H9: 100 | I9: USD | J9: GBTC
A10: GBTC | B10: 349966059 | C10: 857335356 | D10: 20260320 | E10: 41 | F10: P | G10: SMART | H10: 100 | I10: USD | J10: GBTC
A11: GBTC | B11: 349966059 | C11: 857333778 | D11: 20260320 | E11: 42 | F11: C | G11: SMART | H11: 100 | I11: USD | J11: GBTC
A12: GBTC | B12: 349966059 | C12: 857335426 | D12: 20260320 | E12: 42 | F12: P | G12: SMART | H12: 100 | I12: USD | J12: GBTC
A13: GBTC | B13: 349966059 | C13: 857333852 | D13: 20260320 | E13: 43 | F13: C | G13: SMART | H13: 100 | I13: USD | J13: GBTC
A14: GBTC | B14: 349966059 | C14: 857335476 | D14: 20260320 | E14: 43 | F14: P | G14: SMART | H14: 100 | I14: USD | J14: GBTC
... A904: GBTC | B904: 349966059 | C904: 820960160 | D904: 20280121 | E904: 140 | F904: P | G904: SMART | H904: 100 | I904: USD | J904: GBTC

Sheet HODL Options
A1: 46098.677
A2: underlying_symbol | B2: underlying_conId | C2: option_conId | D2: expiry | E2: strike | F2: right | G2: exchange | H2: multiplier | I2: currency | J2: tradingClass
A3: HODL | B3: 677037670 | C3: 852765490 | D3: 20260320 | E3: 15 | F3: C | G3: SMART | H3: 100 | I3: USD | J3: HODL
A4: HODL | B4: 677037670 | C4: 852765543 | D4: 20260320 | E4: 15 | F4: P | G4: SMART | H4: 100 | I4: USD | J4: HODL
A5: HODL | B5: 677037670 | C5: 846326707 | D5: 20260320 | E5: 16 | F5: C | G5: SMART | H5: 100 | I5: USD | J5: HODL
A6: HODL | B6: 677037670 | C6: 846328127 | D6: 20260320 | E6: 16 | F6: P | G6: SMART | H6: 100 | I6: USD | J6: HODL
A7: HODL | B7: 677037670 | C7: 846326804 | D7: 20260320 | E7: 17 | F7: C | G7: SMART | H7: 100 | I7: USD | J7: HODL
A8: HODL | B8: 677037670 | C8: 846328203 | D8: 20260320 | E8: 17 | F8: P | G8: SMART | H8: 100 | I8: USD | J8: HODL
A9: HODL | B9: 677037670 | C9: 846326874 | D9: 20260320 | E9: 18 | F9: C | G9: SMART | H9: 100 | I9: USD | J9: HODL
A10: HODL | B10: 677037670 | C10: 846328290 | D10: 20260320 | E10: 18 | F10: P | G10: SMART | H10: 100 | I10: USD | J10: HODL
A11: HODL | B11: 677037670 | C11: 846326940 | D11: 20260320 | E11: 19 | F11: C | G11: SMART | H11: 100 | I11: USD | J11: HODL
A12: HODL | B12: 677037670 | C12: 846328371 | D12: 20260320 | E12: 19 | F12: P | G12: SMART | H12: 100 | I12: USD | J12: HODL
A13: HODL | B13: 677037670 | C13: 846326994 | D13: 20260320 | E13: 20 | F13: C | G13: SMART | H13: 100 | I13: USD | J13: HODL
A14: HODL | B14: 677037670 | C14: 846328445 | D14: 20260320 | E14: 20 | F14: P | G14: SMART | H14: 100 | I14: USD | J14: HODL
... A196: HODL | B196: 677037670 | C196: 839773455 | D196: 20260821 | E196: 35 | F196: P | G196: SMART | H196: 100 | I196: USD | J196: HODL

Sheet IBIT Options
A1: 46098.683
A2: underlying_symbol | B2: underlying_conId | C2: option_conId | D2: expiry | E2: strike | F2: right | G2: exchange | H2: multiplier | I2: currency | J2: tradingClass
A3: IBIT | B3: 677037673 | C3: 860146617 | D3: 20260318 | E3: 25 | F3: C | G3: SMART | H3: 100 | I3: USD | J3: IBIT
A4: IBIT | B4: 677037673 | C4: 860157677 | D4: 20260318 | E4: 25 | F4: P | G4: SMART | H4: 100 | I4: USD | J4: IBIT
A5: IBIT | B5: 677037673 | C5: 860156695 | D5: 20260318 | E5: 26 | F5: C | G5: SMART | H5: 100 | I5: USD | J5: IBIT
A6: IBIT | B6: 677037673 | C6: 860157703 | D6: 20260318 | E6: 26 | F6: P | G6: SMART | H6: 100 | I6: USD | J6: IBIT
A7: IBIT | B7: 677037673 | C7: 860156735 | D7: 20260318 | E7: 27 | F7: C | G7: SMART | H7: 100 | I7: USD | J7: IBIT
A8: IBIT | B8: 677037673 | C8: 860157724 | D8: 20260318 | E8: 27 | F8: P | G8: SMART | H8: 100 | I8: USD | J8: IBIT
A9: IBIT | B9: 677037673 | C9: 860156783 | D9: 20260318 | E9: 28 | F9: C | G9: SMART | H9: 100 | I9: USD | J9: IBIT
A10: IBIT | B10: 677037673 | C10: 860157769 | D10: 20260318 | E10: 28 | F10: P | G10: SMART | H10: 100 | I10: USD | J10: IBIT
A11: IBIT | B11: 677037673 | C11: 860554511 | D11: 20260318 | E11: 28.5 | F11: C | G11: SMART | H11: 100 | I11: USD | J11: IBIT
A12: IBIT | B12: 677037673 | C12: 860555226 | D12: 20260318 | E12: 28.5 | F12: P | G12: SMART | H12: 100 | I12: USD | J12: IBIT
A13: IBIT | B13: 677037673 | C13: 860156826 | D13: 20260318 | E13: 29 | F13: C | G13: SMART | H13: 100 | I13: USD | J13: IBIT
A14: IBIT | B14: 677037673 | C14: 860157803 | D14: 20260318 | E14: 29 | F14: P | G14: SMART | H14: 100 | I14: USD | J14: IBIT
... A3022: IBIT | B3022: 677037673 | C3022: 860161491 | D3022: 20281215 | E3022: 75 | F3022: P | G3022: SMART | H3022: 100 | I3022: USD | J3022: IBIT
