Workbook

Sheet ALL
A1: my_fi_name | B1: price_mkt_bid | C1: price_mkt_ask | D1: time | E1: scalar | F1: adj | G1: adj scalar | H1: unit bid | I1: unit ask
A2: ARKB | B2: 20.73 | C2: 20.74 | D2: 2026-06-10_11-53-43 | E2: 3014.7412 | F2: =Sheet1!L3 -> 0 | G2: =E2+F2 -> 3014.7412 | H2: =B2*G2 -> 62495.585 | I2: =C2*G2 -> 62525.732
A3: BITB | B3: 33.93 | C3: 33.94 | D3: 2026-06-10_11-53-43 | E3: 1841.9993 | F3: =Sheet1!L4 -> -0.1 | G3: =E3+F3 -> 1841.8993 | H3: =B3*G3 -> 62495.643 | I3: =C3*G3 -> 62514.062
A4: BRRR | B4: 17.62 | C4: 17.63 | D4: 2026-06-10_11-53-43 | E4: 3546.2949 | F4: =Sheet1!L5 -> 0 | G4: =E4+F4 -> 3546.2949 | H4: =B4*G4 -> 62485.716 | I4: =C4*G4 -> 62521.179
A5: BTC | B5: 27.64 | C5: 27.65 | D5: 2026-06-10_11-53-43 | E5: 2261.23 | F5: =Sheet1!L6 -> -0.2 | G5: =E5+F5 -> 2261.03 | H5: =B5*G5 -> 62494.869 | I5: =C5*G5 -> 62517.48
A6: BTCW | B6: 66.06 | C6: 66.17 | D6: 2026-06-10_11-53-43 | E6: 946.0584 | F6: =Sheet1!L7 -> 0 | G6: =E6+F6 -> 946.0584 | H6: =B6*G6 -> 62496.618 | I6: =C6*G6 -> 62600.684
A7: EZBC | B7: 36.12 | C7: 36.14 | D7: 2026-06-10_11-53-43 | E7: 1730.0098 | F7: =Sheet1!L8 -> 0.2 | G7: =E7+F7 -> 1730.2098 | H7: =B7*G7 -> 62495.178 | I7: =C7*G7 -> 62529.782
A8: FBTC | B8: 54.41 | C8: 54.42 | D8: 2026-06-10_11-53-43 | E8: 1148.7584 | F8: =Sheet1!L9 -> 0.05 | G8: =E8+F8 -> 1148.8084 | H8: =B8*G8 -> 62506.665 | I8: =C8*G8 -> 62518.153
A9: GBTC | B9: 48.51 | C9: 48.52 | D9: 2026-06-10_11-53-43 | E9: 1288.3256 | F9: =Sheet1!L10 -> 0 | G9: =E9+F9 -> 1288.3256 | H9: =B9*G9 -> 62496.675 | I9: =C9*G9 -> 62509.558
A10: HODL | B10: 17.67 | C10: 17.68 | D10: 2026-06-10_11-53-43 | E10: 3535.8029 | F10: =Sheet1!L11 -> 0 | G10: =E10+F10 -> 3535.8029 | H10: =B10*G10 -> 62477.637 | I10: =C10*G10 -> 62512.995
A11: IBIT | B11: 35.41 | C11: 35.42 | D11: 2026-06-10_11-53-43 | E11: 1764.9141 | F11: =Sheet1!L12 -> 0.2 | G11: =E11+F11 -> 1765.1141 | H11: =B11*G11 -> 62502.69 | I11: =C11*G11 -> 62520.341
A12: ARKB | B12: 20.68 | C12: 20.69 | D12: 2026-06-10_12-08-43 | E12: 3014.7412 | F12: =F2 -> 0 | G12: =E12+F12 -> 3014.7412 | H12: =B12*G12 -> 62344.848 | I12: =C12*G12 -> 62374.995
A13: BITB | B13: 33.86 | C13: 33.87 | D13: 2026-06-10_12-08-43 | E13: 1841.9993 | F13: =F3 -> -0.1 | G13: =E13+F13 -> 1841.8993 | H13: =B13*G13 -> 62366.71 | I13: =C13*G13 -> 62385.129
A14: BRRR | B14: 17.58 | C14: 17.59 | D14: 2026-06-10_12-08-43 | E14: 3546.2949 | F14: =F4 -> 0 | G14: =E14+F14 -> 3546.2949 | H14: =B14*G14 -> 62343.864 | I14: =C14*G14 -> 62379.327
A15: BTC | B15: 27.58 | C15: 27.59 | D15: 2026-06-10_12-08-43 | E15: 2261.23 | F15: =F5 -> -0.2 | G15: =E15+F15 -> 2261.03 | H15: =B15*G15 -> 62359.207 | I15: =C15*G15 -> 62381.818
A16: BTCW | B16: 65.92 | C16: 66.03 | D16: 2026-06-10_12-08-43 | E16: 946.0584 | F16: =F6 -> 0 | G16: =E16+F16 -> 946.0584 | H16: =B16*G16 -> 62364.17 | I16: =C16*G16 -> 62468.236
A17: EZBC | B17: 36.03 | C17: 36.05 | D17: 2026-06-10_12-08-43 | E17: 1730.0098 | F17: =F7 -> 0.2 | G17: =E17+F17 -> 1730.2098 | H17: =B17*G17 -> 62339.459 | I17: =C17*G17 -> 62374.063
A18: FBTC | B18: 54.29 | C18: 54.3 | D18: 2026-06-10_12-08-43 | E18: 1148.7584 | F18: =F8 -> 0.05 | G18: =E18+F18 -> 1148.8084 | H18: =B18*G18 -> 62368.808 | I18: =C18*G18 -> 62380.296
A19: GBTC | B19: 48.4 | C19: 48.41 | D19: 2026-06-10_12-08-43 | E19: 1288.3256 | F19: =F9 -> 0 | G19: =E19+F19 -> 1288.3256 | H19: =B19*G19 -> 62354.959 | I19: =C19*G19 -> 62367.842
A20: HODL | B20: 17.63 | C20: 17.64 | D20: 2026-06-10_12-08-43 | E20: 3535.8029 | F20: =F10 -> 0 | G20: =E20+F20 -> 3535.8029 | H20: =B20*G20 -> 62336.205 | I20: =C20*G20 -> 62371.563
A21: IBIT | B21: 35.33 | C21: 35.34 | D21: 2026-06-10_12-08-43 | E21: 1764.9141 | F21: =F11 -> 0.2 | G21: =E21+F21 -> 1765.1141 | H21: =B21*G21 -> 62361.481 | I21: =C21*G21 -> 62379.132
A22: ARKB | B22: 20.64 | C22: 20.65 | D22: 2026-06-10_12-23-43 | E22: 3014.7412 | F22: =F12 -> 0 | G22: =E22+F22 -> 3014.7412 | H22: =B22*G22 -> 62224.258 | I22: =C22*G22 -> 62254.406
A23: BITB | B23: 33.79 | C23: 33.8 | D23: 2026-06-10_12-23-43 | E23: 1841.9993 | F23: =F13 -> -0.1 | G23: =E23+F23 -> 1841.8993 | H23: =B23*G23 -> 62237.777 | I23: =C23*G23 -> 62256.196
... A3341: IBIT | B3341: 34.87 | C3341: 34.88 | D3341: 2026-07-02_15-57-59 | E3341: 1765.2166 | F3341: =F3331 -> 0.2 | G3341: =E3341+F3341 -> 1765.4166 | H3341: =B3341*G3341 -> 61560.077 | I3341: =C3341*G3341 -> 61577.731

Sheet Sheet1
A1: Row Labels | B1: Max of unit bid | C1: Min of unit ask | D1: net | E1: bid name | F1: ask name
A2: 2026-06-10_11-53-43 | B2: 62506.665 | C2: 62509.558 | D2: =B2-C2 -> -2.893068 | E2: {=_xlfn.XLOOKUP(1,(Table1[time]=A2)*(Table1[unit bid]=B2),Table1[my_fi_name],"Not found")} -> FBTC | F2: {=_xlfn.XLOOKUP(1,(Table1[time]=A2)*(Table1[unit ask]=C2),Table1[my_fi_name],"Not found")} -> GBTC | I2: hit bid | J2: lift ask | K2: net | L2: diff | M2: price | N2: $ diff | O2: % diff | P2: chg in net | R2: hit bid | S2: lift ask | T2: net | U2: diff | V2: price | W2: $ diff | X2: % diff
A3: 2026-06-10_12-08-43 | B3: 62368.808 | C3: 62367.842 | D3: =B3-C3 -> 0.96574 | E3: {=_xlfn.XLOOKUP(1,(Table1[time]=A3)*(Table1[unit bid]=B3),Table1[my_fi_name],"Not found")} -> FBTC | F3: {=_xlfn.XLOOKUP(1,(Table1[time]=A3)*(Table1[unit ask]=C3),Table1[my_fi_name],"Not found")} -> GBTC | H3: ARKB | I3: =-COUNTIF(E:E,H3) -> -32 | J3: =COUNTIF(F:F,H3) -> 20 | K3: =I3+J3 -> -12 | M3: =ALL!C2 -> 20.74 | N3: =L3*M3 -> 0 | O3: =N3/C3 -> 0 | P3: =+K3-T3 -> -21 | Q3: ARKB | R3: -20 | S3: 29 | T3: 9 | V3: 20.74 | W3: 0 | X3: 0
A4: 2026-06-10_12-23-43 | B4: 62242.439 | C4: 62237.475 | D4: =B4-C4 -> 4.963617 | E4: {=_xlfn.XLOOKUP(1,(Table1[time]=A4)*(Table1[unit bid]=B4),Table1[my_fi_name],"Not found")} -> FBTC | F4: {=_xlfn.XLOOKUP(1,(Table1[time]=A4)*(Table1[unit ask]=C4),Table1[my_fi_name],"Not found")} -> BRRR | H4: BITB | I4: =-COUNTIF(E:E,H4) -> -33 | J4: =COUNTIF(F:F,H4) -> 18 | K4: =I4+J4 -> -15 | L4: -0.1 | M4: =ALL!C3 -> 33.94 | N4: =L4*M4 -> -3.394 | O4: =N4/C4 -> -5.453306e-05 | P4: =+K4-T4 -> 41 | Q4: BITB | R4: -58 | S4: 2 | T4: -56 | V4: 33.94 | W4: 0 | X4: 0
A5: 2026-06-10_12-38-43 | B5: 62288.391 | C5: 62277.66 | D5: =B5-C5 -> 10.731944 | E5: {=_xlfn.XLOOKUP(1,(Table1[time]=A5)*(Table1[unit bid]=B5),Table1[my_fi_name],"Not found")} -> FBTC | F5: {=_xlfn.XLOOKUP(1,(Table1[time]=A5)*(Table1[unit ask]=C5),Table1[my_fi_name],"Not found")} -> GBTC | H5: BRRR | I5: =-COUNTIF(E:E,H5) -> -32 | J5: =COUNTIF(F:F,H5) -> 15 | K5: =I5+J5 -> -17 | M5: =ALL!C4 -> 17.63 | N5: =L5*M5 -> 0 | O5: =N5/C5 -> 0 | P5: =+K5-T5 -> -1 | Q5: BRRR | R5: -26 | S5: 10 | T5: -16 | V5: 17.63 | W5: 0 | X5: 0
A6: 2026-06-10_12-53-43 | B6: 62081.606 | C6: 62071.527 | D6: =B6-C6 -> 10.078528 | E6: {=_xlfn.XLOOKUP(1,(Table1[time]=A6)*(Table1[unit bid]=B6),Table1[my_fi_name],"Not found")} -> FBTC | F6: {=_xlfn.XLOOKUP(1,(Table1[time]=A6)*(Table1[unit ask]=C6),Table1[my_fi_name],"Not found")} -> GBTC | H6: BTC | I6: =-COUNTIF(E:E,H6) -> -36 | J6: =COUNTIF(F:F,H6) -> 12 | K6: =I6+J6 -> -24 | L6: -0.2 | M6: =ALL!C5 -> 27.65 | N6: =L6*M6 -> -5.53 | O6: =N6/C6 -> -8.9090767e-05 | P6: =+K6-T6 -> 52 | Q6: BTC | R6: -76 | S6: 0 | T6: -76 | V6: 27.65 | W6: 0 | X6: 0
A7: 2026-06-10_13-08-43 | B7: 62116.07 | C7: 62103.669 | D7: =B7-C7 -> 12.401468 | E7: {=_xlfn.XLOOKUP(1,(Table1[time]=A7)*(Table1[unit bid]=B7),Table1[my_fi_name],"Not found")} -> FBTC | F7: {=_xlfn.XLOOKUP(1,(Table1[time]=A7)*(Table1[unit ask]=C7),Table1[my_fi_name],"Not found")} -> ARKB | H7: BTCW | I7: =-COUNTIF(E:E,H7) -> -6 | J7: =COUNTIF(F:F,H7) -> 0 | K7: =I7+J7 -> -6 | M7: =ALL!C6 -> 66.17 | N7: =L7*M7 -> 0 | O7: =N7/C7 -> 0 | P7: =+K7-T7 -> -1 | Q7: BTCW | R7: -5 | S7: 0 | T7: -5 | V7: 66.17 | W7: 0 | X7: 0
A8: 2026-06-10_13-23-43 | B8: 62016.749 | C8: 61994.228 | D8: =B8-C8 -> 22.521559 | E8: {=_xlfn.XLOOKUP(1,(Table1[time]=A8)*(Table1[unit bid]=B8),Table1[my_fi_name],"Not found")} -> BITB | F8: {=_xlfn.XLOOKUP(1,(Table1[time]=A8)*(Table1[unit ask]=C8),Table1[my_fi_name],"Not found")} -> GBTC | H8: EZBC | I8: =-COUNTIF(E:E,H8) -> -4 | J8: =COUNTIF(F:F,H8) -> 11 | K8: =I8+J8 -> 7 | L8: 0.2 | M8: =ALL!C7 -> 36.14 | N8: =L8*M8 -> 7.228 | O8: =N8/C8 -> 0.0001165915 | P8: =+K8-T8 -> -19 | Q8: EZBC | R8: 0 | S8: 26 | T8: 26 | V8: 36.14 | W8: 0 | X8: 0
A9: 2026-06-10_13-38-43 | B9: 61668.035 | C9: 61659.263 | D9: =B9-C9 -> 8.771696 | E9: {=_xlfn.XLOOKUP(1,(Table1[time]=A9)*(Table1[unit bid]=B9),Table1[my_fi_name],"Not found")} -> FBTC | F9: {=_xlfn.XLOOKUP(1,(Table1[time]=A9)*(Table1[unit ask]=C9),Table1[my_fi_name],"Not found")} -> GBTC | H9: FBTC | I9: =-COUNTIF(E:E,H9) -> -60 | J9: =COUNTIF(F:F,H9) -> 61 | K9: =I9+J9 -> 1 | L9: 0.05 | M9: =ALL!C8 -> 54.42 | N9: =L9*M9 -> 2.721 | O9: =N9/C9 -> 4.4129622e-05 | P9: =+K9-T9 -> -46 | Q9: FBTC | R9: -16 | S9: 63 | T9: 47 | V9: 54.42 | W9: 0 | X9: 0
A10: 2026-06-10_13-53-43 | B10: 61782.916 | C10: 61770.477 | D10: =B10-C10 -> 12.439089 | E10: {=_xlfn.XLOOKUP(1,(Table1[time]=A10)*(Table1[unit bid]=B10),Table1[my_fi_name],"Not found")} -> FBTC | F10: {=_xlfn.XLOOKUP(1,(Table1[time]=A10)*(Table1[unit ask]=C10),Table1[my_fi_name],"Not found")} -> HODL | H10: GBTC | I10: =-COUNTIF(E:E,H10) -> -68 | J10: =COUNTIF(F:F,H10) -> 80 | K10: =I10+J10 -> 12 | M10: =ALL!C9 -> 48.52 | N10: =L10*M10 -> 0 | O10: =N10/C10 -> 0 | P10: =+K10-T10 -> 81 | Q10: GBTC | R10: -112 | S10: 43 | T10: -69 | V10: 48.52 | W10: 0 | X10: 0
A11: 2026-06-10_14-08-43 | B11: 61979.911 | C11: 61968.461 | D11: =B11-C11 -> 11.450085 | E11: {=_xlfn.XLOOKUP(1,(Table1[time]=A11)*(Table1[unit bid]=B11),Table1[my_fi_name],"Not found")} -> BITB | F11: {=_xlfn.XLOOKUP(1,(Table1[time]=A11)*(Table1[unit ask]=C11),Table1[my_fi_name],"Not found")} -> GBTC | H11: HODL | I11: =-COUNTIF(E:E,H11) -> -14 | J11: =COUNTIF(F:F,H11) -> 20 | K11: =I11+J11 -> 6 | M11: =ALL!C10 -> 17.68 | N11: =L11*M11 -> 0 | O11: =N11/C11 -> 0 | P11: =+K11-T11 -> 10 | Q11: HODL | R11: -14 | S11: 10 | T11: -4 | V11: 17.68 | W11: 0 | X11: 0
A12: 2026-06-10_14-23-43 | B12: 61874.82 | C12: 61862.489 | D12: =B12-C12 -> 12.331 | E12: {=_xlfn.XLOOKUP(1,(Table1[time]=A12)*(Table1[unit bid]=B12),Table1[my_fi_name],"Not found")} -> FBTC | F12: {=_xlfn.XLOOKUP(1,(Table1[time]=A12)*(Table1[unit ask]=C12),Table1[my_fi_name],"Not found")} -> ARKB | H12: IBIT | I12: =-COUNTIF(E:E,H12) -> -49 | J12: =COUNTIF(F:F,H12) -> 97 | K12: =I12+J12 -> 48 | L12: 0.2 | M12: =ALL!C11 -> 35.42 | N12: =L12*M12 -> 7.084 | O12: =N12/C12 -> 0.00011451204 | P12: =+K12-T12 -> -96 | Q12: IBIT | R12: -7 | S12: 151 | T12: 144 | V12: 35.42 | W12: 0 | X12: 0
A13: 2026-06-10_14-38-43 | B13: 61740.465 | C13: 61723.679 | D13: =B13-C13 -> 16.78504 | E13: {=_xlfn.XLOOKUP(1,(Table1[time]=A13)*(Table1[unit bid]=B13),Table1[my_fi_name],"Not found")} -> BITB | F13: {=_xlfn.XLOOKUP(1,(Table1[time]=A13)*(Table1[unit ask]=C13),Table1[my_fi_name],"Not found")} -> GBTC | I13: =SUM(I3:I12) -> -334 | J13: =SUM(J3:J12) -> 334 | K13: =SUM(K3:K12) -> 0 | R13: -334 | S13: 334 | T13: 0
A14: 2026-06-10_14-53-43 | B14: 61726.04 | C14: 61723.679 | D14: =B14-C14 -> 2.360581 | E14: {=_xlfn.XLOOKUP(1,(Table1[time]=A14)*(Table1[unit bid]=B14),Table1[my_fi_name],"Not found")} -> IBIT | F14: {=_xlfn.XLOOKUP(1,(Table1[time]=A14)*(Table1[unit ask]=C14),Table1[my_fi_name],"Not found")} -> GBTC
A15: 2026-06-10_15-08-43 | B15: 61851.844 | C15: 61841.193 | D15: =B15-C15 -> 10.651535 | E15: {=_xlfn.XLOOKUP(1,(Table1[time]=A15)*(Table1[unit bid]=B15),Table1[my_fi_name],"Not found")} -> FBTC | F15: {=_xlfn.XLOOKUP(1,(Table1[time]=A15)*(Table1[unit ask]=C15),Table1[my_fi_name],"Not found")} -> HODL
A16: 2026-06-10_15-23-43 | B16: 61633.571 | C16: 61620.613 | D16: =B16-C16 -> 12.957212 | E16: {=_xlfn.XLOOKUP(1,(Table1[time]=A16)*(Table1[unit bid]=B16),Table1[my_fi_name],"Not found")} -> FBTC | F16: {=_xlfn.XLOOKUP(1,(Table1[time]=A16)*(Table1[unit ask]=C16),Table1[my_fi_name],"Not found")} -> GBTC | N16: Commissions | T16: Revenues
A17: 2026-06-10_15-38-43 | B17: 61928.983 | C17: 61911.909 | D17: =B17-C17 -> 17.074085 | E17: {=_xlfn.XLOOKUP(1,(Table1[time]=A17)*(Table1[unit bid]=B17),Table1[my_fi_name],"Not found")} -> BTCW | F17: {=_xlfn.XLOOKUP(1,(Table1[time]=A17)*(Table1[unit ask]=C17),Table1[my_fi_name],"Not found")} -> HODL | N17: =H3 -> ARKB | O17: 16.581743 | P17: =I3-J3 -> -52 | Q17: =O17*P17 -> -862.25062 | S17: =COUNT(D:D) -> 334 | T17: Trades | V17: =SUM(D:D) -> 3226.9867
A18: 2026-06-10_15-53-43 | B18: 61943.749 | C18: 61929.812 | D18: =B18-C18 -> 13.937336 | E18: {=_xlfn.XLOOKUP(1,(Table1[time]=A18)*(Table1[unit bid]=B18),Table1[my_fi_name],"Not found")} -> FBTC | F18: {=_xlfn.XLOOKUP(1,(Table1[time]=A18)*(Table1[unit ask]=C18),Table1[my_fi_name],"Not found")} -> GBTC | N18: =H4 -> BITB | O18: 10.131385 | P18: =I4-J4 -> -51 | Q18: =O18*P18 -> -516.70064 | S18: =COUNTIF(D:D,">0") -> 281 | T18: Positive Trades | V18: =SUMIF(D:D,">0") -> 3400.228
A19: 2026-06-11_09-32-32 | B19: 62607.348 | C19: 62591.375 | D19: =B19-C19 -> 15.972465 | E19: {=_xlfn.XLOOKUP(1,(Table1[time]=A19)*(Table1[unit bid]=B19),Table1[my_fi_name],"Not found")} -> BTC | F19: {=_xlfn.XLOOKUP(1,(Table1[time]=A19)*(Table1[unit ask]=C19),Table1[my_fi_name],"Not found")} -> IBIT | N19: =H5 -> BRRR | O19: 19.505557 | P19: =I5-J5 -> -47 | Q19: =O19*P19 -> -916.7612 | S19: =S18/S17 -> 0.84131737 | T19: Positive Pct
A20: 2026-06-11_09-47-32 | B20: 62982.629 | C20: 62975.941 | D20: =B20-C20 -> 6.687912 | E20: {=_xlfn.XLOOKUP(1,(Table1[time]=A20)*(Table1[unit bid]=B20),Table1[my_fi_name],"Not found")} -> BRRR | F20: {=_xlfn.XLOOKUP(1,(Table1[time]=A20)*(Table1[unit ask]=C20),Table1[my_fi_name],"Not found")} -> GBTC | N20: =H6 -> BTC | O20: 12.437123 | P20: =I6-J6 -> -48 | Q20: =O20*P20 -> -596.98191
A21: 2026-06-11_10-25-57 | B21: 62926.749 | C21: 62924.406 | D21: =B21-C21 -> 2.34309 | E21: {=_xlfn.XLOOKUP(1,(Table1[time]=A21)*(Table1[unit bid]=B21),Table1[my_fi_name],"Not found")} -> IBIT | F21: {=_xlfn.XLOOKUP(1,(Table1[time]=A21)*(Table1[unit ask]=C21),Table1[my_fi_name],"Not found")} -> GBTC | N21: =H7 -> BTCW | O21: 5.2035714 | P21: =I7-J7 -> -6 | Q21: =O21*P21 -> -31.221429
A22: 2026-06-11_10-40-57 | B22: 62856.059 | C22: 62847.103 | D22: =B22-C22 -> 8.95531 | E22: {=_xlfn.XLOOKUP(1,(Table1[time]=A22)*(Table1[unit bid]=B22),Table1[my_fi_name],"Not found")} -> BTC | F22: {=_xlfn.XLOOKUP(1,(Table1[time]=A22)*(Table1[unit ask]=C22),Table1[my_fi_name],"Not found")} -> GBTC | N22: =H8 -> EZBC | O22: 9.5160054 | P22: =I8-J8 -> -15 | Q22: =O22*P22 -> -142.74008
A23: 2026-06-11_10-55-57 | B23: 62805.787 | C23: 62795.568 | D23: =B23-C23 -> 10.219031 | E23: {=_xlfn.XLOOKUP(1,(Table1[time]=A23)*(Table1[unit bid]=B23),Table1[my_fi_name],"Not found")} -> FBTC | F23: {=_xlfn.XLOOKUP(1,(Table1[time]=A23)*(Table1[unit ask]=C23),Table1[my_fi_name],"Not found")} -> GBTC | N23: =H9 -> FBTC | O23: 6.3184753 | P23: =I9-J9 -> -121 | Q23: =O23*P23 -> -764.53552
A24: 2026-06-11_11-10-57 | B24: 62667.929 | C24: 62653.846 | D24: =B24-C24 -> 14.08271 | E24: {=_xlfn.XLOOKUP(1,(Table1[time]=A24)*(Table1[unit bid]=B24),Table1[my_fi_name],"Not found")} -> FBTC | F24: {=_xlfn.XLOOKUP(1,(Table1[time]=A24)*(Table1[unit ask]=C24),Table1[my_fi_name],"Not found")} -> GBTC | N24: =H10 -> GBTC | O24: 7.0883807 | P24: =I10-J10 -> -148 | Q24: =O24*P24 -> -1049.0804
A25: 2026-06-11_11-25-57 | B25: 62690.905 | C25: 62689.785 | D25: =B25-C25 -> 1.120074 | E25: {=_xlfn.XLOOKUP(1,(Table1[time]=A25)*(Table1[unit bid]=B25),Table1[my_fi_name],"Not found")} -> FBTC | F25: {=_xlfn.XLOOKUP(1,(Table1[time]=A25)*(Table1[unit ask]=C25),Table1[my_fi_name],"Not found")} -> HODL | N25: =H11 -> HODL | O25: 19.446916 | P25: =I11-J11 -> -34 | Q25: =O25*P25 -> -661.19514
A26: 2026-06-11_11-40-57 | B26: 62797.42 | C26: 62782.684 | D26: =B26-C26 -> 14.73525 | E26: {=_xlfn.XLOOKUP(1,(Table1[time]=A26)*(Table1[unit bid]=B26),Table1[my_fi_name],"Not found")} -> ARKB | F26: {=_xlfn.XLOOKUP(1,(Table1[time]=A26)*(Table1[unit ask]=C26),Table1[my_fi_name],"Not found")} -> GBTC | N26: =H12 -> IBIT | O26: 9.7074934 | P26: =I12-J12 -> -146 | Q26: =O26*P26 -> -1417.294
A27: 2026-06-11_11-55-57 | B27: 62576.024 | C27: 62563.66 | D27: =B27-C27 -> 12.363901 | E27: {=_xlfn.XLOOKUP(1,(Table1[time]=A27)*(Table1[unit bid]=B27),Table1[my_fi_name],"Not found")} -> FBTC | F27: {=_xlfn.XLOOKUP(1,(Table1[time]=A27)*(Table1[unit ask]=C27),Table1[my_fi_name],"Not found")} -> GBTC | P27: =SUM(P17:P26) -> -668 | Q27: =SUM(Q17:Q26) -> -6958.7609
A28: 2026-06-11_12-10-57 | B28: 62656.441 | C28: 62653.617 | D28: =B28-C28 -> 2.8242 | E28: {=_xlfn.XLOOKUP(1,(Table1[time]=A28)*(Table1[unit bid]=B28),Table1[my_fi_name],"Not found")} -> FBTC | F28: {=_xlfn.XLOOKUP(1,(Table1[time]=A28)*(Table1[unit ask]=C28),Table1[my_fi_name],"Not found")} -> BITB
A29: 2026-06-11_12-25-57 | B29: 62486.144 | C29: 62486.357 | D29: =B29-C29 -> -0.212946 | E29: {=_xlfn.XLOOKUP(1,(Table1[time]=A29)*(Table1[unit bid]=B29),Table1[my_fi_name],"Not found")} -> BRRR | F29: {=_xlfn.XLOOKUP(1,(Table1[time]=A29)*(Table1[unit ask]=C29),Table1[my_fi_name],"Not found")} -> GBTC
A30: 2026-06-11_12-40-57 | B30: 62616.534 | C30: 62615.195 | D30: =B30-C30 -> 1.338945 | E30: {=_xlfn.XLOOKUP(1,(Table1[time]=A30)*(Table1[unit bid]=B30),Table1[my_fi_name],"Not found")} -> ARKB | F30: {=_xlfn.XLOOKUP(1,(Table1[time]=A30)*(Table1[unit ask]=C30),Table1[my_fi_name],"Not found")} -> GBTC
A31: 2026-06-11_12-55-57 | B31: 62499.241 | C31: 62503.119 | D31: =B31-C31 -> -3.877707 | E31: {=_xlfn.XLOOKUP(1,(Table1[time]=A31)*(Table1[unit bid]=B31),Table1[my_fi_name],"Not found")} -> GBTC | F31: {=_xlfn.XLOOKUP(1,(Table1[time]=A31)*(Table1[unit ask]=C31),Table1[my_fi_name],"Not found")} -> IBIT
A32: 2026-06-11_13-10-57 | B32: 62477.637 | C32: 62460.59 | D32: =B32-C32 -> 17.047563 | E32: {=_xlfn.XLOOKUP(1,(Table1[time]=A32)*(Table1[unit bid]=B32),Table1[my_fi_name],"Not found")} -> HODL | F32: {=_xlfn.XLOOKUP(1,(Table1[time]=A32)*(Table1[unit ask]=C32),Table1[my_fi_name],"Not found")} -> GBTC
A33: 2026-06-11_13-25-57 | B33: 62300.847 | C33: 62303.699 | D33: =B33-C33 -> -2.852385 | E33: {=_xlfn.XLOOKUP(1,(Table1[time]=A33)*(Table1[unit bid]=B33),Table1[my_fi_name],"Not found")} -> HODL | F33: {=_xlfn.XLOOKUP(1,(Table1[time]=A33)*(Table1[unit ask]=C33),Table1[my_fi_name],"Not found")} -> BITB
A34: 2026-06-11_13-40-57 | B34: 63255.514 | C34: 63259.384 | D34: =B34-C34 -> -3.870469 | E34: {=_xlfn.XLOOKUP(1,(Table1[time]=A34)*(Table1[unit bid]=B34),Table1[my_fi_name],"Not found")} -> HODL | F34: {=_xlfn.XLOOKUP(1,(Table1[time]=A34)*(Table1[unit ask]=C34),Table1[my_fi_name],"Not found")} -> GBTC
A35: 2026-06-11_13-55-57 | B35: 63391.683 | C35: 63388.222 | D35: =B35-C35 -> 3.461234 | E35: {=_xlfn.XLOOKUP(1,(Table1[time]=A35)*(Table1[unit bid]=B35),Table1[my_fi_name],"Not found")} -> FBTC | F35: {=_xlfn.XLOOKUP(1,(Table1[time]=A35)*(Table1[unit ask]=C35),Table1[my_fi_name],"Not found")} -> GBTC
A36: 2026-06-11_14-10-57 | B36: 63288.29 | C36: 63279.781 | D36: =B36-C36 -> 8.509052 | E36: {=_xlfn.XLOOKUP(1,(Table1[time]=A36)*(Table1[unit bid]=B36),Table1[my_fi_name],"Not found")} -> FBTC | F36: {=_xlfn.XLOOKUP(1,(Table1[time]=A36)*(Table1[unit ask]=C36),Table1[my_fi_name],"Not found")} -> ARKB
A37: 2026-06-11_14-25-57 | B37: 63376.091 | C37: 63362.455 | D37: =B37-C37 -> 13.636049 | E37: {=_xlfn.XLOOKUP(1,(Table1[time]=A37)*(Table1[unit bid]=B37),Table1[my_fi_name],"Not found")} -> BTC | F37: {=_xlfn.XLOOKUP(1,(Table1[time]=A37)*(Table1[unit ask]=C37),Table1[my_fi_name],"Not found")} -> GBTC
A38: 2026-06-11_14-40-57 | B38: 63426.148 | C38: 63426.874 | D38: =B38-C38 -> -0.725632 | E38: {=_xlfn.XLOOKUP(1,(Table1[time]=A38)*(Table1[unit bid]=B38),Table1[my_fi_name],"Not found")} -> FBTC | F38: {=_xlfn.XLOOKUP(1,(Table1[time]=A38)*(Table1[unit ask]=C38),Table1[my_fi_name],"Not found")} -> GBTC
A39: 2026-06-11_14-55-57 | B39: 63426.148 | C39: 63412.519 | D39: =B39-C39 -> 13.628903 | E39: {=_xlfn.XLOOKUP(1,(Table1[time]=A39)*(Table1[unit bid]=B39),Table1[my_fi_name],"Not found")} -> FBTC | F39: {=_xlfn.XLOOKUP(1,(Table1[time]=A39)*(Table1[unit ask]=C39),Table1[my_fi_name],"Not found")} -> EZBC
... A335: 2026-07-02_15-57-59 | B335: 61560.077 | C335: 61539.695 | D335: =B335-C335 -> 20.381625 | E335: {=_xlfn.XLOOKUP(1,(Table1[time]=A335)*(Table1[unit bid]=B335),Table1[my_fi_name],"Not found")} -> IBIT | F335: {=_xlfn.XLOOKUP(1,(Table1[time]=A335)*(Table1[unit ask]=C335),Table1[my_fi_name],"Not found")} -> ARKB

Sheet Tests
A1: my_fi_name | B1: IBIT
A3: Row Labels | B3: Sum of unit bid | C3: Sum of unit ask | D3: Sum of price_mkt_bid | E3: Sum of price_mkt_ask | F3: =Sheet1!E1 -> bid name | G3: =Sheet1!F1 -> ask name | H3: sell buy | I3: buy sell | L3: =H3 -> sell buy | M3: =I3 -> buy sell | N3: total
A4: 2026-06-10_11-53-43 | B4: 62502.69 | C4: 62520.341 | D4: 35.41 | E4: 35.42 | F4: =Sheet1!E2 -> FBTC | G4: =Sheet1!F2 -> GBTC | H4: =B4-C5 -> 123.55799 | I4: =B5-C4 -> -158.86027 | K4: =Sheet1!H3 -> ARKB | L4: =SUMIF(F$4:F$180,"ARKB",H$4:H$180) -> 317.80272 | M4: =SUMIF(G$4:G$180,"ARKB",I$4:I$180) -> -352.95621 | N4: =L4+M4 -> -35.153492
A5: 2026-06-10_12-08-43 | B5: 62361.481 | C5: 62379.132 | D5: 35.33 | E5: 35.34 | F5: =Sheet1!E3 -> FBTC | G5: =Sheet1!F3 -> GBTC | H5: =B5-C6 -> 123.55799 | I5: =B6-C5 -> -158.86027 | K5: =Sheet1!H4 -> BITB | L5: =SUMIF(F$4:F$180,"BITB",H$4:H$180) -> 105.90862 | M5: =SUMIF(G$4:G$180,"BITB",I$4:I$180) -> 458.57664 | N5: =L5+M5 -> 564.48526
A6: 2026-06-10_12-23-43 | B6: 62220.272 | C6: 62237.923 | D6: 35.25 | E6: 35.26 | F6: =Sheet1!E4 -> FBTC | G6: =Sheet1!F4 -> BRRR | H6: =B6-C7 -> -70.604564 | I6: =B7-C6 -> 35.302282 | K6: =Sheet1!H5 -> BRRR | L6: =SUMIF(F$4:F$180,"BRRR",H$4:H$180) -> -106.23757 | M6: =SUMIF(G$4:G$180,"BRRR",I$4:I$180) -> 35.322282 | N6: =L6+M6 -> -70.91529
A7: 2026-06-10_12-38-43 | B7: 62273.225 | C7: 62290.877 | D7: 35.28 | E7: 35.29 | F7: =Sheet1!E5 -> FBTC | G7: =Sheet1!F5 -> GBTC | H7: =B7-C8 -> 176.51141 | I7: =B8-C7 -> -211.81369 | K7: =Sheet1!H6 -> BTC | L7: =SUMIF(F$4:F$180,"BTC",H$4:H$180) -> -476.29407 | M7: =SUMIF(G$4:G$180,"BTC",I$4:I$180) -> -0.35 | N7: =L7+M7 -> -476.64407
A8: 2026-06-10_12-53-43 | B8: 62079.063 | C8: 62096.714 | D8: 35.17 | E8: 35.18 | F8: =Sheet1!E6 -> FBTC | G8: =Sheet1!F6 -> GBTC | H8: =B8-C9 -> -52.953423 | I8: =B9-C8 -> 17.651141 | K8: =Sheet1!H7 -> BTCW | L8: =SUMIF(F$4:F$180,"BTCW",H$4:H$180) -> -35.192282 | M8: =SUMIF(G$4:G$180,"BTCW",I$4:I$180) -> 0 | N8: =L8+M8 -> -35.192282
A9: 2026-06-10_13-08-43 | B9: 62114.365 | C9: 62132.016 | D9: 35.19 | E9: 35.2 | F9: =Sheet1!E7 -> FBTC | G9: =Sheet1!F7 -> ARKB | H9: =B9-C10 -> 88.255705 | I9: =B10-C9 -> -123.55799 | K9: =Sheet1!H8 -> EZBC | L9: =SUMIF(F$4:F$180,"EZBC",H$4:H$180) -> 0.01 | M9: =SUMIF(G$4:G$180,"EZBC",I$4:I$180) -> 88.258851 | N9: =L9+M9 -> 88.268851
A10: 2026-06-10_13-23-43 | B10: 62008.458 | C10: 62026.109 | D10: 35.13 | E10: 35.14 | F10: =Sheet1!E8 -> BITB | G10: =Sheet1!F8 -> GBTC | H10: =B10-C11 -> 335.37168 | I10: =B11-C10 -> -370.67396 | K10: =Sheet1!H9 -> FBTC | L10: =SUMIF(F$4:F$180,"FBTC",H$4:H$180) -> -1271.2182 | M10: =SUMIF(G$4:G$180,"FBTC",I$4:I$180) -> -1.18 | N10: =L10+M10 -> -1272.3982
A11: 2026-06-10_13-38-43 | B11: 61655.436 | C11: 61673.087 | D11: 34.93 | E11: 34.94 | F11: =Sheet1!E9 -> FBTC | G11: =Sheet1!F9 -> GBTC | H11: =B11-C12 -> -141.20913 | I11: =B12-C11 -> 105.90685 | K11: =Sheet1!H10 -> GBTC | L11: =SUMIF(F$4:F$180,"GBTC",H$4:H$180) -> 18.381262 | M11: =SUMIF(G$4:G$180,"GBTC",I$4:I$180) -> -652.49264 | N11: =L11+M11 -> -634.11138
A12: 2026-06-10_13-53-43 | B12: 61778.993 | C12: 61796.645 | D12: 35 | E12: 35.01 | F12: =Sheet1!E10 -> FBTC | G12: =Sheet1!F10 -> HODL | H12: =B12-C13 -> -211.81369 | I12: =B13-C12 -> 176.51141 | K12: =Sheet1!H11 -> HODL | L12: =SUMIF(F$4:F$180,"HODL",H$4:H$180) -> -1217.7971 | M12: =SUMIF(G$4:G$180,"HODL",I$4:I$180) -> 123.1015 | N12: =L12+M12 -> -1094.6956
A13: 2026-06-10_14-08-43 | B13: 61973.156 | C13: 61990.807 | D13: 35.11 | E13: 35.12 | F13: =Sheet1!E11 -> BITB | G13: =Sheet1!F11 -> GBTC | H13: =B13-C14 -> 88.255705 | I13: =B14-C13 -> -123.55799 | K13: =Sheet1!H12 -> IBIT | L13: =SUMIF(F$4:F$180,"IBIT",H$4:H$180) -> 440.44479 | M13: =SUMIF(G$4:G$180,"IBIT",I$4:I$180) -> 334.99398 | N13: =L13+M13 -> 775.43877
A14: 2026-06-10_14-23-43 | B14: 61867.249 | C14: 61884.9 | D14: 35.05 | E14: 35.06 | F14: =Sheet1!E12 -> FBTC | G14: =Sheet1!F12 -> ARKB | H14: =B14-C15 -> 123.55799 | I14: =B15-C14 -> -158.86027
A15: 2026-06-10_14-38-43 | B15: 61726.04 | C15: 61743.691 | D15: 34.97 | E15: 34.98 | F15: =Sheet1!E13 -> BITB | G15: =Sheet1!F13 -> GBTC | H15: =B15-C16 -> -17.651141 | I15: =B16-C15 -> -17.651141
A16: 2026-06-10_14-53-43 | B16: 61726.04 | C16: 61743.691 | D16: 34.97 | E16: 34.98 | F16: =Sheet1!E14 -> IBIT | G16: =Sheet1!F14 -> GBTC | H16: =B16-C17 -> -141.20913 | I16: =B17-C16 -> 105.90685
A17: 2026-06-10_15-08-43 | B17: 61849.598 | C17: 61867.249 | D17: 35.04 | E17: 35.05 | F17: =Sheet1!E15 -> FBTC | G17: =Sheet1!F15 -> HODL | H17: =B17-C18 -> 211.81369 | I17: =B18-C17 -> -247.11597
A18: 2026-06-10_15-23-43 | B18: 61620.133 | C18: 61637.784 | D18: 34.91 | E18: 34.92 | F18: =Sheet1!E16 -> FBTC | G18: =Sheet1!F16 -> GBTC | H18: =B18-C19 -> -317.72054 | I18: =B19-C18 -> 282.41826
A19: 2026-06-10_15-38-43 | B19: 61920.203 | C19: 61937.854 | D19: 35.08 | E19: 35.09 | F19: =Sheet1!E17 -> BTCW | G19: =Sheet1!F17 -> HODL | H19: =B19-C20 -> -35.302282 | I19: =B20-C19 -> 0
A20: 2026-06-10_15-53-43 | B20: 61937.854 | C20: 61955.505 | D20: 35.09 | E20: 35.1 | F20: =Sheet1!E18 -> FBTC | G20: =Sheet1!F18 -> GBTC | H20: =B20-C21 -> -653.52128 | I20: =B21-C20 -> 618.21888
A21: 2026-06-11_09-32-32 | B21: 62573.724 | C21: 62591.375 | D21: 35.45 | E21: 35.46 | F21: =Sheet1!E19 -> BTC | G21: =Sheet1!F19 -> IBIT | H21: =B21-C22 -> -423.63029 | I21: =B22-C21 -> 388.32776
A22: 2026-06-11_09-47-32 | B22: 62979.703 | C22: 62997.354 | D22: 35.68 | E22: 35.69 | F22: =Sheet1!E20 -> BRRR | G22: =Sheet1!F20 -> GBTC | H22: =B22-C23 -> 35.302524 | I22: =B23-C22 -> -70.605048
A23: 2026-06-11_10-25-57 | B23: 62926.749 | C23: 62944.4 | D23: 35.65 | E23: 35.66 | F23: =Sheet1!E21 -> IBIT | G23: =Sheet1!F21 -> GBTC | H23: =B23-C24 -> 70.605048 | I23: =B24-C23 -> -105.90757
A24: 2026-06-11_10-40-57 | B24: 62838.493 | C24: 62856.144 | D24: 35.6 | E24: 35.61 | F24: =Sheet1!E22 -> BTC | G24: =Sheet1!F22 -> GBTC | H24: =B24-C25 -> 17.651262 | I24: =B25-C24 -> -52.953786
A25: 2026-06-11_10-55-57 | B25: 62803.19 | C25: 62820.841 | D25: 35.58 | E25: 35.59 | F25: =Sheet1!E23 -> FBTC | G25: =Sheet1!F23 -> GBTC | H25: =B25-C26 -> 123.55883 | I25: =B26-C25 -> -158.86136
... A65: 2026-06-12_15-30-28 | B65: 63687.063 | C65: 63704.715 | D65: 36.08 | E65: 36.09 | F65: =Sheet1!E63 -> BTC | G65: =Sheet1!F63 -> FBTC | H65: =B65-C66 -> 35.30325 | I65: =B66-C65 -> -70.6065
A66: 2026-06-12_15-45-28 | B66: 63634.108 | C66: 63651.76 | D66: 36.05 | E66: 36.06 | F66: =Sheet1!E64 -> FBTC | G66: =Sheet1!F64 -> EZBC
A67: 2026-06-15_12-35-12 | B67: 67171.127 | C67: 67188.776 | D67: 38.06 | E67: 38.07 | F67: =Sheet1!E65 -> BTC | G67: =Sheet1!F65 -> HODL | H67: =D67-E68 -> 0.05 | I67: =D68-E67 -> -0.07
A68: 2026-06-15_12-50-12 | B68: 67076.635 | C68: 67094.287 | D68: 38 | E68: 38.01 | F68: =Sheet1!E66 -> ARKB | G68: =Sheet1!F66 -> BITB | H68: =D68-E69 -> 0.12 | I68: =D69-E68 -> -0.14
A69: 2026-06-15_13-05-12 | B69: 66847.162 | C69: 66864.814 | D69: 37.87 | E69: 37.88 | F69: =Sheet1!E67 -> BTC | G69: =Sheet1!F67 -> GBTC | H69: =D69-E70 -> 0.01 | I69: =D70-E69 -> -0.03
A70: 2026-06-15_13-20-12 | B70: 66811.859 | C70: 66829.51 | D70: 37.85 | E70: 37.86 | F70: =Sheet1!E68 -> FBTC | G70: =Sheet1!F68 -> GBTC | H70: =D70-E71 -> 0.03 | I70: =D71-E70 -> -0.05
A71: 2026-06-15_13-35-12 | B71: 66741.252 | C71: 66758.903 | D71: 37.81 | E71: 37.82 | F71: =Sheet1!E69 -> BRRR | G71: =Sheet1!F69 -> GBTC | H71: =D71-E72 -> -0.09 | I71: =D72-E71 -> 0.07
A72: 2026-06-15_13-50-12 | B72: 66882.466 | C72: 66900.117 | D72: 37.89 | E72: 37.9 | F72: =Sheet1!E70 -> BRRR | G72: =Sheet1!F70 -> GBTC | H72: =D72-E73 -> 0.06 | I72: =D73-E72 -> -0.08
A73: 2026-06-15_14-05-12 | B73: 66758.903 | C73: 66776.555 | D73: 37.82 | E73: 37.83 | F73: =Sheet1!E71 -> IBIT | G73: =Sheet1!F71 -> GBTC | H73: =D73-E74 -> -0.03 | I73: =D74-E73 -> 0.01
A74: 2026-06-15_14-20-12 | B74: 66794.207 | C74: 66811.859 | D74: 37.84 | E74: 37.85 | F74: =Sheet1!E72 -> IBIT | G74: =Sheet1!F72 -> GBTC | H74: =D74-E75 -> -0.01 | I74: =D75-E74 -> -0.01
A75: 2026-06-15_14-35-12 | B75: 66794.207 | C75: 66811.859 | D75: 37.84 | E75: 37.85 | F75: =Sheet1!E73 -> IBIT | G75: =Sheet1!F73 -> GBTC | H75: =D75-E76 -> -0.05 | I75: =D76-E75 -> 0.03
A76: 2026-06-15_14-50-12 | B76: 66864.814 | C76: 66882.466 | D76: 37.88 | E76: 37.89 | F76: =Sheet1!E74 -> BRRR | G76: =Sheet1!F74 -> GBTC | H76: =D76-E77 -> 0.03 | I76: =D77-E76 -> -0.05
A77: 2026-06-15_15-05-12 | B77: 66794.207 | C77: 66811.859 | D77: 37.84 | E77: 37.85 | F77: =Sheet1!E75 -> IBIT | G77: =Sheet1!F75 -> GBTC | H77: =D77-E78 -> 0.18 | I77: =D78-E77 -> -0.2
A78: 2026-06-15_15-20-12 | B78: 66458.824 | C78: 66476.475 | D78: 37.65 | E78: 37.66 | F78: =Sheet1!E76 -> BTC | G78: =Sheet1!F76 -> GBTC | H78: =D78-E79 -> -0.11 | I78: =D79-E78 -> 0.09
A79: 2026-06-15_15-35-12 | B79: 66635.341 | C79: 66652.993 | D79: 37.75 | E79: 37.76 | F79: =Sheet1!E77 -> BRRR | G79: =Sheet1!F77 -> GBTC | H79: =D79-E80 -> 0.03 | I79: =D80-E79 -> -0.05
A80: 2026-06-15_15-50-13 | B80: 66564.734 | C80: 66582.386 | D80: 37.71 | E80: 37.72 | F80: =Sheet1!E78 -> BRRR | G80: =Sheet1!F78 -> GBTC
...
