Workbook

Sheet ETF_2026-06-11
A1: my_fi_name | B1: price_mkt_bid | C1: price_mkt_ask | D1: time | E1: scalar | F1: adj | G1: adj scalar | H1: unit bid | I1: unit ask
A2: ARKB | B2: 20.76 | C2: 20.77 | D2: 2026-06-11_09-32-32 | E2: 3014.7585 | F2: =Sheet1!L3 -> -0.1 | G2: =Table1[[#This Row],[scalar]]-Table1[[#This Row],[adj]] -> 3014.8585 | H2: =Table1[[#This Row],[price_mkt_bid]]*Table1[[#This Row],[adj scalar]] -> 62588.462 | I2: =Table1[[#This Row],[price_mkt_ask]]*Table1[[#This Row],[adj scalar]] -> 62618.611
A3: BITB | B3: 33.98 | C3: 33.99 | D3: 2026-06-11_09-32-32 | E3: =1841.9994-0.2393 -> 1841.7601 | F3: =Sheet1!L4 -> 0.1 | G3: =Table1[[#This Row],[scalar]]-Table1[[#This Row],[adj]] -> 1841.6601 | H3: =Table1[[#This Row],[price_mkt_bid]]*Table1[[#This Row],[adj scalar]] -> 62579.61 | I3: =Table1[[#This Row],[price_mkt_ask]]*Table1[[#This Row],[adj scalar]] -> 62598.027
A4: BRRR | B4: 17.65 | C4: 17.66 | D4: 2026-06-11_09-32-32 | E4: 3546.3342 | F4: =Sheet1!L5 -> 0 | G4: =Table1[[#This Row],[scalar]]-Table1[[#This Row],[adj]] -> 3546.3342 | H4: =Table1[[#This Row],[price_mkt_bid]]*Table1[[#This Row],[adj scalar]] -> 62592.799 | I4: =Table1[[#This Row],[price_mkt_ask]]*Table1[[#This Row],[adj scalar]] -> 62628.262
A5: BTC | B5: 27.69 | C5: 27.7 | D5: 2026-06-11_09-32-32 | E5: =2261.2393-0.03 -> 2261.2093 | F5: =Sheet1!L6 -> 0.2 | G5: =Table1[[#This Row],[scalar]]-Table1[[#This Row],[adj]] -> 2261.0093 | H5: =Table1[[#This Row],[price_mkt_bid]]*Table1[[#This Row],[adj scalar]] -> 62607.348 | I5: =Table1[[#This Row],[price_mkt_ask]]*Table1[[#This Row],[adj scalar]] -> 62629.958
A6: BTCW | B6: 66.15 | C6: 66.26 | D6: 2026-06-11_09-32-32 | E6: 946.0649 | F6: =Sheet1!L7 -> 0 | G6: =Table1[[#This Row],[scalar]]-Table1[[#This Row],[adj]] -> 946.0649 | H6: =Table1[[#This Row],[price_mkt_bid]]*Table1[[#This Row],[adj scalar]] -> 62582.193 | I6: =Table1[[#This Row],[price_mkt_ask]]*Table1[[#This Row],[adj scalar]] -> 62686.26
A7: EZBC | B7: 36.17 | C7: 36.18 | D7: 2026-06-11_09-32-32 | E7: 1730.0288 | F7: =Sheet1!L8 -> -0.2 | G7: =Table1[[#This Row],[scalar]]-Table1[[#This Row],[adj]] -> 1730.2288 | H7: =Table1[[#This Row],[price_mkt_bid]]*Table1[[#This Row],[adj scalar]] -> 62582.376 | I7: =Table1[[#This Row],[price_mkt_ask]]*Table1[[#This Row],[adj scalar]] -> 62599.678
A8: FBTC | B8: 54.48 | C8: 54.49 | D8: 2026-06-11_09-32-32 | E8: 1148.7663 | F8: =Sheet1!L9 -> 0.05 | G8: =Table1[[#This Row],[scalar]]-Table1[[#This Row],[adj]] -> 1148.7163 | H8: =Table1[[#This Row],[price_mkt_bid]]*Table1[[#This Row],[adj scalar]] -> 62582.064 | I8: =Table1[[#This Row],[price_mkt_ask]]*Table1[[#This Row],[adj scalar]] -> 62593.551
A9: GBTC | B9: 48.57 | C9: 48.59 | D9: 2026-06-11_09-32-32 | E9: 1288.4785 | F9: =Sheet1!L10 -> -0.05 | G9: =Table1[[#This Row],[scalar]]-Table1[[#This Row],[adj]] -> 1288.5285 | H9: =Table1[[#This Row],[price_mkt_bid]]*Table1[[#This Row],[adj scalar]] -> 62583.829 | I9: =Table1[[#This Row],[price_mkt_ask]]*Table1[[#This Row],[adj scalar]] -> 62609.6
A10: HODL | B10: 17.7 | C10: 17.71 | D10: 2026-06-11_09-32-32 | E10: 3535.8029 | F10: =Sheet1!L11 -> 0 | G10: =Table1[[#This Row],[scalar]]-Table1[[#This Row],[adj]] -> 3535.8029 | H10: =Table1[[#This Row],[price_mkt_bid]]*Table1[[#This Row],[adj scalar]] -> 62583.711 | I10: =Table1[[#This Row],[price_mkt_ask]]*Table1[[#This Row],[adj scalar]] -> 62619.069
A11: IBIT | B11: 35.45 | C11: 35.46 | D11: 2026-06-11_09-32-32 | E11: 1764.9262 | F11: =Sheet1!L12 -> 0 | G11: =Table1[[#This Row],[scalar]]-Table1[[#This Row],[adj]] -> 1764.9262 | H11: =Table1[[#This Row],[price_mkt_bid]]*Table1[[#This Row],[adj scalar]] -> 62566.634 | I11: =Table1[[#This Row],[price_mkt_ask]]*Table1[[#This Row],[adj scalar]] -> 62584.283
A12: ARKB | B12: 20.88 | C12: 20.89 | D12: 2026-06-11_09-47-32 | E12: 3014.7585 | F12: =F2 -> -0.1 | G12: =Table1[[#This Row],[scalar]]-Table1[[#This Row],[adj]] -> 3014.8585 | H12: =Table1[[#This Row],[price_mkt_bid]]*Table1[[#This Row],[adj scalar]] -> 62950.245 | I12: =Table1[[#This Row],[price_mkt_ask]]*Table1[[#This Row],[adj scalar]] -> 62980.394
A13: BITB | B13: 34.19 | C13: 34.2 | D13: 2026-06-11_09-47-32 | E13: =1841.9994-0.2393 -> 1841.7601 | F13: =F3 -> 0.1 | G13: =Table1[[#This Row],[scalar]]-Table1[[#This Row],[adj]] -> 1841.6601 | H13: =Table1[[#This Row],[price_mkt_bid]]*Table1[[#This Row],[adj scalar]] -> 62966.359 | I13: =Table1[[#This Row],[price_mkt_ask]]*Table1[[#This Row],[adj scalar]] -> 62984.775
A14: BRRR | B14: 17.76 | C14: 17.77 | D14: 2026-06-11_09-47-32 | E14: 3546.3342 | F14: =F4 -> 0 | G14: =Table1[[#This Row],[scalar]]-Table1[[#This Row],[adj]] -> 3546.3342 | H14: =Table1[[#This Row],[price_mkt_bid]]*Table1[[#This Row],[adj scalar]] -> 62982.895 | I14: =Table1[[#This Row],[price_mkt_ask]]*Table1[[#This Row],[adj scalar]] -> 63018.359
A15: BTC | B15: 27.85 | C15: 27.86 | D15: 2026-06-11_09-47-32 | E15: =2261.2393-0.03 -> 2261.2093 | F15: =F5 -> 0.2 | G15: =Table1[[#This Row],[scalar]]-Table1[[#This Row],[adj]] -> 2261.0093 | H15: =Table1[[#This Row],[price_mkt_bid]]*Table1[[#This Row],[adj scalar]] -> 62969.109 | I15: =Table1[[#This Row],[price_mkt_ask]]*Table1[[#This Row],[adj scalar]] -> 62991.719
A16: BTCW | B16: 66.53 | C16: 66.64 | D16: 2026-06-11_09-47-32 | E16: 946.0649 | F16: =F6 -> 0 | G16: =Table1[[#This Row],[scalar]]-Table1[[#This Row],[adj]] -> 946.0649 | H16: =Table1[[#This Row],[price_mkt_bid]]*Table1[[#This Row],[adj scalar]] -> 62941.698 | I16: =Table1[[#This Row],[price_mkt_ask]]*Table1[[#This Row],[adj scalar]] -> 63045.765
A17: EZBC | B17: 36.39 | C17: 36.41 | D17: 2026-06-11_09-47-32 | E17: 1730.0288 | F17: =F7 -> -0.2 | G17: =Table1[[#This Row],[scalar]]-Table1[[#This Row],[adj]] -> 1730.2288 | H17: =Table1[[#This Row],[price_mkt_bid]]*Table1[[#This Row],[adj scalar]] -> 62963.026 | I17: =Table1[[#This Row],[price_mkt_ask]]*Table1[[#This Row],[adj scalar]] -> 62997.631
A18: FBTC | B18: 54.82 | C18: 54.83 | D18: 2026-06-11_09-47-32 | E18: 1148.7663 | F18: =F8 -> 0.05 | G18: =Table1[[#This Row],[scalar]]-Table1[[#This Row],[adj]] -> 1148.7163 | H18: =Table1[[#This Row],[price_mkt_bid]]*Table1[[#This Row],[adj scalar]] -> 62972.628 | I18: =Table1[[#This Row],[price_mkt_ask]]*Table1[[#This Row],[adj scalar]] -> 62984.115
A19: GBTC | B19: 48.87 | C19: 48.88 | D19: 2026-06-11_09-47-32 | E19: 1288.4785 | F19: =F9 -> -0.05 | G19: =Table1[[#This Row],[scalar]]-Table1[[#This Row],[adj]] -> 1288.5285 | H19: =Table1[[#This Row],[price_mkt_bid]]*Table1[[#This Row],[adj scalar]] -> 62970.388 | I19: =Table1[[#This Row],[price_mkt_ask]]*Table1[[#This Row],[adj scalar]] -> 62983.273
A20: HODL | B20: 17.81 | C20: 17.82 | D20: 2026-06-11_09-47-32 | E20: 3535.8029 | F20: =F10 -> 0 | G20: =Table1[[#This Row],[scalar]]-Table1[[#This Row],[adj]] -> 3535.8029 | H20: =Table1[[#This Row],[price_mkt_bid]]*Table1[[#This Row],[adj scalar]] -> 62972.65 | I20: =Table1[[#This Row],[price_mkt_ask]]*Table1[[#This Row],[adj scalar]] -> 63008.008
A21: IBIT | B21: 35.68 | C21: 35.69 | D21: 2026-06-11_09-47-32 | E21: 1764.9262 | F21: =F11 -> 0 | G21: =Table1[[#This Row],[scalar]]-Table1[[#This Row],[adj]] -> 1764.9262 | H21: =Table1[[#This Row],[price_mkt_bid]]*Table1[[#This Row],[adj scalar]] -> 62972.567 | I21: =Table1[[#This Row],[price_mkt_ask]]*Table1[[#This Row],[adj scalar]] -> 62990.216
A22: ARKB | B22: 20.87 | C22: 20.88 | D22: 2026-06-11_10-25-57 | E22: 3014.7585 | F22: =F12 -> -0.1 | G22: =Table1[[#This Row],[scalar]]-Table1[[#This Row],[adj]] -> 3014.8585 | H22: =Table1[[#This Row],[price_mkt_bid]]*Table1[[#This Row],[adj scalar]] -> 62920.097 | I22: =Table1[[#This Row],[price_mkt_ask]]*Table1[[#This Row],[adj scalar]] -> 62950.245
A23: BITB | B23: 34.16 | C23: 34.17 | D23: 2026-06-11_10-25-57 | E23: =1841.9994-0.2393 -> 1841.7601 | F23: =F13 -> 0.1 | G23: =Table1[[#This Row],[scalar]]-Table1[[#This Row],[adj]] -> 1841.6601 | H23: =Table1[[#This Row],[price_mkt_bid]]*Table1[[#This Row],[adj scalar]] -> 62911.109 | I23: =Table1[[#This Row],[price_mkt_ask]]*Table1[[#This Row],[adj scalar]] -> 62929.526
A24: BRRR | B24: 17.74 | C24: 17.75 | D24: 2026-06-11_10-25-57 | E24: 3546.3342 | F24: =F14 -> 0 | G24: =Table1[[#This Row],[scalar]]-Table1[[#This Row],[adj]] -> 3546.3342 | H24: =Table1[[#This Row],[price_mkt_bid]]*Table1[[#This Row],[adj scalar]] -> 62911.969 | I24: =Table1[[#This Row],[price_mkt_ask]]*Table1[[#This Row],[adj scalar]] -> 62947.432
A25: BTC | B25: 27.83 | C25: 27.84 | D25: 2026-06-11_10-25-57 | E25: =2261.2393-0.03 -> 2261.2093 | F25: =F15 -> 0.2 | G25: =Table1[[#This Row],[scalar]]-Table1[[#This Row],[adj]] -> 2261.0093 | H25: =Table1[[#This Row],[price_mkt_bid]]*Table1[[#This Row],[adj scalar]] -> 62923.889 | I25: =Table1[[#This Row],[price_mkt_ask]]*Table1[[#This Row],[adj scalar]] -> 62946.499
A26: BTCW | B26: 66.51 | C26: 66.66 | D26: 2026-06-11_10-25-57 | E26: 946.0649 | F26: =F16 -> 0 | G26: =Table1[[#This Row],[scalar]]-Table1[[#This Row],[adj]] -> 946.0649 | H26: =Table1[[#This Row],[price_mkt_bid]]*Table1[[#This Row],[adj scalar]] -> 62922.776 | I26: =Table1[[#This Row],[price_mkt_ask]]*Table1[[#This Row],[adj scalar]] -> 63064.686
A27: EZBC | B27: 36.36 | C27: 36.38 | D27: 2026-06-11_10-25-57 | E27: 1730.0288 | F27: =F17 -> -0.2 | G27: =Table1[[#This Row],[scalar]]-Table1[[#This Row],[adj]] -> 1730.2288 | H27: =Table1[[#This Row],[price_mkt_bid]]*Table1[[#This Row],[adj scalar]] -> 62911.119 | I27: =Table1[[#This Row],[price_mkt_ask]]*Table1[[#This Row],[adj scalar]] -> 62945.724
A28: FBTC | B28: 54.77 | C28: 54.78 | D28: 2026-06-11_10-25-57 | E28: 1148.7663 | F28: =F18 -> 0.05 | G28: =Table1[[#This Row],[scalar]]-Table1[[#This Row],[adj]] -> 1148.7163 | H28: =Table1[[#This Row],[price_mkt_bid]]*Table1[[#This Row],[adj scalar]] -> 62915.192 | I28: =Table1[[#This Row],[price_mkt_ask]]*Table1[[#This Row],[adj scalar]] -> 62926.679
A29: GBTC | B29: 48.83 | C29: 48.84 | D29: 2026-06-11_10-25-57 | E29: 1288.4785 | F29: =F19 -> -0.05 | G29: =Table1[[#This Row],[scalar]]-Table1[[#This Row],[adj]] -> 1288.5285 | H29: =Table1[[#This Row],[price_mkt_bid]]*Table1[[#This Row],[adj scalar]] -> 62918.847 | I29: =Table1[[#This Row],[price_mkt_ask]]*Table1[[#This Row],[adj scalar]] -> 62931.732
A30: HODL | B30: 17.79 | C30: 17.8 | D30: 2026-06-11_10-25-57 | E30: 3535.8029 | F30: =F20 -> 0 | G30: =Table1[[#This Row],[scalar]]-Table1[[#This Row],[adj]] -> 3535.8029 | H30: =Table1[[#This Row],[price_mkt_bid]]*Table1[[#This Row],[adj scalar]] -> 62901.934 | I30: =Table1[[#This Row],[price_mkt_ask]]*Table1[[#This Row],[adj scalar]] -> 62937.292
A31: IBIT | B31: 35.65 | C31: 35.66 | D31: 2026-06-11_10-25-57 | E31: 1764.9262 | F31: =F21 -> 0 | G31: =Table1[[#This Row],[scalar]]-Table1[[#This Row],[adj]] -> 1764.9262 | H31: =Table1[[#This Row],[price_mkt_bid]]*Table1[[#This Row],[adj scalar]] -> 62919.619 | I31: =Table1[[#This Row],[price_mkt_ask]]*Table1[[#This Row],[adj scalar]] -> 62937.268
A32: ARKB | B32: 20.84 | C32: 20.85 | D32: 2026-06-11_10-40-57 | E32: 3014.7585 | F32: =F22 -> -0.1 | G32: =Table1[[#This Row],[scalar]]-Table1[[#This Row],[adj]] -> 3014.8585 | H32: =Table1[[#This Row],[price_mkt_bid]]*Table1[[#This Row],[adj scalar]] -> 62829.651 | I32: =Table1[[#This Row],[price_mkt_ask]]*Table1[[#This Row],[adj scalar]] -> 62859.8
A33: BITB | B33: 34.12 | C33: 34.13 | D33: 2026-06-11_10-40-57 | E33: =1841.9994-0.2393 -> 1841.7601 | F33: =F23 -> 0.1 | G33: =Table1[[#This Row],[scalar]]-Table1[[#This Row],[adj]] -> 1841.6601 | H33: =Table1[[#This Row],[price_mkt_bid]]*Table1[[#This Row],[adj scalar]] -> 62837.443 | I33: =Table1[[#This Row],[price_mkt_ask]]*Table1[[#This Row],[adj scalar]] -> 62855.859
A34: BRRR | B34: 17.72 | C34: 17.73 | D34: 2026-06-11_10-40-57 | E34: 3546.3342 | F34: =F24 -> 0 | G34: =Table1[[#This Row],[scalar]]-Table1[[#This Row],[adj]] -> 3546.3342 | H34: =Table1[[#This Row],[price_mkt_bid]]*Table1[[#This Row],[adj scalar]] -> 62841.042 | I34: =Table1[[#This Row],[price_mkt_ask]]*Table1[[#This Row],[adj scalar]] -> 62876.505
A35: BTC | B35: 27.8 | C35: 27.81 | D35: 2026-06-11_10-40-57 | E35: =2261.2393-0.03 -> 2261.2093 | F35: =F25 -> 0.2 | G35: =Table1[[#This Row],[scalar]]-Table1[[#This Row],[adj]] -> 2261.0093 | H35: =Table1[[#This Row],[price_mkt_bid]]*Table1[[#This Row],[adj scalar]] -> 62856.059 | I35: =Table1[[#This Row],[price_mkt_ask]]*Table1[[#This Row],[adj scalar]] -> 62878.669
A36: BTCW | B36: 66.4 | C36: 66.5 | D36: 2026-06-11_10-40-57 | E36: 946.0649 | F36: =F26 -> 0 | G36: =Table1[[#This Row],[scalar]]-Table1[[#This Row],[adj]] -> 946.0649 | H36: =Table1[[#This Row],[price_mkt_bid]]*Table1[[#This Row],[adj scalar]] -> 62818.709 | I36: =Table1[[#This Row],[price_mkt_ask]]*Table1[[#This Row],[adj scalar]] -> 62913.316
A37: EZBC | B37: 36.32 | C37: 36.33 | D37: 2026-06-11_10-40-57 | E37: 1730.0288 | F37: =F27 -> -0.2 | G37: =Table1[[#This Row],[scalar]]-Table1[[#This Row],[adj]] -> 1730.2288 | H37: =Table1[[#This Row],[price_mkt_bid]]*Table1[[#This Row],[adj scalar]] -> 62841.91 | I37: =Table1[[#This Row],[price_mkt_ask]]*Table1[[#This Row],[adj scalar]] -> 62859.212
A38: FBTC | B38: 54.71 | C38: 54.72 | D38: 2026-06-11_10-40-57 | E38: 1148.7663 | F38: =F28 -> 0.05 | G38: =Table1[[#This Row],[scalar]]-Table1[[#This Row],[adj]] -> 1148.7163 | H38: =Table1[[#This Row],[price_mkt_bid]]*Table1[[#This Row],[adj scalar]] -> 62846.269 | I38: =Table1[[#This Row],[price_mkt_ask]]*Table1[[#This Row],[adj scalar]] -> 62857.756
A39: GBTC | B39: 48.77 | C39: 48.78 | D39: 2026-06-11_10-40-57 | E39: 1288.4785 | F39: =F29 -> -0.05 | G39: =Table1[[#This Row],[scalar]]-Table1[[#This Row],[adj]] -> 1288.5285 | H39: =Table1[[#This Row],[price_mkt_bid]]*Table1[[#This Row],[adj scalar]] -> 62841.535 | I39: =Table1[[#This Row],[price_mkt_ask]]*Table1[[#This Row],[adj scalar]] -> 62854.42
A40: HODL | B40: 17.77 | C40: 17.78 | D40: 2026-06-11_10-40-57 | E40: 3535.8029 | F40: =F30 -> 0 | G40: =Table1[[#This Row],[scalar]]-Table1[[#This Row],[adj]] -> 3535.8029 | H40: =Table1[[#This Row],[price_mkt_bid]]*Table1[[#This Row],[adj scalar]] -> 62831.218 | I40: =Table1[[#This Row],[price_mkt_ask]]*Table1[[#This Row],[adj scalar]] -> 62866.576
...

Sheet Sheet1
A1: Row Labels | B1: Max of unit bid | C1: Min of unit ask | D1: net | E1: bid name | F1: ask name | Q1: running total
A2: 2026-06-11_09-32-32 | B2: 62607.348 | C2: 62584.283 | D2: =B2-C2 -> 23.064465 | E2: =_xlfn.XLOOKUP(B2,Table1[unit bid],Table1[my_fi_name]) -> BTC | F2: =_xlfn.XLOOKUP(C2,Table1[unit ask],Table1[my_fi_name]) -> IBIT | I2: hit bid | J2: lift ask | K2: net | L2: diff | M2: price | N2: $ diff | O2: % diff | Q2: =I2 -> hit bid | R2: =J2 -> lift ask | S2: =K2 -> net
A3: 2026-06-11_09-47-32 | B3: 62982.895 | C3: 62980.394 | D3: =B3-C3 -> 2.501327 | E3: =_xlfn.XLOOKUP(B3,Table1[unit bid],Table1[my_fi_name]) -> BRRR | F3: =_xlfn.XLOOKUP(C3,Table1[unit ask],Table1[my_fi_name]) -> ARKB | H3: ARKB | I3: =COUNTIF(E:E,H3) -> 2 | J3: =COUNTIF(F:F,H3) -> 2 | K3: =I3-J3 -> 0 | L3: =[2]Sheet1!L3 -> -0.1 | M3: ='ETF_2026-06-11'!C2 -> 20.77 | N3: =L3*M3 -> -2.077 | O3: =N3/C3 -> -3.2978517e-05 | Q3: =[1]Sheet1!Q3+I3 -> 3 | R3: =[1]Sheet1!R3+J3 -> 5 | S3: =Q3-R3 -> -2
A4: 2026-06-11_10-25-57 | B4: 62923.889 | C4: 62926.679 | D4: =B4-C4 -> -2.790095 | E4: =_xlfn.XLOOKUP(B4,Table1[unit bid],Table1[my_fi_name]) -> BTC | F4: =_xlfn.XLOOKUP(C4,Table1[unit ask],Table1[my_fi_name]) -> FBTC | H4: BITB | I4: =COUNTIF(E:E,H4) -> 1 | J4: =COUNTIF(F:F,H4) -> 7 | K4: =I4-J4 -> -6 | L4: =[2]Sheet1!L4 -> 0.1 | M4: ='ETF_2026-06-11'!C3 -> 33.99 | N4: =L4*M4 -> 3.399 | O4: =N4/C4 -> 5.4015245e-05 | Q4: =[1]Sheet1!Q4+I4 -> 11 | R4: =[1]Sheet1!R4+J4 -> 7 | S4: =Q4-R4 -> 4
A5: 2026-06-11_10-40-57 | B5: 62856.059 | C5: 62849.022 | D5: =B5-C5 -> 7.036558 | E5: =_xlfn.XLOOKUP(B5,Table1[unit bid],Table1[my_fi_name]) -> BTC | F5: =_xlfn.XLOOKUP(C5,Table1[unit ask],Table1[my_fi_name]) -> IBIT | H5: BRRR | I5: =COUNTIF(E:E,H5) -> 3 | J5: =COUNTIF(F:F,H5) -> 0 | K5: =I5-J5 -> 3 | L5: =[2]Sheet1!L5 -> 0 | M5: ='ETF_2026-06-11'!C4 -> 17.66 | N5: =L5*M5 -> 0 | O5: =N5/C5 -> 0 | Q5: =[1]Sheet1!Q5+I5 -> 3 | R5: =[1]Sheet1!R5+J5 -> 0 | S5: =Q5-R5 -> 3
A6: 2026-06-11_10-55-57 | B6: 62805.579 | C6: 62802.879 | D6: =B6-C6 -> 2.699592 | E6: =_xlfn.XLOOKUP(B6,Table1[unit bid],Table1[my_fi_name]) -> BRRR | F6: =_xlfn.XLOOKUP(C6,Table1[unit ask],Table1[my_fi_name]) -> GBTC | H6: BTC | I6: =COUNTIF(E:E,H6) -> 6 | J6: =COUNTIF(F:F,H6) -> 0 | K6: =I6-J6 -> 6 | L6: =[2]Sheet1!L6 -> 0.2 | M6: ='ETF_2026-06-11'!C5 -> 27.7 | N6: =L6*M6 -> 5.54 | O6: =N6/C6 -> 8.8212516e-05 | Q6: =[1]Sheet1!Q6+I6 -> 6 | R6: =[1]Sheet1!R6+J6 -> 2 | S6: =Q6-R6 -> 4
A7: 2026-06-11_11-10-57 | B7: 62662.474 | C7: 62661.141 | D7: =B7-C7 -> 1.33321 | E7: =_xlfn.XLOOKUP(B7,Table1[unit bid],Table1[my_fi_name]) -> FBTC | F7: =_xlfn.XLOOKUP(C7,Table1[unit ask],Table1[my_fi_name]) -> GBTC | H7: BTCW | I7: =COUNTIF(E:E,H7) -> 0 | J7: =COUNTIF(F:F,H7) -> 0 | K7: =I7-J7 -> 0 | L7: =[2]Sheet1!L7 -> 0 | M7: ='ETF_2026-06-11'!C6 -> 66.26 | N7: =L7*M7 -> 0 | O7: =N7/C7 -> 0 | Q7: =[1]Sheet1!Q7+I7 -> 2 | R7: =[1]Sheet1!R7+J7 -> 0 | S7: =Q7-R7 -> 2
A8: 2026-06-11_11-25-57 | B8: 62685.448 | C8: 62689.785 | D8: =B8-C8 -> -4.336926 | E8: =_xlfn.XLOOKUP(B8,Table1[unit bid],Table1[my_fi_name]) -> FBTC | F8: =_xlfn.XLOOKUP(C8,Table1[unit ask],Table1[my_fi_name]) -> HODL | H8: EZBC | I8: =COUNTIF(E:E,H8) -> 0 | J8: =COUNTIF(F:F,H8) -> 1 | K8: =I8-J8 -> -1 | L8: =[2]Sheet1!L8 -> -0.2 | M8: ='ETF_2026-06-11'!C7 -> 36.18 | N8: =L8*M8 -> -7.236 | O8: =N8/C8 -> -0.0001154255 | Q8: =[1]Sheet1!Q8+I8 -> 0 | R8: =[1]Sheet1!R8+J8 -> 1 | S8: =Q8-R8 -> -1
A9: 2026-06-11_11-40-57 | B9: 62799.503 | C9: 62788.833 | D9: =B9-C9 -> 10.669597 | E9: =_xlfn.XLOOKUP(B9,Table1[unit bid],Table1[my_fi_name]) -> ARKB | F9: =_xlfn.XLOOKUP(C9,Table1[unit ask],Table1[my_fi_name]) -> FBTC | H9: FBTC | I9: =COUNTIF(E:E,H9) -> 6 | J9: =COUNTIF(F:F,H9) -> 2 | K9: =I9-J9 -> 4 | L9: =[2]Sheet1!L9 -> 0.05 | M9: ='ETF_2026-06-11'!C8 -> 54.49 | N9: =L9*M9 -> 2.7245 | O9: =N9/C9 -> 4.3391474e-05 | Q9: =[1]Sheet1!Q9+I9 -> 9 | R9: =[1]Sheet1!R9+J9 -> 3 | S9: =Q9-R9 -> 6
A10: 2026-06-11_11-55-57 | B10: 62570.577 | C10: 62566.634 | D10: =B10-C10 -> 3.943071 | E10: =_xlfn.XLOOKUP(B10,Table1[unit bid],Table1[my_fi_name]) -> FBTC | F10: =_xlfn.XLOOKUP(C10,Table1[unit ask],Table1[my_fi_name]) -> IBIT | H10: GBTC | I10: =COUNTIF(E:E,H10) -> 2 | J10: =COUNTIF(F:F,H10) -> 5 | K10: =I10-J10 -> -3 | L10: =[2]Sheet1!L10 -> -0.05 | M10: ='ETF_2026-06-11'!C9 -> 48.59 | N10: =L10*M10 -> -2.4295 | O10: =N10/C10 -> -3.8830601e-05 | Q10: =[1]Sheet1!Q10+I10 -> 3 | R10: =[1]Sheet1!R10+J10 -> 9 | S10: =Q10-R10 -> -6
A11: 2026-06-11_12-10-57 | B11: 62654.427 | C11: 62653.277 | D11: =B11-C11 -> 1.150786 | E11: =_xlfn.XLOOKUP(B11,Table1[unit bid],Table1[my_fi_name]) -> HODL | F11: =_xlfn.XLOOKUP(C11,Table1[unit ask],Table1[my_fi_name]) -> BITB | H11: HODL | I11: =COUNTIF(E:E,H11) -> 5 | J11: =COUNTIF(F:F,H11) -> 1 | K11: =I11-J11 -> 4 | L11: =[2]Sheet1!L11 -> 0 | M11: ='ETF_2026-06-11'!C10 -> 17.71 | N11: =L11*M11 -> 0 | O11: =N11/C11 -> 0 | Q11: =[1]Sheet1!Q11+I11 -> 5 | R11: =[1]Sheet1!R11+J11 -> 6 | S11: =Q11-R11 -> -1
A12: 2026-06-11_12-25-57 | B12: 62486.409 | C12: 62487.527 | D12: =B12-C12 -> -1.118589 | E12: =_xlfn.XLOOKUP(B12,Table1[unit bid],Table1[my_fi_name]) -> BRRR | F12: =_xlfn.XLOOKUP(C12,Table1[unit ask],Table1[my_fi_name]) -> BITB | H12: IBIT | I12: =COUNTIF(E:E,H12) -> 0 | J12: =COUNTIF(F:F,H12) -> 7 | K12: =I12-J12 -> -7 | L12: =[2]Sheet1!L12 -> 0 | M12: ='ETF_2026-06-11'!C11 -> 35.46 | N12: =L12*M12 -> 0 | O12: =N12/C12 -> 0 | Q12: =[1]Sheet1!Q12+I12 -> 0 | R12: =[1]Sheet1!R12+J12 -> 9 | S12: =Q12-R12 -> -9
A13: 2026-06-11_12-40-57 | B13: 62618.611 | C13: 62616.443 | D13: =B13-C13 -> 2.167645 | E13: =_xlfn.XLOOKUP(B13,Table1[unit bid],Table1[my_fi_name]) -> ARKB | F13: =_xlfn.XLOOKUP(C13,Table1[unit ask],Table1[my_fi_name]) -> BITB | I13: =SUM(I3:I12) -> 25 | J13: =SUM(J3:J12) -> 25 | K13: =SUM(K3:K12) -> 0 | Q13: =SUM(Q3:Q12) -> 42 | R13: =SUM(R3:R12) -> 42 | S13: =SUM(S3:S12) -> 0
A14: 2026-06-11_12-55-57 | B14: 62506.518 | C14: 62496.037 | D14: =B14-C14 -> 10.480793 | E14: =_xlfn.XLOOKUP(B14,Table1[unit bid],Table1[my_fi_name]) -> GBTC | F14: =_xlfn.XLOOKUP(C14,Table1[unit ask],Table1[my_fi_name]) -> IBIT
A15: 2026-06-11_13-10-57 | B15: 62477.637 | C15: 62460.738 | D15: =B15-C15 -> 16.899025 | E15: =_xlfn.XLOOKUP(B15,Table1[unit bid],Table1[my_fi_name]) -> HODL | F15: =_xlfn.XLOOKUP(C15,Table1[unit ask],Table1[my_fi_name]) -> IBIT
A16: 2026-06-11_13-25-57 | B16: 62300.847 | C16: 62301.895 | D16: =B16-C16 -> -1.047762 | E16: =_xlfn.XLOOKUP(B16,Table1[unit bid],Table1[my_fi_name]) -> HODL | F16: =_xlfn.XLOOKUP(C16,Table1[unit ask],Table1[my_fi_name]) -> IBIT
A17: 2026-06-11_13-40-57 | B17: 63255.514 | C17: 63254.955 | D17: =B17-C17 -> 0.558873 | E17: =_xlfn.XLOOKUP(B17,Table1[unit bid],Table1[my_fi_name]) -> HODL | F17: =_xlfn.XLOOKUP(C17,Table1[unit ask],Table1[my_fi_name]) -> IBIT
A18: 2026-06-11_13-55-57 | B18: 63386.165 | C18: 63389.941 | D18: =B18-C18 -> -3.775208 | E18: =_xlfn.XLOOKUP(B18,Table1[unit bid],Table1[my_fi_name]) -> FBTC | F18: =_xlfn.XLOOKUP(C18,Table1[unit ask],Table1[my_fi_name]) -> BITB
A19: 2026-06-11_14-10-57 | B19: 63285.65 | C19: 63281.88 | D19: =B19-C19 -> 3.770392 | E19: =_xlfn.XLOOKUP(B19,Table1[unit bid],Table1[my_fi_name]) -> BTC | F19: =_xlfn.XLOOKUP(C19,Table1[unit ask],Table1[my_fi_name]) -> ARKB
A20: 2026-06-11_14-25-57 | B20: 63376.091 | C20: 63369.832 | D20: =B20-C20 -> 6.259049 | E20: =_xlfn.XLOOKUP(B20,Table1[unit bid],Table1[my_fi_name]) -> BTC | F20: =_xlfn.XLOOKUP(C20,Table1[unit ask],Table1[my_fi_name]) -> GBTC
A21: 2026-06-11_14-40-57 | B21: 63421.373 | C21: 63426.774 | D21: =B21-C21 -> -5.401074 | E21: =_xlfn.XLOOKUP(B21,Table1[unit bid],Table1[my_fi_name]) -> GBTC | F21: =_xlfn.XLOOKUP(C21,Table1[unit ask],Table1[my_fi_name]) -> BITB
A22: 2026-06-11_14-55-57 | B22: 63421.311 | C22: 63412.886 | D22: =B22-C22 -> 8.425345 | E22: =_xlfn.XLOOKUP(B22,Table1[unit bid],Table1[my_fi_name]) -> BTC | F22: =_xlfn.XLOOKUP(C22,Table1[unit ask],Table1[my_fi_name]) -> EZBC
A23: 2026-06-11_15-10-57 | B23: 63396.946 | C23: 63389.941 | D23: =B23-C23 -> 7.005355 | E23: =_xlfn.XLOOKUP(B23,Table1[unit bid],Table1[my_fi_name]) -> HODL | F23: =_xlfn.XLOOKUP(C23,Table1[unit ask],Table1[my_fi_name]) -> BITB
A24: 2026-06-11_15-25-57 | B24: 63592.934 | C24: 63601.767 | D24: =B24-C24 -> -8.832392 | E24: =_xlfn.XLOOKUP(B24,Table1[unit bid],Table1[my_fi_name]) -> FBTC | F24: =_xlfn.XLOOKUP(C24,Table1[unit ask],Table1[my_fi_name]) -> GBTC
A25: 2026-06-11_15-40-57 | B25: 63684.832 | C25: 63691.964 | D25: =B25-C25 -> -7.132083 | E25: =_xlfn.XLOOKUP(B25,Table1[unit bid],Table1[my_fi_name]) -> FBTC | F25: =_xlfn.XLOOKUP(C25,Table1[unit ask],Table1[my_fi_name]) -> GBTC
A26: 2026-06-11_15-55-57 | B26: 63610.94 | C26: 63610.94 | D26: =B26-C26 -> 0 | E26: =_xlfn.XLOOKUP(B26,Table1[unit bid],Table1[my_fi_name]) -> BITB | F26: =_xlfn.XLOOKUP(C26,Table1[unit ask],Table1[my_fi_name]) -> BITB
D27: =SUM(D2:D26) -> 73.530954
